Workbook

Sheet Summary tables
A1: Comparación Errores por modelo, canal y perfil demográfico - General | E1: Comparación Errores por modelo, canal y prompt - General
B2: RECM(+B) - Edad | C2: RECM(+B) - Edad + ingresos | F2: RECM(+B) - P.Original | G2: RECM(+B) - P.Perfecto
A3: API | E3: API
A4: GPT 4 | B4: =AVERAGE('Madrid - PIMLE'!J5,'Madrid - PIMLE'!J11,'Andalusia - PIMLE'!J5,'Andalusia - PIMLE'!J11,'Valencia - PIMLE'!J5,'Valencia - PIMLE'!J14) -> 10.345279 | C4: =AVERAGE('Madrid - PIMLE'!J6,'Madrid - PIMLE'!J12,'Andalusia - PIMLE'!J6,'Andalusia - PIMLE'!J12,'Valencia - PIMLE'!J6) -> 11.327763 | E4: GPT 4 | F4: =AVERAGE('Madrid - PIMLE'!J5:J6,'Andalusia - PIMLE'!J5:J6,'Valencia - PIMLE'!J5:J6) -> 11.277569 | G4: =AVERAGE('Madrid - PIMLE'!J11:J12,'Andalusia - PIMLE'!J11:J12,'Valencia - PIMLE'!J14) -> 10.209015
A5: GPT 4o - mini | B5: =AVERAGE('Madrid - PIMLE'!J7,'Madrid - PIMLE'!J13,'Andalusia - PIMLE'!J7,'Valencia - PIMLE'!J7) -> 6.5995051 | C5: =AVERAGE('Madrid - PIMLE'!J8,'Madrid - PIMLE'!J14,'Andalusia - PIMLE'!J8,'Valencia - PIMLE'!J8) -> 7.2023601 | E5: GPT 4o - mini | F5: =AVERAGE('Madrid - PIMLE'!J7:J8,'Andalusia - PIMLE'!J7:J8,'Valencia - PIMLE'!J7:J8) -> 6.6659907 | G5: =AVERAGE('Madrid - PIMLE'!J13:J14) -> 7.6057585
A6: GPT 5 | B6: =AVERAGE('Madrid - PIMLE'!J3,'Madrid - PIMLE'!J9,'Andalusia - PIMLE'!J3,'Valencia - PIMLE'!J3,'Valencia - PIMLE'!J9) -> 4.074943 | C6: =AVERAGE('Madrid - PIMLE'!J10,'Madrid - PIMLE'!J4,'Andalusia - PIMLE'!J4,'Andalusia - PIMLE'!J10,'Valencia - PIMLE'!J10,'Valencia - PIMLE'!J4) -> 3.9671522 | E6: GPT 5 | F6: =AVERAGE('Madrid - PIMLE'!J3:J4,'Andalusia - PIMLE'!J3:J4,'Valencia - PIMLE'!J3:J4) -> 4.1910256 | G6: =AVERAGE('Madrid - PIMLE'!J9:J10,'Andalusia - PIMLE'!J10,'Valencia - PIMLE'!J9:J10) -> 3.8062949
A7: CHAT | E7: CHAT
A8: GPT 4o - mini | B8: =AVERAGE('Madrid - PIMLE'!J17) -> 3.3840804 | C8: =AVERAGE('Madrid - PIMLE'!J18,'Andalusia - PIMLE'!J17,'Valencia - PIMLE'!J17) -> 3.4340908 | E8: GPT 4o - mini | F8: =AVERAGE('Madrid - PIMLE'!J17:J18,'Andalusia - PIMLE'!J17,'Valencia - PIMLE'!J17) -> 3.4215882 | G8: -
A9: GPT 5 | B9: =AVERAGE('Madrid - PIMLE'!J15,'Madrid - PIMLE'!J19,'Andalusia - PIMLE'!J15,'Andalusia - PIMLE'!J18,'Valencia - PIMLE'!J15,'Valencia - PIMLE'!J18) -> 4.0565269 | C9: =AVERAGE('Madrid - PIMLE'!J16,'Madrid - PIMLE'!J20,'Andalusia - PIMLE'!J16,'Andalusia - PIMLE'!J19,'Valencia - PIMLE'!J16,'Valencia - PIMLE'!J19) -> 3.3867563 | E9: GPT 5 | F9: =AVERAGE('Madrid - PIMLE'!J15:J16,'Andalusia - PIMLE'!J15:J16,'Valencia - PIMLE'!J15:J16) -> 4.0456761 | G9: =AVERAGE('Madrid - PIMLE'!J19:J20,'Andalusia - PIMLE'!J18:J19,'Valencia - PIMLE'!J18:J19) -> 3.3976071
A14: Comparación RMSE +B - PIMLE | I14: Emulación RMSE +B - PIMLE
B15: MADRID | D15: ANDALUCÍA | F15: VALENCIA | J15: MADRID | L15: ANDALUCÍA | N15: VALENCIA
B16: Edad | C16: Edad + Ingresos | D16: Edad | E16: Edad + Ingresos | F16: Edad | G16: Edad + Ingresos | J16: Edad | K16: Edad + Ingresos | L16: Edad | M16: Edad + Ingresos | N16: Edad | O16: Edad + Ingresos
A17: API | I17: API
A18: GPT 4 | B18: =AVERAGE('Madrid - PIMLE'!J11,'Madrid - PIMLE'!J5) -> 10.838483 | C18: =AVERAGE('Madrid - PIMLE'!J6,'Madrid - PIMLE'!J12) -> 11.674339 | D18: =AVERAGE('Andalusia - PIMLE'!J5,'Andalusia - PIMLE'!J11) -> 10.957609 | E18: =AVERAGE('Andalusia - PIMLE'!J6,'Andalusia - PIMLE'!J12) -> 11.244109 | F18: =AVERAGE('Valencia - PIMLE'!J5,'Valencia - PIMLE'!J11) -> 11.575531 | G18: =AVERAGE('Valencia - PIMLE'!J6) -> 10.80192 | I18: GPT 4 | J18: =AVERAGE('Madrid - PIMLE'!L11,'Madrid - PIMLE'!L5) -> 10.262868 | K18: =AVERAGE('Madrid - PIMLE'!L6,'Madrid - PIMLE'!L12) -> 11.099146 | L18: =AVERAGE('Andalusia - PIMLE'!L5,'Andalusia - PIMLE'!L11) -> 9.9337533 | M18: =AVERAGE('Andalusia - PIMLE'!L6,'Andalusia - PIMLE'!L12) -> 10.312528 | N18: =AVERAGE('Valencia - PIMLE'!L5,'Valencia - PIMLE'!L14) -> 6.9452404 | O18: =AVERAGE('Valencia - PIMLE'!L6) -> 8.589312
A19: GPT 4o - mini | B19: =AVERAGE('Madrid - PIMLE'!J7,'Madrid - PIMLE'!J13) -> 6.8604583 | C19: =AVERAGE('Madrid - PIMLE'!J14,'Madrid - PIMLE'!J8) -> 7.6573234 | D19: =AVERAGE('Andalusia - PIMLE'!J7,'Andalusia - PIMLE'!J13) -> 6.6536433 | E19: =AVERAGE('Andalusia - PIMLE'!J14,'Andalusia - PIMLE'!J8) -> 7.3726285 | F19: =AVERAGE('Valencia - PIMLE'!J7,'Valencia - PIMLE'!J13) -> 7.1159893 | G19: =AVERAGE('Valencia - PIMLE'!J14,'Valencia - PIMLE'!J8) -> 6.9073257 | I19: GPT 4o - mini | J19: =AVERAGE('Madrid - PIMLE'!L7,'Madrid - PIMLE'!L13) -> 6.293146 | K19: =AVERAGE('Madrid - PIMLE'!L14,'Madrid - PIMLE'!L8) -> 7.1400769 | L19: =AVERAGE('Andalusia - PIMLE'!L7) -> 2.8774989 | M19: ='Andalusia - PIMLE'!L8 -> 4.1646128 | N19: =AVERAGE('Valencia - PIMLE'!L7) -> 3.487641 | O19: ='Valencia - PIMLE'!L8 -> 3.8645931
A20: GPT 5 | B20: =AVERAGE('Madrid - PIMLE'!J3,'Madrid - PIMLE'!J9) -> 3.7693895 | C20: =AVERAGE('Madrid - PIMLE'!J4,'Madrid - PIMLE'!J10) -> 3.7245822 | D20: =AVERAGE('Andalusia - PIMLE'!J3,'Andalusia - PIMLE'!J9) -> 3.9499468 | E20: =AVERAGE('Andalusia - PIMLE'!J4,'Andalusia - PIMLE'!J10) -> 3.92279 | F20: =AVERAGE('Valencia - PIMLE'!J3,'Valencia - PIMLE'!J9) -> 4.2838406 | G20: =AVERAGE('Valencia - PIMLE'!J4,'Valencia - PIMLE'!J10) -> 4.2540843 | I20: GPT 5 | J20: =AVERAGE('Madrid - PIMLE'!L3,'Madrid - PIMLE'!L9) -> 3.197019 | K20: =AVERAGE('Madrid - PIMLE'!L4,'Madrid - PIMLE'!L10) -> 3.1862581 | L20: =AVERAGE('Andalusia - PIMLE'!L3) -> 1.8433665 | M20: =AVERAGE('Andalusia - PIMLE'!L4,'Andalusia - PIMLE'!L10) -> 1.4793216 | N20: =AVERAGE('Valencia - PIMLE'!L3,'Valencia - PIMLE'!L9) -> 1.2941141 | O20: =AVERAGE('Valencia - PIMLE'!L4,'Valencia - PIMLE'!L10) -> 1.4851464
A21: CHAT | I21: CHAT
A22: GPT 4o - mini | B22: =AVERAGE('Madrid - PIMLE'!J17) -> 3.3840804 | C22: =AVERAGE('Madrid - PIMLE'!J18,'Madrid - PIMLE'!J21) -> 3.7908859 | D22: -- | E22: =AVERAGE('Andalusia - PIMLE'!J17) -> 3.4793678 | F22: -- | G22: ='Valencia - PIMLE'!J17 -> 3.9902381 | I22: GPT 4o - mini | J22: =AVERAGE('Madrid - PIMLE'!L17) -> 2.7846005 | K22: ='Madrid - PIMLE'!L18 -> 2.3405128 | L22: -- | M22: =AVERAGE('Andalusia - PIMLE'!L17) -> 1.2107849 | N22: -- | O22: ='Valencia - PIMLE'!L17 -> 2.4811288
A23: GPT 5 | B23: =AVERAGE('Madrid - PIMLE'!J15,'Madrid - PIMLE'!J19) -> 4.1037788 | C23: =AVERAGE('Madrid - PIMLE'!J16,'Madrid - PIMLE'!J20) -> 3.4590582 | D23: =AVERAGE('Andalusia - PIMLE'!J15,'Andalusia - PIMLE'!J18) -> 3.8605958 | E23: =AVERAGE('Andalusia - PIMLE'!J16,'Andalusia - PIMLE'!J19) -> 3.2791004 | F23: =AVERAGE('Valencia - PIMLE'!J15,'Valencia - PIMLE'!J18) -> 4.2052061 | G23: =AVERAGE('Valencia - PIMLE'!J16,'Valencia - PIMLE'!J19) -> 3.4221103 | I23: GPT 5 | J23: =AVERAGE('Madrid - PIMLE'!L15,'Madrid - PIMLE'!L19) -> 3.5901457 | K23: =AVERAGE('Madrid - PIMLE'!L16,'Madrid - PIMLE'!L20) -> 2.991399 | L23: =AVERAGE('Andalusia - PIMLE'!L15,'Andalusia - PIMLE'!L18) -> 1.7404867 | M23: =AVERAGE('Andalusia - PIMLE'!L16,'Andalusia - PIMLE'!L19) -> 1.4770996 | N23: =AVERAGE('Valencia - PIMLE'!L15,'Valencia - PIMLE'!L18) -> 1.8059506 | O23: =AVERAGE('Valencia - PIMLE'!L16,'Valencia - PIMLE'!L19) -> 1.3522046
A26: Comparación RMSE +B - PIMLE | I26: Emulación RMSE +B - PIMLE
B27: MADRID | D27: ANDALUCÍA | F27: VALENCIA | J27: MADRID | L27: ANDALUCÍA | N27: VALENCIA
B28: P.Original | C28: P.Perfecto | D28: P.Original | E28: P.Perfecto | F28: P.Original | G28: P.Perfecto | J28: P.Original | K28: P.Perfecto | L28: P.Original | M28: P.Perfecto | N28: P.Original | O28: P.Perfecto
A29: API | I29: API
A30: GPT 4 | B30: =AVERAGE('Madrid - PIMLE'!J5:J6) -> 11.541567 | C30: =AVERAGE('Madrid - PIMLE'!J11:J12) -> 10.971255 | D30: =AVERAGE('Andalusia - PIMLE'!J5:J6) -> 11.248822 | E30: =AVERAGE('Andalusia - PIMLE'!J11:J12) -> 10.952895 | F30: =AVERAGE('Valencia - PIMLE'!J5:J6) -> 11.042317 | G30: =AVERAGE('Valencia - PIMLE'!J11:J12) -> 12.09045 | I30: GPT 4 | J30: =AVERAGE('Madrid - PIMLE'!L5:L6) -> 10.975307 | K30: =AVERAGE('Madrid - PIMLE'!L11:L12) -> 10.386707 | L30: =AVERAGE('Andalusia - PIMLE'!L5:L6) -> 10.14002 | M30: =AVERAGE('Andalusia - PIMLE'!L11:L12) -> 10.106262 | N30: =AVERAGE('Valencia - PIMLE'!L5:L6) -> 8.8045124 | O30: =AVERAGE('Valencia - PIMLE'!L11:L12) -> 9.8716956
A31: GPT 4o - mini | B31: =AVERAGE('Madrid - PIMLE'!J7:J8) -> 6.9120232 | C31: =AVERAGE('Madrid - PIMLE'!J13:J14) -> 7.6057585 | D31: =AVERAGE('Andalusia - PIMLE'!J7:J8) -> 6.518881 | E31: =AVERAGE('Andalusia - PIMLE'!J13:J14) -> 7.5073908 | F31: =AVERAGE('Valencia - PIMLE'!J7:J8) -> 6.5670677 | G31: =AVERAGE('Valencia - PIMLE'!J13:J14) -> 7.4562473 | I31: GPT 4o - mini | J31: =AVERAGE('Madrid - PIMLE'!L7:L8) -> 6.3811332 | K31: =AVERAGE('Madrid - PIMLE'!L13:L14) -> 7.0520898 | L31: =AVERAGE('Andalusia - PIMLE'!L7:L8) -> 3.5210559 | M31: =AVERAGE('Andalusia - PIMLE'!L13:L14) -> 5.4232469 | N31: =AVERAGE('Valencia - PIMLE'!L7:L8) -> 3.6761171 | O31: =AVERAGE('Valencia - PIMLE'!L13:L14) -> 5.1479252
A32: GPT 5 | B32: =AVERAGE('Madrid - PIMLE'!J3:J4) -> 3.9849688 | C32: =AVERAGE('Madrid - PIMLE'!J9:J10) -> 3.5090029 | D32: =AVERAGE('Andalusia - PIMLE'!J3:J4) -> 4.3039201 | E32: =AVERAGE('Andalusia - PIMLE'!J9:J10) -> 3.5688168 | F32: =AVERAGE('Valencia - PIMLE'!J3:J4) -> 4.284188 | G32: =AVERAGE('Valencia - PIMLE'!J9:J10) -> 4.253737 | I32: GPT 5 | J32: =AVERAGE('Madrid - PIMLE'!L3:L4) -> 3.4115249 | K32: =AVERAGE('Madrid - PIMLE'!L9:L10) -> 2.9717521 | L32: =AVERAGE('Andalusia - PIMLE'!L3:L4) -> 1.9030089 | M32: =AVERAGE('Andalusia - PIMLE'!L9,'Andalusia - PIMLE'!L10) -> 0.86974859 | N32: =AVERAGE('Valencia - PIMLE'!L3:L4) -> 1.3450606 | O32: =AVERAGE('Valencia - PIMLE'!L9:L10) -> 1.4341999
A33: CHAT | I33: CHAT
A34: GPT 4o - mini | B34: =AVERAGE('Madrid - PIMLE'!J17:J18) -> 3.1083735 | C34: ='Madrid - PIMLE'!J21 -> 4.7491052 | D34: =AVERAGE('Andalusia - PIMLE'!J17) -> 3.4793678 | E34: -- | F34: =AVERAGE('Valencia - PIMLE'!J17) -> 3.9902381 | G34: -- | I34: GPT 4o - mini | J34: =AVERAGE('Madrid - PIMLE'!L17:L18) -> 2.5625566 | K34: 4.38 | L34: =AVERAGE('Andalusia - PIMLE'!L17) -> 1.2107849 | M34: -- | N34: =AVERAGE('Valencia - PIMLE'!L17) -> 2.4811288 | O34: --
A35: GPT 5 | B35: =AVERAGE('Madrid - PIMLE'!J15:J16) -> 4.1421133 | C35: =AVERAGE('Madrid - PIMLE'!J19:J20) -> 3.4207237 | D35: =AVERAGE('Andalusia - PIMLE'!J15:J16) -> 4.1716419 | E35: =AVERAGE('Andalusia - PIMLE'!J18:J19) -> 2.9680543 | F35: =AVERAGE('Valencia - PIMLE'!J15:J16) -> 3.8232729 | G35: =AVERAGE('Valencia - PIMLE'!J18:J19) -> 3.8040434 | I35: GPT 5 | J35: =AVERAGE('Madrid - PIMLE'!L15:L16) -> 3.6086825 | K35: =AVERAGE('Madrid - PIMLE'!L19:L20) -> 2.9728622 | L35: =AVERAGE('Andalusia - PIMLE'!L15:L16) -> 1.8602261 | M35: =AVERAGE('Andalusia - PIMLE'!L18:L19) -> 1.3573602 | N35: =AVERAGE('Valencia - PIMLE'!L15:L16) -> 1.370758 | O35: =AVERAGE('Valencia - PIMLE'!L18:L19) -> 1.7873972
A38: Comparación RMSE +B - PIMLE | I38: Emulación RMSE +B - PIMLE
A39: Modelo | B39: MADRID | C39: ANDALUCÍA | D39: VALENCIA | I39: Modelo | J39: MADRID | K39: ANDALUCÍA | L39: VALENCIA
A40: API | I40: API
A41: GPT 4 | B41: =AVERAGE('Madrid - PIMLE'!J5:J6,'Madrid - PIMLE'!J11:J12) -> 11.256411 | C41: =AVERAGE('Andalusia - PIMLE'!J5:J6,'Andalusia - PIMLE'!J11:J12) -> 11.100859 | D41: =AVERAGE('Valencia - PIMLE'!J5:J6,'Valencia - PIMLE'!J11:J12) -> 11.566383 | I41: GPT 4 | J41: =AVERAGE('Madrid - PIMLE'!L5:L6,'Madrid - PIMLE'!L11:L12) -> 10.681007 | K41: =AVERAGE('Andalusia - PIMLE'!L5:L6,'Andalusia - PIMLE'!L11:L12) -> 10.123141 | L41: =AVERAGE('Valencia - PIMLE'!L5:L6,'Valencia - PIMLE'!L11:L12) -> 9.338104
A42: GPT 4o - mini | B42: =AVERAGE('Madrid - PIMLE'!J7:J8,'Madrid - PIMLE'!J13:J14) -> 7.2588909 | C42: =AVERAGE('Andalusia - PIMLE'!J7:J8,'Andalusia - PIMLE'!J13:J14) -> 7.0131359 | D42: =AVERAGE('Valencia - PIMLE'!J7:J8,'Valencia - PIMLE'!J13:J14) -> 7.0116575 | I42: GPT 4o - mini | J42: =AVERAGE('Madrid - PIMLE'!L7:L8,'Madrid - PIMLE'!L13:L14) -> 6.7166115 | K42: =AVERAGE('Andalusia - PIMLE'!L7:L8,'Andalusia - PIMLE'!L13:L14) -> 4.4721514 | L42: =AVERAGE('Valencia - PIMLE'!L7:L8,'Valencia - PIMLE'!L13:L14) -> 4.4120211
A43: GPT 5 | B43: =AVERAGE('Madrid - PIMLE'!J3:J4,'Madrid - PIMLE'!J9:J10) -> 3.7469859 | C43: =AVERAGE('Andalusia - PIMLE'!J3:J4,'Andalusia - PIMLE'!J9:J10) -> 3.9363684 | D43: =AVERAGE('Valencia - PIMLE'!J3:J4,'Valencia - PIMLE'!J9:J10) -> 4.2689625 | I43: GPT 5 | J43: =AVERAGE('Madrid - PIMLE'!L3:L4,'Madrid - PIMLE'!L9:L10) -> 3.1916385 | K43: =AVERAGE('Andalusia - PIMLE'!L3:L4,'Andalusia - PIMLE'!L9:L10) -> 1.3863787 | L43: =AVERAGE('Valencia - PIMLE'!L3:L4,'Valencia - PIMLE'!L9:L10) -> 1.3896302
A44: CHAT | I44: CHAT
A45: GPT 4o - mini | B45: =AVERAGE('Madrid - PIMLE'!J17:J18) -> 3.1083735 | C45: =AVERAGE('Andalusia - PIMLE'!J17) -> 3.4793678 | D45: =AVERAGE('Valencia - PIMLE'!J17) -> 3.9902381 | I45: GPT 4o - mini | J45: =AVERAGE('Madrid - PIMLE'!L17:L18,'Madrid - PIMLE'!L21) -> 3.1675946 | K45: =AVERAGE('Andalusia - PIMLE'!L17) -> 1.2107849 | L45: =AVERAGE('Valencia - PIMLE'!L17) -> 2.4811288
A46: GPT 5 | B46: =AVERAGE('Madrid - PIMLE'!J15:J16,'Madrid - PIMLE'!J19:J20) -> 3.7814185 | C46: =AVERAGE('Andalusia - PIMLE'!J15:J16,'Andalusia - PIMLE'!J18:J19) -> 3.5698481 | D46: =AVERAGE('Valencia - PIMLE'!J15:J16,'Valencia - PIMLE'!J18:J19) -> 3.8136582 | I46: GPT 5 | J46: =AVERAGE('Madrid - PIMLE'!L15:L16,'Madrid - PIMLE'!L19:L20) -> 3.2907724 | K46: =AVERAGE('Andalusia - PIMLE'!L15:L16,'Andalusia - PIMLE'!L18:L19) -> 1.6087931 | L46: =AVERAGE('Valencia - PIMLE'!L15:L16,'Valencia - PIMLE'!L18:L19) -> 1.5790776

Sheet Madrid - PIMLE
A1: Survey | B1: PP | C1: PSOE | D1: VOX | E1: Sumar | F1: Blank | G1: MSE | H1: RMSE | I1: MSE (+Blank) | J1: RMSE (+Blank) | K1: Emulation
A2: Human Survey | B2: 39.2 | C2: 27.6 | D2: 14.6 | E2: 14.7 | F2: 3.8 | G2: =AVERAGE((B2-$B$22)^2, (C2-$C$22)^2, (D2-$D$22)^2, (E2-$E$22)^2) -> 0.465 | H2: =SQRT(G2) -> 0.68190908 | I2: 0.534 | J2: 0.73075304 | K2: MSE (+Blank) | L2: RMSE (+Blank)
A3: API - P.original - Edad - GPT 5 | B3: 34.1 | C3: 25 | D3: 16.8 | E3: 16.4 | F3: 7.8 | G3: =AVERAGE((B3-$B$22)^2, (C3-$C$22)^2, (D3-$D$22)^2, (E3-$E$22)^2) -> 13.53 | H3: =SQRT(G3) -> 3.6783148 | I3: =AVERAGE((B3-$B$22)^2,(C3-$C$22)^2,(D3-$D$22)^2,(E3-$E$22)^2,(F3-$F$22)^2) -> 15.626 | J3: =SQRT(I3) -> 3.9529736 | K3: =AVERAGE((B3-$B$2)^2,(C3-$C$2)^2,(D3-$D$2)^2,(E3-$E$2)^2,(F3-$F$2)^2) -> 11.3 | L3: =SQRT(K3) -> 3.3615473
A4: API - P.original - Edad e ingresos - GPT 5 | B4: 33.9 | C4: 24.9 | D4: 16.4 | E4: 17 | F4: 7.8 | G4: =AVERAGE((B4-$B$22)^2, (C4-$C$22)^2, (D4-$D$22)^2, (E4-$E$22)^2) -> 14.1675 | H4: =SQRT(G4) -> 3.763974 | I4: =AVERAGE((B4-$B$22)^2,(C4-$C$22)^2,(D4-$D$22)^2,(E4-$E$22)^2,(F4-$F$22)^2) -> 16.136 | J4: =SQRT(I4) -> 4.016964 | K4: =AVERAGE((B4-$B$2)^2,(C4-$C$2)^2,(D4-$D$2)^2,(E4-$E$2)^2,(F4-$F$2)^2) -> 11.982 | L4: =SQRT(K4) -> 3.4615026
A5: API - P.original - Edad - GPT 4 | B5: 25 | C5: 33.1 | D5: 11.3 | E5: 9.8 | F5: 20.7 | G5: =AVERAGE((B5-$B$22)^2, (C5-$C$22)^2, (D5-$D$22)^2, (E5-$E$22)^2) -> 74.3025 | H5: =SQRT(G5) -> 8.6198898 | I5: =AVERAGE((B5-$B$22)^2,(C5-$C$22)^2,(D5-$D$22)^2,(E5-$E$22)^2,(F5-$F$22)^2) -> 122.81 | J5: =SQRT(I5) -> 11.081967 | K5: =AVERAGE((B5-$B$2)^2,(C5-$C$2)^2,(D5-$D$2)^2,(E5-$E$2)^2,(F5-$F$2)^2) -> 110.48 | L5: =SQRT(K5) -> 10.510947
A6: API - P.original - Edad e ingresos - GPT 4 | B6: 24.4 | C6: 34.9 | D6: 10.8 | E6: 8.1 | F6: 21.8 | G6: =AVERAGE((B6-$B$22)^2, (C6-$C$22)^2, (D6-$D$22)^2, (E6-$E$22)^2) -> 90.7325 | H6: =SQRT(G6) -> 9.5253609 | I6: =AVERAGE((B6-$B$22)^2,(C6-$C$22)^2,(D6-$D$22)^2,(E6-$E$22)^2,(F6-$F$22)^2) -> 144.028 | J6: =SQRT(I6) -> 12.001167 | K6: =AVERAGE((B6-$B$2)^2,(C6-$C$2)^2,(D6-$D$2)^2,(E6-$E$2)^2,(F6-$F$2)^2) -> 130.866 | L6: =SQRT(K6) -> 11.439668
A7: API - P.original - Edad - GPT 4o-mini | B7: 32.8 | C7: 25.6 | D7: 13.3 | E7: 13.5 | F7: 14.8 | G7: =AVERAGE((B7-$B$22)^2, (C7-$C$22)^2, (D7-$D$22)^2, (E7-$E$22)^2) -> 15.6925 | H7: =SQRT(G7) -> 3.961376 | I7: =AVERAGE((B7-$B$22)^2,(C7-$C$22)^2,(D7-$D$22)^2,(E7-$E$22)^2,(F7-$F$22)^2) -> 40.876 | J7: =SQRT(I7) -> 6.3934341 | K7: =AVERAGE((B7-$B$2)^2,(C7-$C$2)^2,(D7-$D$2)^2,(E7-$E$2)^2,(F7-$F$2)^2) -> 33.818 | L7: =SQRT(K7) -> 5.8153246
A8: API - P.original - Edad e ingresos - GPT 4o-mini | B8: 28.8 | C8: 27.6 | D8: 11.4 | E8: 17.6 | F8: 14.5 | G8: =AVERAGE((B8-$B$22)^2, (C8-$C$22)^2, (D8-$D$22)^2, (E8-$E$22)^2) -> 35.3775 | H8: =SQRT(G8) -> 5.9478988 | I8: =AVERAGE((B8-$B$22)^2,(C8-$C$22)^2,(D8-$D$22)^2,(E8-$E$22)^2,(F8-$F$22)^2) -> 55.214 | J8: =SQRT(I8) -> 7.4306124 | K8: =AVERAGE((B8-$B$2)^2,(C8-$C$2)^2,(D8-$D$2)^2,(E8-$E$2)^2,(F8-$F$2)^2) -> 48.26 | L8: =SQRT(K8) -> 6.9469418
A9: API - P.perfect - Edad - GPT 5 | B9: 36.6 | C9: 23.4 | D9: 16.7 | E9: 15.3 | F9: 7.9 | G9: =AVERAGE((B9-$B$22)^2, (C9-$C$22)^2, (D9-$D$22)^2, (E9-$E$22)^2) -> 9.8225 | H9: =SQRT(G9) -> 3.1340868 | I9: =AVERAGE((B9-$B$22)^2,(C9-$C$22)^2,(D9-$D$22)^2,(E9-$E$22)^2,(F9-$F$22)^2) -> 12.858 | J9: =SQRT(I9) -> 3.5858053 | K9: =AVERAGE((B9-$B$2)^2,(C9-$C$2)^2,(D9-$D$2)^2,(E9-$E$2)^2,(F9-$F$2)^2) -> 9.196 | L9: =SQRT(K9) -> 3.0324907
A10: API - P.perfect - Edad e ingresos - GPT 5 | B10: 37.4 | C10: 23.1 | D10: 17 | E10: 15.1 | F10: 7.4 | G10: =AVERAGE((B10-$B$22)^2, (C10-$C$22)^2, (D10-$D$22)^2, (E10-$E$22)^2) -> 9.6625 | H10: =SQRT(G10) -> 3.1084562 | I10: =AVERAGE((B10-$B$22)^2,(C10-$C$22)^2,(D10-$D$22)^2,(E10-$E$22)^2,(F10-$F$22)^2) -> 11.78 | J10: =SQRT(I10) -> 3.4322005 | K10: =AVERAGE((B10-$B$2)^2,(C10-$C$2)^2,(D10-$D$2)^2,(E10-$E$2)^2,(F10-$F$2)^2) -> 8.474 | L10: =SQRT(K10) -> 2.9110136
A11: API - P.perfect - Edad - GPT 4 | B11: 28.9 | C11: 33.2 | D11: 12.3 | E11: 5.4 | F11: 20.3 | G11: =AVERAGE((B11-$B$22)^2, (C11-$C$22)^2, (D11-$D$22)^2, (E11-$E$22)^2) -> 64.6275 | H11: =SQRT(G11) -> 8.0391231 | I11: =AVERAGE((B11-$B$22)^2,(C11-$C$22)^2,(D11-$D$22)^2,(E11-$E$22)^2,(F11-$F$22)^2) -> 112.254 | J11: =SQRT(I11) -> 10.594999 | K11: =AVERAGE((B11-$B$2)^2,(C11-$C$2)^2,(D11-$D$2)^2,(E11-$E$2)^2,(F11-$F$2)^2) -> 100.296 | L11: =SQRT(K11) -> 10.014789
A12: API - P.perfect - Edad e ingresos - GPT 4 | B12: 27.8 | C12: 32.2 | D12: 12.1 | E12: 5.6 | F12: 22.2 | G12: =AVERAGE((B12-$B$22)^2, (C12-$C$22)^2, (D12-$D$22)^2, (E12-$E$22)^2) -> 67.835 | H12: =SQRT(G12) -> 8.2362006 | I12: =AVERAGE((B12-$B$22)^2,(C12-$C$22)^2,(D12-$D$22)^2,(E12-$E$22)^2,(F12-$F$22)^2) -> 128.766 | J12: =SQRT(I12) -> 11.347511 | K12: =AVERAGE((B12-$B$2)^2,(C12-$C$2)^2,(D12-$D$2)^2,(E12-$E$2)^2,(F12-$F$2)^2) -> 115.748 | L12: =SQRT(K12) -> 10.758624
A13: API - P.perfect - Edad - GPT 4o-mini | B13: 30.2 | C13: 25.8 | D13: 12.9 | E13: 15.4 | F13: 15.7 | G13: =AVERAGE((B13-$B$22)^2, (C13-$C$22)^2, (D13-$D$22)^2, (E13-$E$22)^2) -> 26.155 | H13: =SQRT(G13) -> 5.1141959 | I13: =AVERAGE((B13-$B$22)^2,(C13-$C$22)^2,(D13-$D$22)^2,(E13-$E$22)^2,(F13-$F$22)^2) -> 53.692 | J13: =SQRT(I13) -> 7.3274825 | K13: =AVERAGE((B13-$B$2)^2,(C13-$C$2)^2,(D13-$D$2)^2,(E13-$E$2)^2,(F13-$F$2)^2) -> 45.846 | L13: =SQRT(K13) -> 6.7709674
A14: API - P.perfect - Edad e ingresos - GPT 4o-mini | B14: 27.4 | C14: 29.6 | D14: 12.6 | E14: 15.5 | F14: 14.8 | G14: =AVERAGE((B14-$B$22)^2, (C14-$C$22)^2, (D14-$D$22)^2, (E14-$E$22)^2) -> 42.295 | H14: =SQRT(G14) -> 6.5034606 | I14: =AVERAGE((B14-$B$22)^2,(C14-$C$22)^2,(D14-$D$22)^2,(E14-$E$22)^2,(F14-$F$22)^2) -> 62.158 | J14: =SQRT(I14) -> 7.8840345 | K14: =AVERAGE((B14-$B$2)^2,(C14-$C$2)^2,(D14-$D$2)^2,(E14-$E$2)^2,(F14-$F$2)^2) -> 53.776 | L14: =SQRT(K14) -> 7.3332121
... A21: CHAT - P.perfecto - Edad e ingresos GPT 4o | B21: 32.1 | C21: 27.6 | D21: 12.6 | E21: 19.2 | F21: 8.4 | G21: =AVERAGE((B21-$B$22)^2, (C21-$C$22)^2, (D21-$D$22)^2, (E21-$E$22)^2) -> 20.63 | H21: =SQRT(G21) -> 4.542026 | I21: =AVERAGE((B21-$B$22)^2,(C21-$C$22)^2,(D21-$D$22)^2,(E21-$E$22)^2,(F21-$F$22)^2) -> 22.554 | J21: =SQRT(I21) -> 4.7491052 | K21: =AVERAGE((B21-$B$2)^2,(C21-$C$2)^2,(D21-$D$2)^2,(E21-$E$2)^2,(F21-$F$2)^2) -> 19.164 | L21: =SQRT(K21) -> 4.3776706
A22: Electoral Results | B22: 40.2 | C22: 27.7 | D22: 13.9 | E22: 15.3 | F22: 2.9 | K22: =AVERAGE((B22-$B$2)^2,(C22-$C$2)^2,(D22-$D$2)^2,(E22-$E$2)^2,(F22-$F$2)^2) -> 0.534 | L22: =SQRT(K22) -> 0.73075304
A25: Survey | B25: PP | C25: PSOE | D25: VOX | E25: Sumar | F25: MSE | G25: RMSE
A26: Human Survey | B26: 16 | C26: 11 | D26: 5 | E26: 5 | F26: =AVERAGE((B26-$B$46)^2, (C26-$C$46)^2, (D26-$D$46)^2, (E26-$E$46)^2) -> 0.5 | G26: =SQRT(F26) -> 0.70710678
A27: API - P.original - Edad - GPT 5 | B27: 14 | C27: 10 | D27: 7 | E27: 6 | F27: =AVERAGE((B27-$B$46)^2, (C27-$C$46)^2, (D27-$D$46)^2, (E27-$E$46)^2) -> 2 | G27: =SQRT(F27) -> 1.4142136
A28: API - P.original - Edad e ingresos - GPT 5 | B28: 14 | C28: 10 | D28: 6 | E28: 7 | F28: =AVERAGE((B28-$B$46)^2, (C28-$C$46)^2, (D28-$D$46)^2, (E28-$E$46)^2) -> 1.5 | G28: =SQRT(F28) -> 1.2247449
A29: API - P.original - Edad - GPT 4 | B29: 12 | C29: 16 | D29: 5 | E29: 4 | F29: =AVERAGE((B29-$B$46)^2, (C29-$C$46)^2, (D29-$D$46)^2, (E29-$E$46)^2) -> 14 | G29: =SQRT(F29) -> 3.7416574
A30: API - P.original - Edad e ingresos - GPT 4 | B30: 12 | C30: 17 | D30: 5 | E30: 3 | F30: =AVERAGE((B30-$B$46)^2, (C30-$C$46)^2, (D30-$D$46)^2, (E30-$E$46)^2) -> 18.5 | G30: =SQRT(F30) -> 4.3011626
A31: API - P.original - Edad - GPT 4o-mini | B31: 14 | C31: 11 | D31: 6 | E31: 6 | F31: =AVERAGE((B31-$B$46)^2, (C31-$C$46)^2, (D31-$D$46)^2, (E31-$E$46)^2) -> 1.5 | G31: =SQRT(F31) -> 1.2247449
A32: API - P.original - Edad e ingresos - GPT 4o-mini | B32: 13 | C32: 12 | D32: 5 | E32: 7 | F32: =AVERAGE((B32-$B$46)^2, (C32-$C$46)^2, (D32-$D$46)^2, (E32-$E$46)^2) -> 3.5 | G32: =SQRT(F32) -> 1.8708287
A33: API - P.perfecto - Edad - GPT 5 | B33: 15 | C33: 9 | D33: 7 | E33: 6 | F33: =AVERAGE((B33-$B$46)^2, (C33-$C$46)^2, (D33-$D$46)^2, (E33-$E$46)^2) -> 1.5 | G33: =SQRT(F33) -> 1.2247449
A34: API - P.perfecto - Edad e ingresos - GPT 5 | B34: 15 | C34: 9 | D34: 7 | E34: 6 | F34: =AVERAGE((B34-$B$46)^2, (C34-$C$46)^2, (D34-$D$46)^2, (E34-$E$46)^2) -> 1.5 | G34: =SQRT(F34) -> 1.2247449
A35: API - P.perfecto - Edad - GPT 4 | B35: 14 | C35: 16 | D35: 5 | E35: 2 | F35: =AVERAGE((B35-$B$46)^2, (C35-$C$46)^2, (D35-$D$46)^2, (E35-$E$46)^2) -> 14 | G35: =SQRT(F35) -> 3.7416574
A36: API - P.perfecto - Edad e ingresos - GPT 4 | B36: 13 | C36: 16 | D36: 6 | E36: 2 | F36: =AVERAGE((B36-$B$46)^2, (C36-$C$46)^2, (D36-$D$46)^2, (E36-$E$46)^2) -> 15.5 | G36: =SQRT(F36) -> 3.9370039
A37: API - P.perfecto - Edad - GPT 4o-mini | B37: 14 | C37: 11 | D37: 5 | E37: 7 | F37: =AVERAGE((B37-$B$46)^2, (C37-$C$46)^2, (D37-$D$46)^2, (E37-$E$46)^2) -> 1.5 | G37: =SQRT(F37) -> 1.2247449
... A45: CHAT - P.perfecto - Edad e ingresos - GPT 5 | B45: 15 | C45: 10 | D45: 6 | E45: 6 | F45: =AVERAGE((B45-$B$46)^2, (C45-$C$46)^2, (D45-$D$46)^2, (E45-$E$46)^2) -> 0.5 | G45: =SQRT(F45) -> 0.70710678
A46: Resultados Reales | B46: 16 | C46: 10 | D46: 5 | E46: 6

Sheet Andalusia - PIMLE
A1: Survey | B1: PP | C1: PSOE | D1: VOX | E1: Sumar | F1: Blank | G1: MSE | H1: RMSE | I1: MSE (+Blank) | J1: RMSE (+Blank) | K1: Emulation
A2: Human Surveys | B2: 35.3 | C2: 28.3 | D2: 15.3 | E2: 12.6 | F2: 8.5 | G2: 7.1525 | H2: 2.6744158 | I2: 12.22 | J2: 3.4957117 | K2: MSE (+Blank) | L2: RMSE (+Blank)
A3: API - P.original - Edad - GPT 5 | B3: 32.5 | C3: 27.4 | D3: 17.6 | E3: 14.3 | F3: 8.1 | G3: =AVERAGE((B3-$B$20)^2, (C3-$C$20)^2, (D3-$D$20)^2, (E3-$E$20)^2) -> 15.75 | H3: =SQRT(G3) -> 3.968627 | I3: =AVERAGE((B3-$B$20)^2, (C3-$C$20)^2, (D3-$D$20)^2, (E3-$E$20)^2,(F3-$F$20)^2) -> 18.218 | J3: =SQRT(I3) -> 4.2682549 | K3: =AVERAGE((B3-$B$2)^2,(C3-$C$2)^2,(D3-$D$2)^2,(E3-$E$2)^2,(F3-$F$2)^2) -> 3.398 | L3: =SQRT(K3) -> 1.8433665
A4: API - P.original - Edad e ingresos - GPT 5 | B4: 32.3 | C4: 27.4 | D4: 17.6 | E4: 14.6 | F4: 8.1 | G4: =AVERAGE((B4-$B$20)^2, (C4-$C$20)^2, (D4-$D$20)^2, (E4-$E$20)^2) -> 16.5175 | H4: =SQRT(G4) -> 4.0641727 | I4: =AVERAGE((B4-$B$20)^2, (C4-$C$20)^2, (D4-$D$20)^2, (E4-$E$20)^2,(F4-$F$20)^2) -> 18.832 | J4: =SQRT(I4) -> 4.3395852 | K4: =AVERAGE((B4-$B$2)^2,(C4-$C$2)^2,(D4-$D$2)^2,(E4-$E$2)^2,(F4-$F$2)^2) -> 3.852 | L4: =SQRT(K4) -> 1.9626513
A5: API - P.original - Edad - GPT 4 | B5: 21.7 | C5: 39 | D5: 11.3 | E5: 6.7 | F5: 21.3 | G5: =AVERAGE((B5-$B$20)^2, (C5-$C$20)^2, (D5-$D$20)^2, (E5-$E$20)^2) -> 72.6075 | H5: =SQRT(G5) -> 8.5210035 | I5: =AVERAGE((B5-$B$20)^2, (C5-$C$20)^2, (D5-$D$20)^2, (E5-$E$20)^2,(F5-$F$20)^2) -> 126.536 | J5: =SQRT(I5) -> 11.248822 | K5: =AVERAGE((B5-$B$2)^2,(C5-$C$2)^2,(D5-$D$2)^2,(E5-$E$2)^2,(F5-$F$2)^2) -> 102.82 | L5: =SQRT(K5) -> 10.14002
A6: API - P.original - Edad e ingresos - GPT 4 | B6: 21.7 | C6: 39 | D6: 11.3 | E6: 6.7 | F6: 21.3 | G6: =AVERAGE((B6-$B$20)^2, (C6-$C$20)^2, (D6-$D$20)^2, (E6-$E$20)^2) -> 72.6075 | H6: =SQRT(G6) -> 8.5210035 | I6: =AVERAGE((B6-$B$20)^2, (C6-$C$20)^2, (D6-$D$20)^2, (E6-$E$20)^2,(F6-$F$20)^2) -> 126.536 | J6: =SQRT(I6) -> 11.248822 | K6: =AVERAGE((B6-$B$2)^2,(C6-$C$2)^2,(D6-$D$2)^2,(E6-$E$2)^2,(F6-$F$2)^2) -> 102.82 | L6: =SQRT(K6) -> 10.14002
A7: API - P.original - Edad - GPT 4o-mini | B7: 33.4 | C7: 26.2 | D7: 14 | E7: 11.4 | F7: 14 | G7: =AVERAGE((B7-$B$20)^2, (C7-$C$20)^2, (D7-$D$20)^2, (E7-$E$20)^2) -> 16.085 | H7: =SQRT(G7) -> 4.0106109 | I7: =AVERAGE((B7-$B$20)^2, (C7-$C$20)^2, (D7-$D$20)^2, (E7-$E$20)^2,(F7-$F$20)^2) -> 37.956 | J7: =SQRT(I7) -> 6.1608441 | K7: =AVERAGE((B7-$B$2)^2,(C7-$C$2)^2,(D7-$D$2)^2,(E7-$E$2)^2,(F7-$F$2)^2) -> 8.28 | L7: =SQRT(K7) -> 2.8774989
A8: API - P.original - Edad e ingresos - GPT 4o-mini | B8: 29.5 | C8: 28.1 | D8: 12.5 | E8: 15.2 | F8: 14.7 | G8: =AVERAGE((B8-$B$20)^2, (C8-$C$20)^2, (D8-$D$20)^2, (E8-$E$20)^2) -> 23.7125 | H8: =SQRT(G8) -> 4.8695482 | I8: =AVERAGE((B8-$B$20)^2, (C8-$C$20)^2, (D8-$D$20)^2, (E8-$E$20)^2,(F8-$F$20)^2) -> 47.292 | J8: =SQRT(I8) -> 6.8769179 | K8: =AVERAGE((B8-$B$2)^2,(C8-$C$2)^2,(D8-$D$2)^2,(E8-$E$2)^2,(F8-$F$2)^2) -> 17.344 | L8: =SQRT(K8) -> 4.1646128
A9: API-GPT5-P.perfecto-edad | B9: 34.65 | C9: 27.84 | D9: 16.71 | E9: 12.67 | F9: 8.13 | G9: =AVERAGE((B9-$B$20)^2, (C9-$C$20)^2, (D9-$D$20)^2, (E9-$E$20)^2) -> 9.383775 | H9: =SQRT(G9) -> 3.0632948 | I9: =AVERAGE((B9-$B$20)^2, (C9-$C$20)^2, (D9-$D$20)^2, (E9-$E$20)^2,(F9-$F$20)^2) -> 13.1888 | J9: =SQRT(I9) -> 3.6316387 | K9: =AVERAGE((B9-$B$2)^2,(C9-$C$2)^2,(D9-$D$2)^2,(E9-$E$2)^2,(F9-$F$2)^2) -> 0.5528 | L9: =SQRT(K9) -> 0.74350521
A10: API - P.perfect - Edad e ingresos - GPT 5 | B10: 34.3 | C10: 28.1 | D10: 17.1 | E10: 12.8 | F10: 7.7 | G10: =AVERAGE((B10-$B$20)^2, (C10-$C$20)^2, (D10-$D$20)^2, (E10-$E$20)^2) -> 9.3625 | H10: =SQRT(G10) -> 3.0598203 | I10: =AVERAGE((B10-$B$20)^2, (C10-$C$20)^2, (D10-$D$20)^2, (E10-$E$20)^2,(F10-$F$20)^2) -> 12.292 | J10: =SQRT(I10) -> 3.5059949 | K10: =AVERAGE((B10-$B$2)^2,(C10-$C$2)^2,(D10-$D$2)^2,(E10-$E$2)^2,(F10-$F$2)^2) -> 0.992 | L10: =SQRT(K10) -> 0.99599197
A11: API - P.perfect - Edad - GPT 4 | B11: 23.4 | C11: 39.4 | D11: 12.3 | E11: 4.7 | F11: 20.2 | G11: =AVERAGE((B11-$B$20)^2, (C11-$C$20)^2, (D11-$D$20)^2, (E11-$E$20)^2) -> 66.525 | H11: =SQRT(G11) -> 8.1562859 | I11: =AVERAGE((B11-$B$20)^2, (C11-$C$20)^2, (D11-$D$20)^2, (E11-$E$20)^2,(F11-$F$20)^2) -> 113.772 | J11: =SQRT(I11) -> 10.666396 | K11: =AVERAGE((B11-$B$2)^2,(C11-$C$2)^2,(D11-$D$2)^2,(E11-$E$2)^2,(F11-$F$2)^2) -> 94.624 | L11: =SQRT(K11) -> 9.7274868
A12: API - P.perfect - Edad e ingresos - GPT 4 | B12: 22 | C12: 41 | D12: 12.3 | E12: 4.5 | F12: 20.2 | G12: =AVERAGE((B12-$B$20)^2, (C12-$C$20)^2, (D12-$D$20)^2, (E12-$E$20)^2) -> 82.215 | H12: =SQRT(G12) -> 9.0672488 | I12: =AVERAGE((B12-$B$20)^2, (C12-$C$20)^2, (D12-$D$20)^2, (E12-$E$20)^2,(F12-$F$20)^2) -> 126.324 | J12: =SQRT(I12) -> 11.239395 | K12: =AVERAGE((B12-$B$2)^2,(C12-$C$2)^2,(D12-$D$2)^2,(E12-$E$2)^2,(F12-$F$2)^2) -> 109.936 | L12: =SQRT(K12) -> 10.485037
A13: API-GPT4o-mini-P.perfecto-edad | B13: 35.55 | C13: 24.04 | D13: 14.7 | E13: 10.2 | F13: 15.51 | G13: =AVERAGE((B13-$B$20)^2, (C13-$C$20)^2, (D13-$D$20)^2, (E13-$E$20)^2) -> 23.453525 | H13: =SQRT(G13) -> 4.842884 | I13: =AVERAGE((B13-$B$20)^2, (C13-$C$20)^2, (D13-$D$20)^2, (E13-$E$20)^2,(F13-$F$20)^2) -> 51.07164 | J13: =SQRT(I13) -> 7.1464425 | K13: =AVERAGE((B13-$B$2)^2,(C13-$C$2)^2,(D13-$D$2)^2,(E13-$E$2)^2,(F13-$F$2)^2) -> 14.69404 | L13: =SQRT(K13) -> 3.8332806
A14: API-GPT4o-mini-P.perfecto-edad+ingresos | B14: 23.3 | C14: 35.67 | D14: 11.65 | E14: 16.68 | F14: 12.7 | G14: =AVERAGE((B14-$B$20)^2, (C14-$C$20)^2, (D14-$D$20)^2, (E14-$E$20)^2) -> 52.88595 | H14: =SQRT(G14) -> 7.2722727 | I14: =AVERAGE((B14-$B$20)^2, (C14-$C$20)^2, (D14-$D$20)^2, (E14-$E$20)^2,(F14-$F$20)^2) -> 61.91076 | J14: =SQRT(I14) -> 7.8683391 | K14: =AVERAGE((B14-$B$2)^2,(C14-$C$2)^2,(D14-$D$2)^2,(E14-$E$2)^2,(F14-$F$2)^2) -> 49.18516 | L14: =SQRT(K14) -> 7.0132132
... A19: CHAT - P.perfect - Edad e ingresos - GPT 5 | B19: 34.4 | C19: 29.3 | D19: 16.3 | E19: 13.8 | F19: 6.2 | G19: =AVERAGE((B19-$B$20)^2, (C19-$C$20)^2, (D19-$D$20)^2, (E19-$E$20)^2) -> 6.47 | H19: =SQRT(G19) -> 2.5436195 | I19: =AVERAGE((B19-$B$20)^2, (C19-$C$20)^2, (D19-$D$20)^2, (E19-$E$20)^2,(F19-$F$20)^2) -> 7.488 | J19: =SQRT(I19) -> 2.736421 | K19: =AVERAGE((B19-$B$2)^2,(C19-$C$2)^2,(D19-$D$2)^2,(E19-$E$2)^2,(F19-$F$2)^2) -> 1.908 | L19: =SQRT(K19) -> 1.3813037
A20: Electoral Results | B20: 36.4 | C20: 33.5 | D20: 15.3 | E20: 12 | F20: 2.8 | K20: =AVERAGE((B20-$B$2)^2,(C20-$C$2)^2,(D20-$D$2)^2,(E20-$E$2)^2,(F20-$F$2)^2) -> 12.22 | L20: =SQRT(K20) -> 3.4957117
A22: Survey | B22: PP | C22: PSOE | D22: VOX | E22: Sumar | F22: MSE | G22: RMSE
A23: Human Surveys | B23: 25 | C23: 20 | D23: 8 | E23: 8 | F23: =AVERAGE((B23-$B$41)^2, (C23-$C$41)^2, (D23-$D$41)^2, (E23-$E$41)^2) -> 1.5 | G23: =SQRT(F23) -> 1.2247449
A24: API - P.original - Edad - GPT 5 | B24: 22 | C24: 18 | D24: 12 | E24: 9 | F24: =AVERAGE((B24-$B$42)^2, (C24-$C$42)^2, (D24-$D$42)^2, (E24-$E$42)^2) -> 258.25 | G24: =SQRT(F24) -> 16.070159
A25: API - P.original - Edad e ingresos - GPT 5 | B25: 22 | C25: 18 | D25: 12 | E25: 9 | F25: =AVERAGE((B25-$B$42)^2, (C25-$C$42)^2, (D25-$D$42)^2, (E25-$E$42)^2) -> 258.25 | G25: =SQRT(F25) -> 16.070159
A26: API - P.original - Edad - GPT 4 | B26: 17 | C26: 31 | D26: 8 | E26: 5 | F26: =AVERAGE((B26-$B$42)^2, (C26-$C$42)^2, (D26-$D$42)^2, (E26-$E$42)^2) -> 334.75 | G26: =SQRT(F26) -> 18.296174
A27: API - P.original - Edad e ingresos - GPT 4 | B27: 17 | C27: 31 | D27: 8 | E27: 5 | F27: =AVERAGE((B27-$B$42)^2, (C27-$C$42)^2, (D27-$D$42)^2, (E27-$E$42)^2) -> 334.75 | G27: =SQRT(F27) -> 18.296174
A28: API - P.original - Edad - GPT 4o-mini | B28: 24 | C28: 19 | D28: 10 | E28: 8 | F28: =AVERAGE((B28-$B$42)^2, (C28-$C$42)^2, (D28-$D$42)^2, (E28-$E$42)^2) -> 275.25 | G28: =SQRT(F28) -> 16.59066
A29: API - P.original - Edad e ingresos - GPT 4o-mini | B29: 21 | C29: 20 | D29: 9 | E29: 11 | F29: =AVERAGE((B29-$B$42)^2, (C29-$C$42)^2, (D29-$D$42)^2, (E29-$E$42)^2) -> 260.75 | G29: =SQRT(F29) -> 16.147755
A30: API - P.perfecto - Edad - GPT 5 | B30: 23 | C30: 19 | D30: 11 | E30: 8 | F30: =AVERAGE((B30-$B$42)^2, (C30-$C$42)^2, (D30-$D$42)^2, (E30-$E$42)^2) -> 268.75 | G30: =SQRT(F30) -> 16.393596
A31: API - P.perfecto - Edad e ingresos - GPT 5 | B31: 23 | C31: 19 | D31: 11 | E31: 8 | F31: =AVERAGE((B31-$B$42)^2, (C31-$C$42)^2, (D31-$D$42)^2, (E31-$E$42)^2) -> 268.75 | G31: =SQRT(F31) -> 16.393596
A32: API - P.perfecto - Edad - GPT 4 | B32: 18 | C32: 31 | D32: 9 | E32: 3 | F32: =AVERAGE((B32-$B$42)^2, (C32-$C$42)^2, (D32-$D$42)^2, (E32-$E$42)^2) -> 343.75 | G32: =SQRT(F32) -> 18.540496
A33: API - P.perfecto - Edad e ingresos - GPT 4 | B33: 17 | C33: 32 | D33: 9 | E33: 3 | F33: =AVERAGE((B33-$B$42)^2, (C33-$C$42)^2, (D33-$D$42)^2, (E33-$E$42)^2) -> 350.75 | G33: =SQRT(F33) -> 18.728321
A34: API - P.perfecto - Edad - GPT 4o-mini | B34: 26 | C34: 17 | D34: 11 | E34: 7 | F34: =AVERAGE((B34-$B$42)^2, (C34-$C$42)^2, (D34-$D$42)^2, (E34-$E$42)^2) -> 283.75 | G34: =SQRT(F34) -> 16.844881
A35: API - P.perfecto - Edad e ingresos - GPT 4o-mini | B35: 16 | C35: 25 | D35: 8 | E35: 12 | F35: =AVERAGE((B35-$B$42)^2, (C35-$C$42)^2, (D35-$D$42)^2, (E35-$E$42)^2) -> 272.25 | G35: =SQRT(F35) -> 16.5
... A40: CHAT - P.perfecto - Edad e ingresos - GPT 5 | B40: 23 | C40: 19 | D40: 10 | E40: 9 | F40: =AVERAGE((B40-$B$42)^2, (C40-$C$42)^2, (D40-$D$42)^2, (E40-$E$42)^2) -> 267.75 | G40: =SQRT(F40) -> 16.363068
A41: Electoral Results | B41: 25 | C41: 21 | D41: 9 | E41: 6

Sheet Valencia - PIMLE
A1: Survey | B1: PP | C1: PSOE | D1: VOX | E1: Sumar | F1: Blank | G1: MSE | H1: RMSE | I1: MSE (+Blank) | J1: RMSE (+Blank) | K1: Emulation
A2: Human Surveys | B2: 32.3 | C2: 27.7 | D2: 16.5 | E2: 15 | F2: 8.5 | G2: 6.7 | H2: 2.5884358 | I2: 13.298 | J2: 3.6466423 | K2: MSE (+Blank) | L2: RMSE (+Blank)
A3: API - P.original - Edad - GPT 5 | B3: 31.33 | C3: 26.03 | D3: 17.54 | E3: 16.94 | F3: 8.16 | G3: =AVERAGE((B3-$B$20)^2, (C3-$C$20)^2, (D3-$D$20)^2, (E3-$E$20)^2) -> 14.00075 | H3: =SQRT(G3) -> 3.7417576 | I3: =AVERAGE((B3-$B$20)^2,(C3-$C$20)^2,(D3-$D$20)^2,(E3-$E$20)^2,(F3-$F$20)^2) -> 18.30492 | J3: =SQRT(I3) -> 4.2784249 | K3: =AVERAGE((B3-$B$2)^2,(C3-$C$2)^2,(D3-$D$2)^2,(E3-$E$2)^2,(F3-$F$2)^2) -> 1.73812 | L3: =SQRT(K3) -> 1.3183778
A4: API - P.original - Edad e ingresos - GPT 5 | B4: 32.27 | C4: 25.41 | D4: 17.47 | E4: 16.75 | F4: 8.1 | G4: =AVERAGE((B4-$B$20)^2, (C4-$C$20)^2, (D4-$D$20)^2, (E4-$E$20)^2) -> 14.3021 | H4: =SQRT(G4) -> 3.7818117 | I4: =AVERAGE((B4-$B$20)^2,(C4-$C$20)^2,(D4-$D$20)^2,(E4-$E$20)^2,(F4-$F$20)^2) -> 18.40368 | J4: =SQRT(I4) -> 4.289951 | K4: =AVERAGE((B4-$B$2)^2,(C4-$C$2)^2,(D4-$D$2)^2,(E4-$E$2)^2,(F4-$F$2)^2) -> 1.88168 | L4: =SQRT(K4) -> 1.3717434
A5: API - P.original - Edad - GPT 4 | B5: 22.5 | C5: 34.51 | D5: 10.9 | E5: 9.4 | F5: 22.7 | G5: =AVERAGE((B5-$B$20)^2, (C5-$C$20)^2, (D5-$D$20)^2, (E5-$E$20)^2) -> 54.062025 | H5: =SQRT(G5) -> 7.3526883 | I5: =AVERAGE((B5-$B$20)^2,(C5-$C$20)^2,(D5-$D$20)^2,(E5-$E$20)^2,(F5-$F$20)^2) -> 127.29962 | J5: =SQRT(I5) -> 11.282713 | K5: =AVERAGE((B5-$B$2)^2,(C5-$C$2)^2,(D5-$D$2)^2,(E5-$E$2)^2,(F5-$F$2)^2) -> 81.35522 | L5: =SQRT(K5) -> 9.0197129
A6: API - P.original - Edad e ingresos - GPT 4 | B6: 22.97 | C6: 34.62 | D6: 11.13 | E6: 9.54 | F6: 21.74 | G6: =AVERAGE((B6-$B$20)^2, (C6-$C$20)^2, (D6-$D$20)^2, (E6-$E$20)^2) -> 50.39895 | H6: =SQRT(G6) -> 7.0992218 | I6: =AVERAGE((B6-$B$20)^2,(C6-$C$20)^2,(D6-$D$20)^2,(E6-$E$20)^2,(F6-$F$20)^2) -> 116.68148 | J6: =SQRT(I6) -> 10.80192 | K6: =AVERAGE((B6-$B$2)^2,(C6-$C$2)^2,(D6-$D$2)^2,(E6-$E$2)^2,(F6-$F$2)^2) -> 73.77628 | L6: =SQRT(K6) -> 8.589312
A7: API - P.original - Edad - GPT 4o-mini | B7: 34.45 | C7: 24.45 | D7: 13.2 | E7: 13.66 | F7: 14.24 | G7: =AVERAGE((B7-$B$20)^2, (C7-$C$20)^2, (D7-$D$20)^2, (E7-$E$20)^2) -> 16.83665 | H7: =SQRT(G7) -> 4.1032487 | I7: =AVERAGE((B7-$B$20)^2,(C7-$C$20)^2,(D7-$D$20)^2,(E7-$E$20)^2,(F7-$F$20)^2) -> 42.46164 | J7: =SQRT(I7) -> 6.5162597 | K7: =AVERAGE((B7-$B$2)^2,(C7-$C$2)^2,(D7-$D$2)^2,(E7-$E$2)^2,(F7-$F$2)^2) -> 12.16364 | L7: =SQRT(K7) -> 3.487641
A8: API - P.original - Edad e ingresos - GPT 4o-mini | B8: 28.92 | C8: 27.37 | D8: 11.59 | E8: 18.34 | F8: 13.78 | G8: =AVERAGE((B8-$B$20)^2, (C8-$C$20)^2, (D8-$D$20)^2, (E8-$E$20)^2) -> 21.22125 | H8: =SQRT(G8) -> 4.6066528 | I8: =AVERAGE((B8-$B$20)^2,(C8-$C$20)^2,(D8-$D$20)^2,(E8-$E$20)^2,(F8-$F$20)^2) -> 43.79628 | J8: =SQRT(I8) -> 6.6178758 | K8: =AVERAGE((B8-$B$2)^2,(C8-$C$2)^2,(D8-$D$2)^2,(E8-$E$2)^2,(F8-$F$2)^2) -> 14.93508 | L8: =SQRT(K8) -> 3.8645931
A9: API - P.perfecto - Edad - GPT 5 | B9: 32.68 | C9: 25.35 | D9: 17.56 | E9: 16.11 | F9: 8.3 | G9: =AVERAGE((B9-$B$20)^2, (C9-$C$20)^2, (D9-$D$20)^2, (E9-$E$20)^2) -> 13.69465 | H9: =SQRT(G9) -> 3.7006283 | I9: =AVERAGE((B9-$B$20)^2,(C9-$C$20)^2,(D9-$D$20)^2,(E9-$E$20)^2,(F9-$F$20)^2) -> 18.39772 | J9: =SQRT(I9) -> 4.2892563 | K9: =AVERAGE((B9-$B$2)^2,(C9-$C$2)^2,(D9-$D$2)^2,(E9-$E$2)^2,(F9-$F$2)^2) -> 1.61252 | L9: =SQRT(K9) -> 1.2698504
A10: API - P.perfecto - Edad e ingresos - GPT 5 | B10: 33.6 | C10: 24.9 | D10: 17.78 | E10: 16 | F10: 7.72 | G10: =AVERAGE((B10-$B$20)^2, (C10-$C$20)^2, (D10-$D$20)^2, (E10-$E$20)^2) -> 14.6241 | H10: =SQRT(G10) -> 3.824147 | I10: =AVERAGE((B10-$B$20)^2,(C10-$C$20)^2,(D10-$D$20)^2,(E10-$E$20)^2,(F10-$F$20)^2) -> 17.79336 | J10: =SQRT(I10) -> 4.2182176 | K10: =AVERAGE((B10-$B$2)^2,(C10-$C$2)^2,(D10-$D$2)^2,(E10-$E$2)^2,(F10-$F$2)^2) -> 2.55536 | L10: =SQRT(K10) -> 1.5985493
A11: API - P.perfecto - Edad - GPT 4 | B11: 24.99 | C11: 33.9 | D11: 11.23 | E11: 5.55 | F11: 24.33 | G11: =AVERAGE((B11-$B$20)^2, (C11-$C$20)^2, (D11-$D$20)^2, (E11-$E$20)^2) -> 53.637875 | H11: =SQRT(G11) -> 7.3237883 | I11: =AVERAGE((B11-$B$20)^2,(C11-$C$20)^2,(D11-$D$20)^2,(E11-$E$20)^2,(F11-$F$20)^2) -> 140.85768 | J11: =SQRT(I11) -> 11.868348 | K11: =AVERAGE((B11-$B$2)^2,(C11-$C$2)^2,(D11-$D$2)^2,(E11-$E$2)^2,(F11-$F$2)^2) -> 91.90808 | L11: =SQRT(K11) -> 9.5868702
A12: API - P.perfecto - Edad e ingresos - GPT 4 | B12: 23.48 | C12: 35.39 | D12: 10.26 | E12: 6.18 | F12: 24.69 | G12: =AVERAGE((B12-$B$20)^2, (C12-$C$20)^2, (D12-$D$20)^2, (E12-$E$20)^2) -> 63.048625 | H12: =SQRT(G12) -> 7.9403164 | I12: =AVERAGE((B12-$B$20)^2,(C12-$C$20)^2,(D12-$D$20)^2,(E12-$E$20)^2,(F12-$F$20)^2) -> 151.59892 | J12: =SQRT(I12) -> 12.312551 | K12: =AVERAGE((B12-$B$2)^2,(C12-$C$2)^2,(D12-$D$2)^2,(E12-$E$2)^2,(F12-$F$2)^2) -> 103.15492 | L12: =SQRT(K12) -> 10.156521
A13: API - P.perfecto - Edad - GPT 4o-mini | B13: 24.16 | C13: 31.67 | D13: 12.29 | E13: 16.71 | F13: 15.17 | G13: =AVERAGE((B13-$B$20)^2, (C13-$C$20)^2, (D13-$D$20)^2, (E13-$E$20)^2) -> 32.360175 | H13: =SQRT(G13) -> 5.6886004 | I13: =AVERAGE((B13-$B$20)^2,(C13-$C$20)^2,(D13-$D$20)^2,(E13-$E$20)^2,(F13-$F$20)^2) -> 59.53232 | J13: =SQRT(I13) -> 7.715719 | K13: =AVERAGE((B13-$B$2)^2,(C13-$C$2)^2,(D13-$D$2)^2,(E13-$E$2)^2,(F13-$F$2)^2) -> 29.43152 | L13: =SQRT(K13) -> 5.4250825
A14: API - P.perfecto - Edad e ingresos - GPT 4o-mini | B14: 25.37 | C14: 31.33 | D14: 12.26 | E14: 16.41 | F14: 14.62 | G14: =AVERAGE((B14-$B$20)^2, (C14-$C$20)^2, (D14-$D$20)^2, (E14-$E$20)^2) -> 26.177875 | H14: =SQRT(G14) -> 5.1164319 | I14: =AVERAGE((B14-$B$20)^2,(C14-$C$20)^2,(D14-$D$20)^2,(E14-$E$20)^2,(F14-$F$20)^2) -> 51.79358 | J14: =SQRT(I14) -> 7.1967757 | K14: =AVERAGE((B14-$B$2)^2,(C14-$C$2)^2,(D14-$D$2)^2,(E14-$E$2)^2,(F14-$F$2)^2) -> 23.72438 | L14: =SQRT(K14) -> 4.8707679
... A19: CHAT - P.perfecto - Edad e ingresos - GPT 5 | B19: 34.4 | C19: 27.1 | D19: 15.6 | E19: 16 | F19: 7 | G19: =AVERAGE((B19-$B$20)^2, (C19-$C$20)^2, (D19-$D$20)^2, (E19-$E$20)^2) -> 6.475 | H19: =SQRT(G19) -> 2.5446021 | I19: =AVERAGE((B19-$B$20)^2,(C19-$C$20)^2,(D19-$D$20)^2,(E19-$E$20)^2,(F19-$F$20)^2) -> 9.788 | J19: =SQRT(I19) -> 3.128578 | K19: =AVERAGE((B19-$B$2)^2,(C19-$C$2)^2,(D19-$D$2)^2,(E19-$E$2)^2,(F19-$F$2)^2) -> 1.766 | L19: =SQRT(K19) -> 1.3289093
A20: Electoral Results | B20: 34.9 | C20: 32.1 | D20: 15.7 | E20: 15.2 | F20: 2.2 | K20: =AVERAGE((B20-$B$2)^2,(C20-$C$2)^2,(D20-$D$2)^2,(E20-$E$2)^2,(F20-$F$2)^2) -> 13.298 | L20: =SQRT(K20) -> 3.6466423
A22: Survey | B22: PP | C22: PSOE | D22: VOX | E22: Sumar | F22: MSE | G22: RMSE
A23: Human Surveys | B23: 12 | C23: 10 | D23: 6 | E23: 5 | F23: =AVERAGE((B23-$B$41)^2, (C23-$C$41)^2, (D23-$D$41)^2, (E23-$E$41)^2) -> 1 | G23: =SQRT(F23) -> 1
A24: API - P.original - Edad - GPT 5 | B24: 12 | C24: 9 | D24: 6 | E24: 6 | F24: =AVERAGE((B24-$B$41)^2, (C24-$C$41)^2, (D24-$D$41)^2, (E24-$E$41)^2) -> 2.5 | G24: =SQRT(F24) -> 1.5811388
A25: API - P.original - Edad e ingresos - GPT 5 | B25: 12 | C25: 9 | D25: 6 | E25: 6 | F25: =AVERAGE((B25-$B$41)^2, (C25-$C$41)^2, (D25-$D$41)^2, (E25-$E$41)^2) -> 2.5 | G25: =SQRT(F25) -> 1.5811388
A26: API - P.original - Edad - GPT 4 | B26: 10 | C26: 15 | D26: 4 | E26: 4 | F26: =AVERAGE((B26-$B$41)^2, (C26-$C$41)^2, (D26-$D$41)^2, (E26-$E$41)^2) -> 6.5 | G26: =SQRT(F26) -> 2.5495098
A27: API - P.original - Edad e ingresos - GPT 4 | B27: 10 | C27: 15 | D27: 4 | E27: 4 | F27: =AVERAGE((B27-$B$41)^2, (C27-$C$41)^2, (D27-$D$41)^2, (E27-$E$41)^2) -> 6.5 | G27: =SQRT(F27) -> 2.5495098
A28: API - P.original - Edad - GPT 4o-mini | B28: 14 | C28: 9 | D28: 5 | E28: 5 | F28: =AVERAGE((B28-$B$41)^2, (C28-$C$41)^2, (D28-$D$41)^2, (E28-$E$41)^2) -> 1.5 | G28: =SQRT(F28) -> 1.2247449
A29: API - P.original - Edad e ingresos - GPT 4o-mini | B29: 11 | C29: 11 | D29: 4 | E29: 7 | F29: =AVERAGE((B29-$B$41)^2, (C29-$C$41)^2, (D29-$D$41)^2, (E29-$E$41)^2) -> 3.5 | G29: =SQRT(F29) -> 1.8708287
A30: API - P.perfecto - Edad - GPT 5 | B30: 12 | C30: 9 | D30: 6 | E30: 6 | F30: =AVERAGE((B30-$B$41)^2, (C30-$C$41)^2, (D30-$D$41)^2, (E30-$E$41)^2) -> 2.5 | G30: =SQRT(F30) -> 1.5811388
A31: API - P.perfecto - Edad e ingresos - GPT 5 | B31: 12 | C31: 9 | D31: 6 | E31: 6 | F31: =AVERAGE((B31-$B$41)^2, (C31-$C$41)^2, (D31-$D$41)^2, (E31-$E$41)^2) -> 2.5 | G31: =SQRT(F31) -> 1.5811388
A32: API - P.perfecto - Edad - GPT 4 | B32: 11 | C32: 15 | D32: 5 | E32: 2 | F32: =AVERAGE((B32-$B$41)^2, (C32-$C$41)^2, (D32-$D$41)^2, (E32-$E$41)^2) -> 6 | G32: =SQRT(F32) -> 2.4494897
A33: API - P.perfecto - Edad e ingresos - GPT 4 | B33: 11 | C33: 16 | D33: 4 | E33: 2 | F33: =AVERAGE((B33-$B$41)^2, (C33-$C$41)^2, (D33-$D$41)^2, (E33-$E$41)^2) -> 8.5 | G33: =SQRT(F33) -> 2.9154759
A34: API - P.perfecto - Edad - GPT 4o-mini | B34: 9 | C34: 13 | D34: 5 | E34: 6 | F34: =AVERAGE((B34-$B$41)^2, (C34-$C$41)^2, (D34-$D$41)^2, (E34-$E$41)^2) -> 6 | G34: =SQRT(F34) -> 2.4494897
... A40: CHAT - P.perfecto - Edad e ingresos - GPT 5 | B40: 12 | C40: 10 | D40: 5 | E40: 6 | F40: =AVERAGE((B40-$B$41)^2, (C40-$C$41)^2, (D40-$D$41)^2, (E40-$E$41)^2) -> 1.5 | G40: =SQRT(F40) -> 1.2247449
A41: Electoral Results | B41: 13 | C41: 11 | D41: 5 | E41: 4

Sheet Madrid - Complete
B1: PP | C1: PSOE | D1: Vox | E1: Sumar | F1: Blank | H1: MSE (+Blank) | I1: RMSE (+Blank) | K1: MSE | L1: RMSE
A2: Real Results | B2: 40.2 | C2: 27.7 | D2: 13.9 | E2: 15.3 | F2: 2.9
A3: NAIVE | H3: MSE (+Blank) | I3: RMSE (+Blank) | K3: MSE | L3: RMSE
A4: API - P.original - Edad - GPT 5 | B4: 34 | C4: 25 | D4: 16.7 | E4: 16.4 | F4: 7.8 | H4: =AVERAGE((B4-$B$2)^2,(C4-$C$2)^2,(D4-$D$2)^2,(E4-$E$2)^2,(F4-$F$2)^2) -> 15.758 | I4: =SQRT(H4) -> 3.9696347 | K4: =AVERAGE((B4-$B$2)^2,(C4-$C$2)^2,(D4-$D$2)^2,(E4-$E$2)^2) -> 13.695 | L4: =SQRT(K4) -> 3.7006756
A5: API - P.original - Edad e ingresos - GPT 5 | B5: 33.9 | C5: 24.9 | D5: 16.4 | E5: 17 | F5: 7.8 | H5: =AVERAGE((B5-$B$2)^2,(C5-$C$2)^2,(D5-$D$2)^2,(E5-$E$2)^2,(F5-$F$2)^2) -> 16.136 | I5: =SQRT(H5) -> 4.016964 | K5: =AVERAGE((B5-$B$2)^2,(C5-$C$2)^2,(D5-$D$2)^2,(E5-$E$2)^2) -> 14.1675 | L5: =SQRT(K5) -> 3.763974
A6: API - P.original - Edad - GPT 4 | B6: 24.9 | C6: 33.1 | D6: 11.3 | E6: 9.8 | F6: 21 | H6: =AVERAGE((B6-$B$2)^2,(C6-$C$2)^2,(D6-$D$2)^2,(E6-$E$2)^2,(F6-$F$2)^2) -> 125.574 | I6: =SQRT(H6) -> 11.205981 | K6: =AVERAGE((B6-$B$2)^2,(C6-$C$2)^2,(D6-$D$2)^2,(E6-$E$2)^2) -> 75.065 | L6: =SQRT(K6) -> 8.664006
A7: API - P.original - Edad e ingresos - GPT 4 | B7: 24.3 | C7: 34.9 | D7: 10.8 | E7: 7.9 | F7: 22.1 | H7: =AVERAGE((B7-$B$2)^2,(C7-$C$2)^2,(D7-$D$2)^2,(E7-$E$2)^2,(F7-$F$2)^2) -> 147.532 | I7: =SQRT(H7) -> 12.146275 | K7: =AVERAGE((B7-$B$2)^2,(C7-$C$2)^2,(D7-$D$2)^2,(E7-$E$2)^2) -> 92.255 | L7: =SQRT(K7) -> 9.6049466
A8: API - P.original - Edad - GPT 4o-mini | B8: 33 | C8: 25.7 | D8: 13.3 | E8: 13.4 | F8: 14.7 | H8: =AVERAGE((B8-$B$2)^2,(C8-$C$2)^2,(D8-$D$2)^2,(E8-$E$2)^2,(F8-$F$2)^2) -> 39.81 | I8: =SQRT(H8) -> 6.3095166 | K8: =AVERAGE((B8-$B$2)^2,(C8-$C$2)^2,(D8-$D$2)^2,(E8-$E$2)^2) -> 14.9525 | L8: =SQRT(K8) -> 3.8668463
A9: API - P.original - Edad e ingresos - GPT 4o-mini | B9: 29.1 | C9: 27.7 | D9: 11.4 | E9: 17.3 | F9: 14.5 | H9: =AVERAGE((B9-$B$2)^2,(C9-$C$2)^2,(D9-$D$2)^2,(E9-$E$2)^2,(F9-$F$2)^2) -> 53.604 | I9: =SQRT(H9) -> 7.3214753 | K9: =AVERAGE((B9-$B$2)^2,(C9-$C$2)^2,(D9-$D$2)^2,(E9-$E$2)^2) -> 33.365 | L9: =SQRT(K9) -> 5.7762445
A10: API - P.perfect - Edad - GPT 5 | B10: 36.57 | C10: 23.4 | D10: 16.7 | E10: 15.38 | F10: 7.95 | H10: =AVERAGE((B10-$B$2)^2,(C10-$C$2)^2,(D10-$D$2)^2,(E10-$E$2)^2,(F10-$F$2)^2) -> 13.00316 | I10: =SQRT(H10) -> 3.6059895 | K10: =AVERAGE((B10-$B$2)^2,(C10-$C$2)^2,(D10-$D$2)^2,(E10-$E$2)^2) -> 9.878325 | L10: =SQRT(K10) -> 3.1429803
A11: API - P.perfect - Edad e ingresos - GPT 5 | B11: 37.29 | C11: 23.11 | D11: 17 | E11: 15.17 | F11: 7.45 | H11: =AVERAGE((B11-$B$2)^2,(C11-$C$2)^2,(D11-$D$2)^2,(E11-$E$2)^2,(F11-$F$2)^2) -> 11.97312 | I11: =SQRT(H11) -> 3.4602196 | K11: =AVERAGE((B11-$B$2)^2,(C11-$C$2)^2,(D11-$D$2)^2,(E11-$E$2)^2) -> 9.790775 | L11: =SQRT(K11) -> 3.1290214
A12: API - P.perfect - Edad - GPT 4 | B12: 29.05 | C12: 33.02 | D12: 12.33 | E12: 5.42 | F12: 20.18 | H12: =AVERAGE((B12-$B$2)^2,(C12-$C$2)^2,(D12-$D$2)^2,(E12-$E$2)^2,(F12-$F$2)^2) -> 110.26052 | I12: =SQRT(H12) -> 10.500501 | K12: =AVERAGE((B12-$B$2)^2,(C12-$C$2)^2,(D12-$D$2)^2,(E12-$E$2)^2) -> 63.17605 | L12: =SQRT(K12) -> 7.9483363
A13: API - P.perfect - Edad e ingresos - GPT 4 | B13: 27.61 | C13: 32.49 | D13: 12.06 | E13: 5.43 | F13: 22.41 | H13: =AVERAGE((B13-$B$2)^2,(C13-$C$2)^2,(D13-$D$2)^2,(E13-$E$2)^2,(F13-$F$2)^2) -> 132.57896 | I13: =SQRT(H13) -> 11.514294 | K13: =AVERAGE((B13-$B$2)^2,(C13-$C$2)^2,(D13-$D$2)^2,(E13-$E$2)^2) -> 70.563675 | L13: =SQRT(K13) -> 8.4002187
A14: API - P.perfect - Edad - GPT 4o-mini | B14: 30.94 | C14: 25.93 | D14: 13.18 | E14: 14.32 | F14: 15.63 | H14: =AVERAGE((B14-$B$2)^2,(C14-$C$2)^2,(D14-$D$2)^2,(E14-$E$2)^2,(F14-$F$2)^2) -> 50.48244 | I14: =SQRT(H14) -> 7.1050996 | K14: =AVERAGE((B14-$B$2)^2,(C14-$C$2)^2,(D14-$D$2)^2,(E14-$E$2)^2) -> 22.589825 | L14: =SQRT(K14) -> 4.7528754
A15: API - P.perfect - Edad e ingresos - GPT 4o-mini | B15: 27.62 | C15: 29.74 | D15: 12.73 | E15: 15.37 | F15: 14.55 | H15: =AVERAGE((B15-$B$2)^2,(C15-$C$2)^2,(D15-$D$2)^2,(E15-$E$2)^2,(F15-$F$2)^2) -> 59.90286 | I15: =SQRT(H15) -> 7.7396938 | K15: =AVERAGE((B15-$B$2)^2,(C15-$C$2)^2,(D15-$D$2)^2,(E15-$E$2)^2) -> 40.94795 | L15: =SQRT(K15) -> 6.3990585
... A22: CHAT - P.perfecto - Edad e ingresos GPT 4o | B22: 31.66 | C22: 27.67 | D22: 12.39 | E22: 19.78 | F22: 8.51 | H22: =AVERAGE((B22-$B$2)^2,(C22-$C$2)^2,(D22-$D$2)^2,(E22-$E$2)^2,(F22-$F$2)^2) -> 25.35102 | I22: =SQRT(H22) -> 5.0349796 | K22: =AVERAGE((B22-$B$2)^2,(C22-$C$2)^2,(D22-$D$2)^2,(E22-$E$2)^2) -> 23.82075 | L22: =SQRT(K22) -> 4.8806506
A23: MOS | H23: MSE (+Blank) | I23: RMSE (+Blank) | K23: MSE | L23: RMSE
A24: API - P.original - Edad - GPT 5 | B24: 34.1 | C24: 25 | D24: 16.8 | E24: 16.4 | F24: 7.8 | H24: =AVERAGE((B24-$B$2)^2,(C24-$C$2)^2,(D24-$D$2)^2,(E24-$E$2)^2,(F24-$F$2)^2) -> 15.626 | I24: =SQRT(H24) -> 3.9529736 | K24: =AVERAGE((B24-$B$2)^2,(C24-$C$2)^2,(D24-$D$2)^2,(E24-$E$2)^2) -> 13.53 | L24: =SQRT(K24) -> 3.6783148
A25: API - P.original - Edad e ingresos - GPT 5 | B25: 33.8 | C25: 25 | D25: 16.4 | E25: 17 | F25: 7.8 | H25: =AVERAGE((B25-$B$2)^2,(C25-$C$2)^2,(D25-$D$2)^2,(E25-$E$2)^2,(F25-$F$2)^2) -> 16.28 | I25: =SQRT(H25) -> 4.0348482 | K25: =AVERAGE((B25-$B$2)^2,(C25-$C$2)^2,(D25-$D$2)^2,(E25-$E$2)^2) -> 14.3475 | L25: =SQRT(K25) -> 3.7878094
A26: API - P.original - Edad - GPT 4 | B26: 25 | C26: 33.2 | D26: 11.3 | E26: 9.8 | F26: 20.7 | H26: =AVERAGE((B26-$B$2)^2,(C26-$C$2)^2,(D26-$D$2)^2,(E26-$E$2)^2,(F26-$F$2)^2) -> 123.028 | I26: =SQRT(H26) -> 11.091799 | K26: =AVERAGE((B26-$B$2)^2,(C26-$C$2)^2,(D26-$D$2)^2,(E26-$E$2)^2) -> 74.575 | L26: =SQRT(K26) -> 8.6356818
A27: API - P.original - Edad e ingresos - GPT 4 | B27: 24.3 | C27: 35 | D27: 10.8 | E27: 8.1 | F27: 21.8 | H27: =AVERAGE((B27-$B$2)^2,(C27-$C$2)^2,(D27-$D$2)^2,(E27-$E$2)^2,(F27-$F$2)^2) -> 144.952 | I27: =SQRT(H27) -> 12.039601 | K27: =AVERAGE((B27-$B$2)^2,(C27-$C$2)^2,(D27-$D$2)^2,(E27-$E$2)^2) -> 91.8875 | L27: =SQRT(K27) -> 9.5857968
A28: API - P.original - Edad - GPT 4o-mini | B28: 32.8 | C28: 25.6 | D28: 13.2 | E28: 13.7 | F28: 14.7 | H28: =AVERAGE((B28-$B$2)^2,(C28-$C$2)^2,(D28-$D$2)^2,(E28-$E$2)^2,(F28-$F$2)^2) -> 40.292 | I28: =SQRT(H28) -> 6.347598 | K28: =AVERAGE((B28-$B$2)^2,(C28-$C$2)^2,(D28-$D$2)^2,(E28-$E$2)^2) -> 15.555 | L28: =SQRT(K28) -> 3.9439828
A29: API - P.original - Edad e ingresos - GPT 4o-mini | B29: 28.9 | C29: 27.6 | D29: 11.5 | E29: 17.5 | F29: 14.5 | H29: =AVERAGE((B29-$B$2)^2,(C29-$C$2)^2,(D29-$D$2)^2,(E29-$E$2)^2,(F29-$F$2)^2) -> 54.572 | I29: =SQRT(H29) -> 7.3872864 | K29: =AVERAGE((B29-$B$2)^2,(C29-$C$2)^2,(D29-$D$2)^2,(E29-$E$2)^2) -> 34.575 | L29: =SQRT(K29) -> 5.880051
A30: API - P.perfect - Edad - GPT 5 | B30: 36.65 | C30: 23.38 | D30: 16.74 | E30: 15.31 | F30: 7.91 | H30: =AVERAGE((B30-$B$2)^2,(C30-$C$2)^2,(D30-$D$2)^2,(E30-$E$2)^2,(F30-$F$2)^2) -> 12.88614 | I30: =SQRT(H30) -> 3.589727 | K30: =AVERAGE((B30-$B$2)^2,(C30-$C$2)^2,(D30-$D$2)^2,(E30-$E$2)^2) -> 9.83265 | L30: =SQRT(K30) -> 3.1357057
A31: API - P.perfect - Edad e ingresos - GPT 5 | B31: 37.34 | C31: 23.08 | D31: 17.02 | E31: 15.14 | F31: 7.42 | H31: =AVERAGE((B31-$B$2)^2,(C31-$C$2)^2,(D31-$D$2)^2,(E31-$E$2)^2,(F31-$F$2)^2) -> 11.94288 | I31: =SQRT(H31) -> 3.4558472 | K31: =AVERAGE((B31-$B$2)^2,(C31-$C$2)^2,(D31-$D$2)^2,(E31-$E$2)^2) -> 9.821 | L31: =SQRT(K31) -> 3.1338475
A32: API - P.perfect - Edad - GPT 4 | B32: 28.76 | C32: 33.26 | D32: 12.28 | E32: 5.4 | F32: 20.3 | H32: =AVERAGE((B32-$B$2)^2,(C32-$C$2)^2,(D32-$D$2)^2,(E32-$E$2)^2,(F32-$F$2)^2) -> 113.03632 | I32: =SQRT(H32) -> 10.631854 | K32: =AVERAGE((B32-$B$2)^2,(C32-$C$2)^2,(D32-$D$2)^2,(E32-$E$2)^2) -> 65.6054 | L32: =SQRT(K32) -> 8.099716
A33: API - P.perfect - Edad e ingresos - GPT 4 | B33: 27.75 | C33: 32.3 | D33: 12.2 | E33: 5.57 | F33: 22.18 | H33: =AVERAGE((B33-$B$2)^2,(C33-$C$2)^2,(D33-$D$2)^2,(E33-$E$2)^2,(F33-$F$2)^2) -> 129.08876 | I33: =SQRT(H33) -> 11.361723 | K33: =AVERAGE((B33-$B$2)^2,(C33-$C$2)^2,(D33-$D$2)^2,(E33-$E$2)^2) -> 68.43135 | L33: =SQRT(K33) -> 8.2723243
A34: API - P.perfect - Edad - GPT 4o-mini | B34: 30.44 | C34: 25.62 | D34: 12.95 | E34: 15.31 | F34: 15.69 | H34: =AVERAGE((B34-$B$2)^2,(C34-$C$2)^2,(D34-$D$2)^2,(E34-$E$2)^2,(F34-$F$2)^2) -> 52.81414 | I34: =SQRT(H34) -> 7.2673338 | K34: =AVERAGE((B34-$B$2)^2,(C34-$C$2)^2,(D34-$D$2)^2,(E34-$E$2)^2) -> 25.12165 | L34: =SQRT(K34) -> 5.0121502
A35: API - P.perfect - Edad e ingresos - GPT 4o-mini | B35: 27.28 | C35: 29.66 | D35: 12.57 | E35: 15.74 | F35: 14.75 | H35: =AVERAGE((B35-$B$2)^2,(C35-$C$2)^2,(D35-$D$2)^2,(E35-$E$2)^2,(F35-$F$2)^2) -> 62.6306 | I35: =SQRT(H35) -> 7.9139497 | K35: =AVERAGE((B35-$B$2)^2,(C35-$C$2)^2,(D35-$D$2)^2,(E35-$E$2)^2) -> 43.182625 | L35: =SQRT(K35) -> 6.5713488
... A42: CHAT - P.perfecto - Edad e ingresos GPT 4o | B42: 31.84 | C42: 27.76 | D42: 12.51 | E42: 19.44 | F42: 8.45 | H42: =AVERAGE((B42-$B$2)^2,(C42-$C$2)^2,(D42-$D$2)^2,(E42-$E$2)^2,(F42-$F$2)^2) -> 23.95348 | I42: =SQRT(H42) -> 4.8942293 | K42: =AVERAGE((B42-$B$2)^2,(C42-$C$2)^2,(D42-$D$2)^2,(E42-$E$2)^2) -> 22.241225 | L42: =SQRT(K42) -> 4.7160603
A43: MLE | H43: MSE (+Blank) | I43: RMSE (+Blank) | K43: MSE | L43: RMSE
A44: API - P.original - Edad - GPT 5 | B44: 34.2 | C44: 25 | D44: 16.8 | E44: 16.2 | F44: 7.8 | H44: =AVERAGE((B44-$B$2)^2,(C44-$C$2)^2,(D44-$D$2)^2,(E44-$E$2)^2,(F44-$F$2)^2) -> 15.304 | I44: =SQRT(H44) -> 3.9120327 | K44: =AVERAGE((B44-$B$2)^2,(C44-$C$2)^2,(D44-$D$2)^2,(E44-$E$2)^2) -> 13.1275 | L44: =SQRT(K44) -> 3.6231892
A45: API - P.original - Edad e ingresos - GPT 5 | B45: 34 | C45: 24.9 | D45: 16.4 | E45: 17 | F45: 7.8 | H45: =AVERAGE((B45-$B$2)^2,(C45-$C$2)^2,(D45-$D$2)^2,(E45-$E$2)^2,(F45-$F$2)^2) -> 15.886 | I45: =SQRT(H45) -> 3.9857245 | K45: =AVERAGE((B45-$B$2)^2,(C45-$C$2)^2,(D45-$D$2)^2,(E45-$E$2)^2) -> 13.855 | L45: =SQRT(K45) -> 3.7222305
A46: API - P.original - Edad - GPT 4 | B46: 24.9 | C46: 33 | D46: 11.2 | E46: 10 | F46: 21 | H46: =AVERAGE((B46-$B$2)^2,(C46-$C$2)^2,(D46-$D$2)^2,(E46-$E$2)^2,(F46-$F$2)^2) -> 125.034 | I46: =SQRT(H46) -> 11.18186 | K46: =AVERAGE((B46-$B$2)^2,(C46-$C$2)^2,(D46-$D$2)^2,(E46-$E$2)^2) -> 74.39 | L46: =SQRT(K46) -> 8.6249638
A47: API - P.original - Edad e ingresos - GPT 4 | B47: 24.5 | C47: 34.5 | D47: 10.9 | E47: 8.5 | F47: 21.6 | H47: =AVERAGE((B47-$B$2)^2,(C47-$C$2)^2,(D47-$D$2)^2,(E47-$E$2)^2,(F47-$F$2)^2) -> 139.532 | I47: =SQRT(H47) -> 11.812366 | K47: =AVERAGE((B47-$B$2)^2,(C47-$C$2)^2,(D47-$D$2)^2,(E47-$E$2)^2) -> 86.9925 | L47: =SQRT(K47) -> 9.326977
A48: API - P.original - Edad - GPT 4o-mini | B48: 33.1 | C48: 25.7 | D48: 13.6 | E48: 13 | F48: 14.6 | H48: =AVERAGE((B48-$B$2)^2,(C48-$C$2)^2,(D48-$D$2)^2,(E48-$E$2)^2,(F48-$F$2)^2) -> 39.336 | I48: =SQRT(H48) -> 6.2718418 | K48: =AVERAGE((B48-$B$2)^2,(C48-$C$2)^2,(D48-$D$2)^2,(E48-$E$2)^2) -> 14.9475 | L48: =SQRT(K48) -> 3.8661997
A49: API - P.original - Edad e ingresos - GPT 4o-mini | B49: 29 | C49: 27.7 | D49: 11.6 | E49: 17.4 | F49: 14.3 | H49: =AVERAGE((B49-$B$2)^2,(C49-$C$2)^2,(D49-$D$2)^2,(E49-$E$2)^2,(F49-$F$2)^2) -> 53.02 | I49: =SQRT(H49) -> 7.2814834 | K49: =AVERAGE((B49-$B$2)^2,(C49-$C$2)^2,(D49-$D$2)^2,(E49-$E$2)^2) -> 33.785 | L49: =SQRT(K49) -> 5.8124866
A50: API - P.perfect - Edad - GPT 5 | B50: 36.64 | C50: 23.39 | D50: 16.7 | E50: 15.3 | F50: 7.96 | H50: =AVERAGE((B50-$B$2)^2,(C50-$C$2)^2,(D50-$D$2)^2,(E50-$E$2)^2,(F50-$F$2)^2) -> 12.93866 | I50: =SQRT(H50) -> 3.5970349 | K50: =AVERAGE((B50-$B$2)^2,(C50-$C$2)^2,(D50-$D$2)^2,(E50-$E$2)^2) -> 9.772425 | L50: =SQRT(K50) -> 3.1260878
A51: API - P.perfect - Edad e ingresos - GPT 5 | B51: 37.54 | C51: 22.94 | D51: 17.05 | E51: 15.06 | F51: 7.41 | H51: =AVERAGE((B51-$B$2)^2,(C51-$C$2)^2,(D51-$D$2)^2,(E51-$E$2)^2,(F51-$F$2)^2) -> 12.01068 | I51: =SQRT(H51) -> 3.4656428 | K51: =AVERAGE((B51-$B$2)^2,(C51-$C$2)^2,(D51-$D$2)^2,(E51-$E$2)^2) -> 9.928325 | L51: =SQRT(K51) -> 3.1509245
A52: API - P.perfect - Edad - GPT 4 | B52: 28.77 | C52: 32.98 | D52: 12.46 | E52: 5.62 | F52: 20.17 | H52: =AVERAGE((B52-$B$2)^2,(C52-$C$2)^2,(D52-$D$2)^2,(E52-$E$2)^2,(F52-$F$2)^2) -> 110.51044 | I52: =SQRT(H52) -> 10.512395 | K52: =AVERAGE((B52-$B$2)^2,(C52-$C$2)^2,(D52-$D$2)^2,(E52-$E$2)^2) -> 63.574825 | L52: =SQRT(K52) -> 7.9733823
...

Sheet Andalusia - Complete
B1: PP | C1: PSOE | D1: Vox | E1: Sumar | F1: Blank | H1: MSE (+Blank) | I1: RMSE (+Blank) | K1: MSE | L1: RMSE
A2: Real Results | B2: 36.4 | C2: 33.5 | D2: 15.3 | E2: 12 | F2: 2.8
A3: NAIVE | H3: MSE (+Blank) | I3: RMSE (+Blank) | K3: MSE | L3: RMSE
A4: API-GPT5-P.original-edad | B4: 32.47 | C4: 27.44 | D4: 17.55 | E4: 14.37 | F4: 8.17 | H4: =AVERAGE((B4-$B$2)^2,(C4-$C$2)^2,(D4-$D$2)^2,(E4-$E$2)^2,(F4-$F$2)^2) -> 18.33696 | I4: =SQRT(H4) -> 4.2821677 | K4: =AVERAGE((B4-$B$2)^2,(C4-$C$2)^2,(D4-$D$2)^2,(E4-$E$2)^2) -> 15.711975 | L4: =SQRT(K4) -> 3.9638334
A5: API-GPT4o-mini-P.original-edad | B5: 33.56 | C5: 26.24 | D5: 13.93 | E5: 11.36 | F5: 14.91 | H5: =AVERAGE((B5-$B$2)^2,(C5-$C$2)^2,(D5-$D$2)^2,(E5-$E$2)^2,(F5-$F$2)^2) -> 41.94236 | I5: =SQRT(H5) -> 6.4762921 | K5: =AVERAGE((B5-$B$2)^2,(C5-$C$2)^2,(D5-$D$2)^2,(E5-$E$2)^2) -> 15.764925 | L5: =SQRT(K5) -> 3.9705069
A6: API-GPT4-P.original-edad | B6: 21.77 | C6: 39.19 | D6: 11.19 | E6: 6.47 | F6: 21.38 | H6: =AVERAGE((B6-$B$2)^2,(C6-$C$2)^2,(D6-$D$2)^2,(E6-$E$2)^2,(F6-$F$2)^2) -> 127.82048 | I6: =SQRT(H6) -> 11.305772 | K6: =AVERAGE((B6-$B$2)^2,(C6-$C$2)^2,(D6-$D$2)^2,(E6-$E$2)^2) -> 73.4715 | L6: =SQRT(K6) -> 8.5715518
A7: API-GPT4-P.original-edad+ingresos | B7: 23.07 | C7: 37.49 | D7: 11.28 | E7: 7.69 | F7: 20.47 | H7: =AVERAGE((B7-$B$2)^2,(C7-$C$2)^2,(D7-$D$2)^2,(E7-$E$2)^2,(F7-$F$2)^2) -> 108.11488 | I7: =SQRT(H7) -> 10.397831 | K7: =AVERAGE((B7-$B$2)^2,(C7-$C$2)^2,(D7-$D$2)^2,(E7-$E$2)^2) -> 57.086375 | L7: =SQRT(K7) -> 7.5555526
A8: API-GPT4o-mini-P.original-edad+ingresos | B8: 29.83 | C8: 27.99 | D8: 12.44 | E8: 15 | F8: 14.75 | H8: =AVERAGE((B8-$B$2)^2,(C8-$C$2)^2,(D8-$D$2)^2,(E8-$E$2)^2,(F8-$F$2)^2) -> 46.70142 | I8: =SQRT(H8) -> 6.8338437 | K8: =AVERAGE((B8-$B$2)^2,(C8-$C$2)^2,(D8-$D$2)^2,(E8-$E$2)^2) -> 22.67615 | L8: =SQRT(K8) -> 4.7619481
A9: API-GPT5-P.original-edad+ingresos | B9: 32.3 | C9: 27.4 | D9: 17.6 | E9: 14.6 | F9: 8.1 | H9: =AVERAGE((B9-$B$2)^2,(C9-$C$2)^2,(D9-$D$2)^2,(E9-$E$2)^2,(F9-$F$2)^2) -> 18.832 | I9: =SQRT(H9) -> 4.3395852 | K9: =AVERAGE((B9-$B$2)^2,(C9-$C$2)^2,(D9-$D$2)^2,(E9-$E$2)^2) -> 16.5175 | L9: =SQRT(K9) -> 4.0641727
A10: API-GPT5-P.perfecto-edad | B10: 34.58 | C10: 27.8 | D10: 16.71 | E10: 12.74 | F10: 8.17 | H10: =AVERAGE((B10-$B$2)^2,(C10-$C$2)^2,(D10-$D$2)^2,(E10-$E$2)^2,(F10-$F$2)^2) -> 13.435 | I10: =SQRT(H10) -> 3.6653786 | K10: =AVERAGE((B10-$B$2)^2,(C10-$C$2)^2,(D10-$D$2)^2,(E10-$E$2)^2) -> 9.584525 | L10: =SQRT(K10) -> 3.0958884
A11: API-GPT5-P.perfecto-edad+ingresos | B11: 34.19 | C11: 28.08 | D11: 17.11 | E11: 12.89 | F11: 7.74 | H11: =AVERAGE((B11-$B$2)^2,(C11-$C$2)^2,(D11-$D$2)^2,(E11-$E$2)^2,(F11-$F$2)^2) -> 12.54646 | I11: =SQRT(H11) -> 3.5420982 | K11: =AVERAGE((B11-$B$2)^2,(C11-$C$2)^2,(D11-$D$2)^2,(E11-$E$2)^2) -> 9.582175 | L11: =SQRT(K11) -> 3.0955088
A12: API-GPT4-P.perfecto-edad | B12: 23.261214 | C12: 39.609877 | D12: 12.155841 | E12: 4.551738 | F12: 20.421329 | H12: =AVERAGE((B12-$B$2)^2,(C12-$C$2)^2,(D12-$D$2)^2,(E12-$E$2)^2,(F12-$F$2)^2) -> 117.16637 | I12: =SQRT(H12) -> 10.824342 | K12: =AVERAGE((B12-$B$2)^2,(C12-$C$2)^2,(D12-$D$2)^2,(E12-$E$2)^2) -> 68.830159 | L12: =SQRT(K12) -> 8.2963944
A13: API-GPT4-P.perfecto-edad+ingresos | B13: 21.87 | C13: 41.22 | D13: 12.2 | E13: 4.49 | F13: 20.22 | H13: =AVERAGE((B13-$B$2)^2,(C13-$C$2)^2,(D13-$D$2)^2,(E13-$E$2)^2,(F13-$F$2)^2) -> 128.03716 | I13: =SQRT(H13) -> 11.315351 | K13: =AVERAGE((B13-$B$2)^2,(C13-$C$2)^2,(D13-$D$2)^2,(E13-$E$2)^2) -> 84.18235 | L13: =SQRT(K13) -> 9.175094
A14: API-GPT4o-mini-P.perfecto-edad | B14: 36.03 | C14: 24 | D14: 14.85 | E14: 9.64 | F14: 15.48 | H14: =AVERAGE((B14-$B$2)^2,(C14-$C$2)^2,(D14-$D$2)^2,(E14-$E$2)^2,(F14-$F$2)^2) -> 51.38828 | I14: =SQRT(H14) -> 7.1685619 | K14: =AVERAGE((B14-$B$2)^2,(C14-$C$2)^2,(D14-$D$2)^2,(E14-$E$2)^2) -> 24.03975 | L14: =SQRT(K14) -> 4.9030348
A15: API-GPT4o-mini-P.perfecto-edad+ingresos | B15: 23.8 | C15: 36.17 | D15: 11.9 | E15: 15.4 | F15: 12.73 | H15: =AVERAGE((B15-$B$2)^2,(C15-$C$2)^2,(D15-$D$2)^2,(E15-$E$2)^2,(F15-$F$2)^2) -> 57.52276 | I15: =SQRT(H15) -> 7.584376 | K15: =AVERAGE((B15-$B$2)^2,(C15-$C$2)^2,(D15-$D$2)^2,(E15-$E$2)^2) -> 47.252225 | L15: =SQRT(K15) -> 6.8740254
... A20: ONLINE-GPT4o-P.original-edad+ingresos | B20: 37.38 | C20: 27.54 | D20: 14.7 | E20: 12.92 | F20: 7.46 | H20: =AVERAGE((B20-$B$2)^2,(C20-$C$2)^2,(D20-$D$2)^2,(E20-$E$2)^2,(F20-$F$2)^2) -> 11.8808 | I20: =SQRT(H20) -> 3.4468536 | K20: =AVERAGE((B20-$B$2)^2,(C20-$C$2)^2,(D20-$D$2)^2,(E20-$E$2)^2) -> 9.4221 | L20: =SQRT(K20) -> 3.0695439
A21: MOS | H21: MSE (+Blank) | I21: RMSE (+Blank) | K21: MSE | L21: RMSE
A22: API-GPT5-P.original-edad | B22: 32.5 | C22: 27.44 | D22: 17.56 | E22: 14.34 | F22: 8.16 | H22: =AVERAGE((B22-$B$2)^2,(C22-$C$2)^2,(D22-$D$2)^2,(E22-$E$2)^2,(F22-$F$2)^2) -> 18.24928 | I22: =SQRT(H22) -> 4.2719176 | K22: =AVERAGE((B22-$B$2)^2,(C22-$C$2)^2,(D22-$D$2)^2,(E22-$E$2)^2) -> 15.6292 | L22: =SQRT(K22) -> 3.9533783
A23: API-GPT4o-mini-P.original-edad | B23: 33.38 | C23: 26.32 | D23: 14 | E23: 11.34 | F23: 14.96 | H23: =AVERAGE((B23-$B$2)^2,(C23-$C$2)^2,(D23-$D$2)^2,(E23-$E$2)^2,(F23-$F$2)^2) -> 42.1328 | I23: =SQRT(H23) -> 6.4909784 | K23: =AVERAGE((B23-$B$2)^2,(C23-$C$2)^2,(D23-$D$2)^2,(E23-$E$2)^2) -> 15.6996 | L23: =SQRT(K23) -> 3.9622721
A24: API-GPT4-P.original-edad | B24: 21.81 | C24: 38.9 | D24: 11.27 | E24: 6.72 | F24: 21.3 | H24: =AVERAGE((B24-$B$2)^2,(C24-$C$2)^2,(D24-$D$2)^2,(E24-$E$2)^2,(F24-$F$2)^2) -> 125.67948 | I24: =SQRT(H24) -> 11.210686 | K24: =AVERAGE((B24-$B$2)^2,(C24-$C$2)^2,(D24-$D$2)^2,(E24-$E$2)^2) -> 71.53685 | L24: =SQRT(K24) -> 8.457946
A25: API-GPT4-P.original-edad+ingresos | B25: 23.16 | C25: 37.14 | D25: 11.2 | E25: 7.96 | F25: 20.54 | H25: =AVERAGE((B25-$B$2)^2,(C25-$C$2)^2,(D25-$D$2)^2,(E25-$E$2)^2,(F25-$F$2)^2) -> 107.27728 | I25: =SQRT(H25) -> 10.357475 | K25: =AVERAGE((B25-$B$2)^2,(C25-$C$2)^2,(D25-$D$2)^2,(E25-$E$2)^2) -> 55.4197 | L25: =SQRT(K25) -> 7.4444409
A26: API-GPT4o-mini-P.originaledad+ingresos | B26: 29.29 | C26: 28.32 | D26: 12.49 | E26: 15.18 | F26: 14.72 | H26: =AVERAGE((B26-$B$2)^2,(C26-$C$2)^2,(D26-$D$2)^2,(E26-$E$2)^2,(F26-$F$2)^2) -> 47.49588 | I26: =SQRT(H26) -> 6.8917255 | K26: =AVERAGE((B26-$B$2)^2,(C26-$C$2)^2,(D26-$D$2)^2,(E26-$E$2)^2) -> 23.84825 | L26: =SQRT(K26) -> 4.883467
