Workbook

Sheet Summary
A1: Tabla 5 - Comparativa LLM - Primera Ronda (PIMLE) | F1: Tabla 6 - Comparativa Prompt - Primera Ronda (PIMLE) | K1: Tabla 6 - Comparativa Prompt - Primera Ronda (PIMLE) | O1: Tabla 9 - Estimaciones PIMLE - Primera Ronda | AA1: Tabla 11 - Comparativa Emulación LLM (PIMLE)
A2: Modelo y Acceso | B2: 46334 | C2: 46347 | F2: Modelo y Acceso | G2: 46334 | H2: 46347 | K2: Modelo y Acceso | L2: P.Original | M2: P.Perfecto | O2: Estimación - Encuesta | P2: FP | Q2: JJ | R2: MEO | S2: JK | T2: JAK | U2: EA | V2: EM | W2: HM | X2: Blanco | AA2: Modelo y Acceso | AB2: 46334 | AC2: 46347 | AD2: 46350 | AE2: 46360 | AF2: 46368
A3: GPT 4 - API | B3: =AVERAGE('Round 1'!N45:N46) -> 8.6814734 | C3: - | F3: P.Original | K3: 46334 | O3: 46334 | AA3: GPT 4 - API | AB3: =AVERAGE('Round 1'!#REF!) -> #REF! | AC3: - | AD3: =AVERAGE('Round 2 - PIMLE'!L3:L4) -> 6.5963038 | AE3: =AVERAGE('Round 2 - PIMLE'!L12:L13) -> 7.3600806 | AF3: -
A4: GPT 4o - API | B4: =AVERAGE('Round 1'!N49:N50) -> 10.481317 | C4: - | F4: GPT 4 - API | G4: ='Round 1'!N45 -> 8.3113109 | H4: - | K4: GPT 4 - API | L4: 8.3113109 | M4: 9.0516358 | O4: Encuestas Humanas | P4: ='Round 1'!B44 -> 6.9 | Q4: ='Round 1'!C44 -> 22.5 | R4: ='Round 1'!D44 -> 2.4 | S4: ='Round 1'!E44 -> 13.6 | T4: ='Round 1'!F44 -> 28 | U4: ='Round 1'!G44 -> 2.1 | V4: ='Round 1'!H44 -> 13.3 | W4: ='Round 1'!I44 -> 2.8 | X4: ='Round 1'!J44 -> 8.4 | AA4: GPT 4o - API | AB4: =AVERAGE('Round 1'!#REF!) -> #REF! | AC4: - | AD4: =AVERAGE('Round 2 - PIMLE'!L7:L8) -> 16.218537 | AE4: =AVERAGE('Round 2 - PIMLE'!L16:L17) -> 16.247303 | AF4: -
A5: GPT 5 - API | B5: =AVERAGE('Round 1'!N47:N48) -> 9.4918257 | C5: - | F5: GPT 4o - API | G5: ='Round 1'!N49 -> 10.48164 | H5: - | K5: GPT 4o - API | L5: 10.48164 | M5: 10.480993 | O5: API - GPT4 - P.Original | P5: ='Round 1'!B45 -> 15.1 | Q5: ='Round 1'!C45 -> 12.7 | R5: ='Round 1'!D45 -> 14.1 | S5: ='Round 1'!E45 -> 2.8 | T5: ='Round 1'!F45 -> 21.7 | U5: ='Round 1'!G45 -> 1.8 | V5: ='Round 1'!H45 -> 16.2 | W5: ='Round 1'!I45 -> 6.7 | X5: ='Round 1'!J45 -> 8.8 | AA5: GPT 5 - API | AB5: =AVERAGE('Round 1'!#REF!) -> #REF! | AC5: - | AD5: =AVERAGE('Round 2 - PIMLE'!L5:L6) -> 2.884684 | AE5: =AVERAGE('Round 2 - PIMLE'!L14:L15) -> 2.9912628 | AF5: -
A6: GPT 5 - ONLINE | B6: =AVERAGE('Round 1'!N51:N52) -> 8.1073624 | C6: =AVERAGE('Round 1'!N53:N54) -> 8.1411294 | F6: GPT 5 - API | G6: ='Round 1'!N47 -> 9.4093629 | H6: - | K6: GPT 5 - API | L6: 9.4093629 | M6: 9.5742885 | O6: CHAT - GPT5 - P.Original | P6: ='Round 1'!B51 -> 20.2 | Q6: ='Round 1'!C51 -> 11.8 | R6: ='Round 1'!D51 -> 7.5 | S6: ='Round 1'!E51 -> 0.9 | T6: ='Round 1'!F51 -> 26.8 | U6: ='Round 1'!G51 -> 0.1 | V6: ='Round 1'!H51 -> 19.8 | W6: ='Round 1'!I51 -> 6 | X6: ='Round 1'!J51 -> 6.9 | AA6: GPT 5 - ONLINE | AB6: =AVERAGE('Round 1'!#REF!) -> #REF! | AC6: =AVERAGE('Round 1'!#REF!) -> #REF! | AD6: =AVERAGE('Round 2 - PIMLE'!L9:L10) -> 2.6905332 | AE6: =AVERAGE('Round 2 - PIMLE'!L18:L19) -> 2.3059115 | AF6: =AVERAGE('Round 2 - PIMLE'!L21:L22) -> 3.0570823
F7: GPT 5 - ONLINE | G7: ='Round 1'!N51 -> 7.8565684 | H7: ='Round 1'!N53 -> 9.8857754 | K7: GPT 5 - ONLINE | L7: 7.8565684 | M7: 8.3581564 | O7: 46347
F8: P.Perfecto | K8: 46347 | O8: CHAT - GPT5 - P.Perfect | P8: ='Round 1'!B54 -> 16.3 | Q8: ='Round 1'!C54 -> 18.6 | R8: ='Round 1'!D54 -> 8.3 | S8: ='Round 1'!E54 -> 1.9 | T8: ='Round 1'!F54 -> 24.3 | U8: ='Round 1'!G54 -> 2.2 | V8: ='Round 1'!H54 -> 17.2 | W8: ='Round 1'!I54 -> 1.8 | X8: ='Round 1'!J54 -> 9.3
F9: GPT 4 - API | G9: ='Round 1'!N46 -> 9.0516358 | H9: - | K9: GPT 5 - ONLINE | L9: 9.8857754 | M9: 6.3964834
F10: GPT 4o - API | G10: ='Round 1'!N50 -> 10.480993 | H10: - | O10: Resultados reales | P10: ='Round 1'!B55 -> 19.71 | Q10: ='Round 1'!C55 -> 26.85 | R10: ='Round 1'!D55 -> 1.2 | S10: ='Round 1'!E55 -> 13.94 | T10: ='Round 1'!F55 -> 23.92 | U10: ='Round 1'!G55 -> 0.66 | V10: ='Round 1'!H55 -> 12.46 | W10: ='Round 1'!I55 -> 1.26 | X10: ='Round 1'!J55 -> 1.06
F11: GPT 5 - API | G11: ='Round 1'!N48 -> 9.5742885 | H11: -
F12: GPT 5 - ONLINE | G12: ='Round 1'!N52 -> 8.3581564 | H12: ='Round 1'!N54 -> 6.3964834
O13: Tabla 10 - Estimaciones PIMLE - Segunda Ronda
A14: Tabla 7 - Comparativa LLM - Segunda Ronda (PIMLE) | F14: Tabla 8 - Comparativa Prompt - Segunda Ronda (PIMLE) | K14: Tabla 8 - Comparativa Prompt - Segunda Ronda (PIMLE) | O14: Estimación - Encuesta | P14: JJ | Q14: JAK | R14: Blank
A15: Modelo y Acceso | B15: 46350 | C15: 46360 | D15: 46368 | F15: Modelo y Acceso | G15: 46350 | H15: 46360 | I15: 46368 | K15: Modelo y Acceso | L15: P.Original | M15: P.Perfecto | O15: 46350
A16: GPT 4 - API | B16: =AVERAGE('Round 2 - PIMLE'!H3:H4) -> 14.353873 | C16: =AVERAGE('Round 2 - PIMLE'!H12:H13) -> 15.232268 | D16: - | F16: P.Original | K16: 46350 | O16: Encuestas Humanas | P16: ='Round 2 - PIMLE'!B2 -> 48 | Q16: ='Round 2 - PIMLE'!C2 -> 38 | R16: ='Round 2 - PIMLE'!D2 -> 12
A17: GPT 4o - API | B17: =AVERAGE('Round 2 - PIMLE'!H7:H8) -> 18.613891 | C17: =AVERAGE('Round 2 - PIMLE'!H16:H17) -> 18.649894 | D17: - | F17: GPT 4 - API | G17: ='Round 2 - PIMLE'!H3 -> 14.504797 | H17: ='Round 2 - PIMLE'!H12 -> 14.29134 | I17: - | K17: GPT 4 - API | L17: 14.504797 | M17: 14.20295 | O17: API - GPT 5 - P.perfect | P17: ='Round 2 - PIMLE'!B6 -> 45.85742 | Q17: ='Round 2 - PIMLE'!C6 -> 37.99741 | R17: ='Round 2 - PIMLE'!D6 -> 16.14517
A18: GPT 5 - API | B18: =AVERAGE('Round 2 - PIMLE'!H5:H6) -> 11.176578 | C18: =AVERAGE('Round 2 - PIMLE'!H14:H15) -> 11.374698 | D18: - | F18: GPT 4o - API | G18: ='Round 2 - PIMLE'!H7 -> 20.204322 | H18: ='Round 2 - PIMLE'!H16 -> 20.204322 | I18: - | K18: GPT 4o - API | L18: 20.204322 | M18: 17.02346 | O18: CHAT - GPT 5 - P.perfect | P18: ='Round 2 - PIMLE'!B10 -> 46.76919 | Q18: ='Round 2 - PIMLE'!C10 -> 39.80572 | R18: ='Round 2 - PIMLE'!D10 -> 13.42509
A19: GPT 5 - ONLINE | B19: =AVERAGE('Round 2 - PIMLE'!H9:H10) -> 10.51917 | C19: =AVERAGE('Round 2 - PIMLE'!H18:H19) -> 10.500585 | D19: =AVERAGE('Round 2 - PIMLE'!H21:H22) -> 11.785174 | F19: GPT 5 - API | G19: ='Round 2 - PIMLE'!H5 -> 11.347058 | H19: ='Round 2 - PIMLE'!H14 -> 11.17264 | I19: - | K19: GPT 5 - API | L19: 11.347058 | M19: 11.006099 | O19: 46360
F20: GPT 5 - ONLINE | G20: ='Round 2 - PIMLE'!H9 -> 11.704471 | H20: ='Round 2 - PIMLE'!H18 -> 11.044849 | I20: ='Round 2 - PIMLE'!H21 -> 14.466442 | K20: GPT 5 - ONLINE | L20: 11.704471 | M20: 9.3338688 | O20: Encuestas Humanas | P20: ='Round 2 - PIMLE'!B11 -> 48.44674 | Q20: ='Round 2 - PIMLE'!C11 -> 38.9969 | R20: ='Round 2 - PIMLE'!D11 -> 12.55636
F21: P.Perfecto | K21: 46360 | O21: API - GPT 5 - P.original | P21: ='Round 2 - PIMLE'!B14 -> 45.305 | Q21: ='Round 2 - PIMLE'!C14 -> 38.51111 | R21: ='Round 2 - PIMLE'!D14 -> 16.1839
F22: GPT 4 - API | G22: ='Round 2 - PIMLE'!H4 -> 14.20295 | H22: ='Round 2 - PIMLE'!H13 -> 16.173196 | I22: - | K22: GPT 4 - API | L22: 14.29134 | M22: 16.173196 | O22: CHAT - GPT 5 - P.perfect | P22: ='Round 2 - PIMLE'!B19 -> 46.52006 | Q22: ='Round 2 - PIMLE'!C19 -> 38.96781 | R22: ='Round 2 - PIMLE'!D19 -> 14.51213
F23: GPT 4o - API | G23: ='Round 2 - PIMLE'!H8 -> 17.02346 | H23: ='Round 2 - PIMLE'!H17 -> 17.095465 | I23: - | K23: GPT 4o - API | L23: 20.204322 | M23: 17.095465 | O23: 46368
F24: GPT 5 - API | G24: ='Round 2 - PIMLE'!H6 -> 11.006099 | H24: ='Round 2 - PIMLE'!H15 -> 11.576756 | I24: - | K24: GPT 5 - API | L24: 11.17264 | M24: 11.576756 | O24: Encuestas Humanas | P24: ='Round 2 - PIMLE'!B20 -> 46.2579 | Q24: ='Round 2 - PIMLE'!C20 -> 40.93662 | R24: ='Round 2 - PIMLE'!D20 -> 12.80549
F25: GPT 5 - ONLINE | G25: ='Round 2 - PIMLE'!H10 -> 9.3338688 | H25: ='Round 2 - PIMLE'!H19 -> 9.9563224 | I25: ='Round 2 - PIMLE'!H22 -> 9.1039068 | K25: GPT 5 - ONLINE | L25: 11.044849 | M25: 9.9563224 | O25: CHAT - GPT 5 - P.perfect | P25: ='Round 2 - PIMLE'!B22 -> 47.10032 | Q25: ='Round 2 - PIMLE'!C22 -> 39.72668 | R25: ='Round 2 - PIMLE'!D22 -> 13.173
K26: 46368
K27: GPT 5 - ONLINE | L27: 14.466442 | M27: 9.1039068 | O27: Resultados reales | P27: ='Round 2 - PIMLE'!B23 -> 57.388958 | Q27: ='Round 2 - PIMLE'!C23 -> 41.285317 | R27: ='Round 2 - PIMLE'!D23 -> 1.3257249

Sheet NSUM Estimators Evaluation
A1: Using MSE considering Blank votes
A2: CHAT - Estimator | B2: 1st Round - 8/11 | C2: 1st Round - 21/11 | D2: 2nd Round - 24/11 | E2: 2nd Round - 4/12 | F2: 2nd Round - 12/12
A3: NAIVE | B3: =AVERAGE('Round 1'!M9:M10) -> 66.290333 | C3: =AVERAGE('Round 1'!M11:M12) -> 73.378556 | D3: =AVERAGE('Round 2 - 24nov'!G9:G10) -> 119.20389 | E3: =AVERAGE('Round 2 - 4dec & 12dec'!G9:G10) -> 116.96063 | F3: =AVERAGE('Round 2 - 4dec & 12dec'!G12:G13) -> 152.15533
A4: MOS | B4: =AVERAGE('Round 1'!M23:M24) -> 66.112111 | C4: =AVERAGE('Round 1'!M25:M26) -> 68.916111 | D4: =AVERAGE('Round 2 - 24nov'!G21:G22) -> 113.15352 | E4: =AVERAGE('Round 2 - 4dec & 12dec'!G24:G25) -> 110.47019 | F4: =AVERAGE('Round 2 - 4dec & 12dec'!G27:G28) -> 146.6643
A5: MLE | B5: =AVERAGE('Round 1'!M37:M38) -> 69.030556 | C5: =AVERAGE('Round 1'!M39:M40) -> 68.932222 | D5: =AVERAGE('Round 2 - 24nov'!G33:G34) -> 114.3221 | E5: =AVERAGE('Round 2 - 4dec & 12dec'!G39:G40) -> 111.41681 | F5: =AVERAGE('Round 2 - 4dec & 12dec'!G42:G43) -> 150.16482
A6: PIMLE | B6: =AVERAGE('Round 1'!M51:M52) -> 65.792222 | C6: =AVERAGE('Round 1'!M53:M54) -> 69.321778 | D6: =AVERAGE('Round 2 - 24nov'!G45:G46) -> 112.05787 | E6: =AVERAGE('Round 2 - 4dec & 12dec'!G54:G55) -> 110.55852 | F6: =AVERAGE('Round 2 - 4dec & 12dec'!G57:G58) -> 146.07953
A8: API - Estimator | B8: 1st Round | C8: 2nd Round (1) | D8: 2nd Round (2)
A9: NAIVE | B9: =AVERAGE('Round 1'!M3:M8) -> 91.842593 | C9: =AVERAGE('Round 2 - 24nov'!G3:G8) -> 229.83882 | D9: =AVERAGE('Round 2 - 4dec & 12dec'!G3:G8) -> 243.03798
A10: MOS | B10: =AVERAGE('Round 1'!M17:M22) -> 91.854481 | C10: =AVERAGE('Round 2 - 24nov'!G15:G20) -> 227.1388 | D10: =AVERAGE('Round 2 - 4dec & 12dec'!G18:G23) -> 238.73101
A11: MLE | B11: =AVERAGE('Round 1'!M31:M36) -> 91.991815 | C11: =AVERAGE('Round 2 - 24nov'!G27:G32) -> 227.97913 | D11: =AVERAGE('Round 2 - 4dec & 12dec'!G33:G38) -> 239.76197
A12: PIMLE | B12: =AVERAGE('Round 1'!M45:M50) -> 91.821519 | C12: =AVERAGE('Round 2 - 24nov'!G39:G44) -> 226.66928 | D12: =AVERAGE('Round 2 - 4dec & 12dec'!G48:G53) -> 237.52223
A15: Using RMSE considering Blank votes
A16: CHAT - Estimator | B16: 1st Round - 8/11 | C16: 1st Round - 21/11 | D16: 2nd Round - 24/11 | E16: 2nd Round - 4/12 | F16: 2nd Round - 12/12
A17: NAIVE | B17: =AVERAGE('Round 1'!N9:N10) -> 8.1372751 | C17: =AVERAGE('Round 1'!N11:N12) -> 8.3913886 | D17: =AVERAGE('Round 2 - 24nov'!H9:H10) -> 10.867336 | E17: =AVERAGE('Round 2 - 4dec & 12dec'!H9:H10) -> 10.809029 | F17: =AVERAGE('Round 2 - 4dec & 12dec'!H12:H13) -> 12.101004
A18: MOS | B18: =AVERAGE('Round 1'!N23:N24) -> 8.1264796 | C18: =AVERAGE('Round 1'!N25:N26) -> 8.1087335 | D18: =AVERAGE('Round 2 - 24nov'!H21:H22) -> 10.568861 | E18: =AVERAGE('Round 2 - 4dec & 12dec'!H24:H25) -> 10.496779 | F18: =AVERAGE('Round 2 - 4dec & 12dec'!H27:H28) -> 11.804441
A19: MLE | B19: =AVERAGE('Round 1'!N37:N38) -> 8.301089 | C19: =AVERAGE('Round 1'!N39:N40) -> 8.1504659 | D19: =AVERAGE('Round 2 - 24nov'!H33:H34) -> 10.632953 | E19: =AVERAGE('Round 2 - 4dec & 12dec'!H39:H40) -> 10.550041 | F19: =AVERAGE('Round 2 - 4dec & 12dec'!H42:H43) -> 11.953801
A20: PIMLE | B20: =AVERAGE('Round 1'!N51:N52) -> 8.1073624 | C20: =AVERAGE('Round 1'!N53:N54) -> 8.1411294 | D20: =AVERAGE('Round 2 - 24nov'!H45:H46) -> 10.51917 | E20: =AVERAGE('Round 2 - 4dec & 12dec'!H54:H55) -> 10.500585 | F20: =AVERAGE('Round 2 - 4dec & 12dec'!H57:H58) -> 11.785174
A22: API - Estimator | B22: 1st Round | C22: 2nd Round (1) | D22: 2nd Round (2)
A23: NAIVE | B23: =AVERAGE('Round 1'!N3:N8) -> 9.5521161 | C23: =AVERAGE('Round 2 - 24nov'!H3:H8) -> 14.821015 | D23: =AVERAGE('Round 2 - 4dec & 12dec'!H3:H8) -> 15.263236
A24: MOS | B24: =AVERAGE('Round 1'!N17:N22) -> 9.5535202 | C24: =AVERAGE('Round 2 - 24nov'!H15:H20) -> 14.7309 | D24: =AVERAGE('Round 2 - 4dec & 12dec'!H18:H23) -> 15.124919
A25: MLE | B25: =AVERAGE('Round 1'!N31:N36) -> 9.5615054 | C25: =AVERAGE('Round 2 - 24nov'!H27:H32) -> 14.754478 | D25: =AVERAGE('Round 2 - 4dec & 12dec'!H33:H38) -> 15.156777
A26: PIMLE | B26: =AVERAGE('Round 1'!N45:N50) -> 9.5515386 | C26: =AVERAGE('Round 2 - 24nov'!H39:H44) -> 14.714781 | D26: =AVERAGE('Round 2 - 4dec & 12dec'!H48:H53) -> 15.08562

Sheet Round 2 - PIMLE
A1: Encuesta (PIMLE) | B1: JAK | C1: JJ | D1: Blank | E1: ECM | F1: RECM | G1: ECM (+B) | H1: RECM (+B) | I1: Emulation
A2: Encuestas Humanas - Ronda 2.1 | B2: 48 | C2: 38 | D2: 12 | E2: =AVERAGE((B2-$B$23)^2, (C2-$C$23)^2) -> 49.472923 | F2: =SQRT(E2) -> 7.0336991 | G2: =AVERAGE((B2-$B$23)^2, (C2-$C$23)^2, (D2-$D$23)^2) -> 70.961998 | H2: =SQRT(G2) -> 8.4238945 | I2: ECM | J2: RECM | K2: ECM (+B) | L2: RECM (+B)
A3: API - P.original - GPT 4 | B3: 38.55591 | C3: 43.66118 | D3: 17.78291 | E3: =AVERAGE((B3-$B$23)^2, (C3-$C$23)^2) -> 180.16422 | F3: =SQRT(E3) -> 13.422527 | G3: =AVERAGE((B3-$B$23)^2, (C3-$C$23)^2, (D3-$D$23)^2) -> 210.38913 | H3: =SQRT(G3) -> 14.504797 | I3: =AVERAGE((B3-$B$2)^2, (C3-$C$2)^2) -> 60.619897 | J3: =SQRT(I3) -> 7.7858781 | K3: =AVERAGE((B3-$B$2)^2, (C3-$C$2)^2, (D3-$D$2)^2) -> 51.560614 | L3: =SQRT(K3) -> 7.180572
A4: API - P.perfecto - GPT 4 | B4: 41.00012 | C4: 39.42289 | D4: 19.57699 | E4: =AVERAGE((B4-$B$23)^2, (C4-$C$23)^2) -> 136.03133 | F4: =SQRT(E4) -> 11.663247 | G4: =AVERAGE((B4-$B$23)^2, (C4-$C$23)^2, (D4-$D$23)^2) -> 201.72378 | H4: =SQRT(G4) -> 14.20295 | I4: =AVERAGE((B4-$B$2)^2, (C4-$C$2)^2) -> 25.511468 | J4: =SQRT(I4) -> 5.0508878 | K4: =AVERAGE((B4-$B$2)^2, (C4-$C$2)^2, (D4-$D$2)^2) -> 36.144571 | L4: =SQRT(K4) -> 6.0120355
A5: API - P.original - GPT 5 | B5: 44.99813 | C5: 38.64987 | D5: 16.352 | E5: =AVERAGE((B5-$B$23)^2, (C5-$C$23)^2) -> 80.239104 | F5: =SQRT(E5) -> 8.9576282 | G5: =AVERAGE((B5-$B$23)^2, (C5-$C$23)^2, (D5-$D$23)^2) -> 128.75572 | H5: =SQRT(G5) -> 11.347058 | I5: =AVERAGE((B5-$B$2)^2, (C5-$C$2)^2) -> 4.7167773 | J5: =SQRT(I5) -> 2.1718143 | K5: =AVERAGE((B5-$B$2)^2, (C5-$C$2)^2, (D5-$D$2)^2) -> 9.4578195 | L5: =SQRT(K5) -> 3.0753568
A6: API - P.perfecto - GPT 5 | B6: 45.85742 | C6: 37.99741 | D6: 16.14517 | E6: =AVERAGE((B6-$B$23)^2, (C6-$C$23)^2) -> 71.893354 | F6: =SQRT(E6) -> 8.4789949 | G6: =AVERAGE((B6-$B$23)^2, (C6-$C$23)^2, (D6-$D$23)^2) -> 121.13422 | H6: =SQRT(G6) -> 11.006099 | I6: =AVERAGE((B6-$B$2)^2, (C6-$C$2)^2) -> 2.2953279 | J6: =SQRT(I6) -> 1.515034 | K6: =AVERAGE((B6-$B$2)^2, (C6-$C$2)^2, (D6-$D$2)^2) -> 7.2576967 | L6: =SQRT(K6) -> 2.6940113
A7: API - P.original - GPT 4o mini | B7: 33.33333 | C7: 66.66667 | D7: 0 | E7: =AVERAGE((B7-$B$23)^2, (C7-$C$23)^2) -> 611.44318 | F7: =SQRT(E7) -> 24.727377 | G7: =AVERAGE((B7-$B$23)^2, (C7-$C$23)^2, (D7-$D$23)^2) -> 408.21463 | H7: =SQRT(G7) -> 20.204322 | I7: =AVERAGE((B7-$B$2)^2, (C7-$C$2)^2) -> 518.44459 | J7: =SQRT(I7) -> 22.769378 | K7: =AVERAGE((B7-$B$2)^2, (C7-$C$2)^2, (D7-$D$2)^2) -> 393.62973 | L7: =SQRT(K7) -> 19.840104
A8: API - P.perfecto - GPT 4o mini | B8: 33.33333 | C8: 54.14521 | D8: 12.52146 | E8: =AVERAGE((B8-$B$23)^2, (C8-$C$23)^2) -> 372.02506 | F8: =SQRT(E8) -> 19.287951 | G8: =AVERAGE((B8-$B$23)^2, (C8-$C$23)^2, (D8-$D$23)^2) -> 289.7982 | H8: =SQRT(G8) -> 17.02346 | I8: =AVERAGE((B8-$B$2)^2, (C8-$C$2)^2) -> 237.88951 | J8: =SQRT(I8) -> 15.423667 | K8: =AVERAGE((B8-$B$2)^2, (C8-$C$2)^2, (D8-$D$2)^2) -> 158.68365 | L8: =SQRT(K8) -> 12.59697
A9: CHAT - P.original - GPT 5 - 2.1 | B9: 47.60633 | C9: 34.61302 | D9: 17.78065 | E9: =AVERAGE((B9-$B$23)^2, (C9-$C$23)^2) -> 70.109681 | F9: =SQRT(E9) -> 8.3731524 | G9: =AVERAGE((B9-$B$23)^2, (C9-$C$23)^2, (D9-$D$23)^2) -> 136.99464 | H9: =SQRT(G9) -> 11.704471 | I9: =AVERAGE((B9-$B$2)^2, (C9-$C$2)^2) -> 5.8133048 | J9: =SQRT(I9) -> 2.4110796 | K9: =AVERAGE((B9-$B$2)^2, (C9-$C$2)^2, (D9-$D$2)^2) -> 15.014175 | L9: =SQRT(K9) -> 3.8748129
A10: CHAT - P.perfecto - GPT 5 - 2.1 | B10: 46.76919 | C10: 39.80572 | D10: 13.42509 | E10: =AVERAGE((B10-$B$23)^2, (C10-$C$23)^2) -> 57.484344 | F10: =SQRT(E10) -> 7.581843 | G10: =AVERAGE((B10-$B$23)^2, (C10-$C$23)^2, (D10-$D$23)^2) -> 87.121108 | H10: =SQRT(G10) -> 9.3338688 | I10: =AVERAGE((B10-$B$2)^2, (C10-$C$2)^2) -> 2.387759 | J10: =SQRT(I10) -> 1.5452375 | K10: =AVERAGE((B10-$B$2)^2, (C10-$C$2)^2, (D10-$D$2)^2) -> 2.2687998 | L10: =SQRT(K10) -> 1.5062536
A11: Encuestas Humanas - Ronda 2.2 | B11: 48.44674 | C11: 38.9969 | D11: 12.55636 | E11: =AVERAGE((B11-$B$23)^2, (C11-$C$23)^2) -> 42.60006 | F11: =SQRT(E11) -> 6.5268722 | G11: =AVERAGE((B11-$B$23)^2, (C11-$C$23)^2, (D11-$D$23)^2) -> 70.442428 | H11: =SQRT(G11) -> 8.3929988
A12: API - P.original - GPT 4 | B12: 39.36175 | C12: 42.38512 | D12: 18.25314 | E12: =AVERAGE((B12-$B$23)^2, (C12-$C$23)^2) -> 163.0949 | F12: =SQRT(E12) -> 12.770862 | G12: =AVERAGE((B12-$B$23)^2, (C12-$C$23)^2, (D12-$D$23)^2) -> 204.2424 | H12: =SQRT(G12) -> 14.29134 | I12: =AVERAGE((B12-$B$11)^2, (C12-$C$11)^2) -> 47.008539 | J12: =SQRT(I12) -> 6.8562773 | K12: =AVERAGE((B12-$B$11)^2, (C12-$C$11)^2, (D12-$D$11)^2) -> 42.156793 | L12: =SQRT(K12) -> 6.4928263
A13: API - P.perfecto - GPT 4 | B13: 37.18082 | C13: 42.11136 | D13: 20.70782 | E13: =AVERAGE((B13-$B$23)^2, (C13-$C$23)^2) -> 204.5256 | F13: =SQRT(E13) -> 14.301245 | G13: =AVERAGE((B13-$B$23)^2, (C13-$C$23)^2, (D13-$D$23)^2) -> 261.57227 | H13: =SQRT(G13) -> 16.173196 | I13: =AVERAGE((B13-$B$11)^2, (C13-$C$11)^2) -> 68.310407 | J13: =SQRT(I13) -> 8.265011 | K13: =AVERAGE((B13-$B$11)^2, (C13-$C$11)^2, (D13-$D$11)^2) -> 67.689038 | L13: =SQRT(K13) -> 8.2273348
A14: API - P.original - GPT 5 | B14: 45.305 | C14: 38.51111 | D14: 16.1839 | E14: =AVERAGE((B14-$B$23)^2, (C14-$C$23)^2) -> 76.859137 | F14: =SQRT(E14) -> 8.7669343 | G14: =AVERAGE((B14-$B$23)^2, (C14-$C$23)^2, (D14-$D$23)^2) -> 124.82788 | H14: =SQRT(G14) -> 11.17264 | I14: =AVERAGE((B14-$B$11)^2, (C14-$C$11)^2) -> 5.0532611 | J14: =SQRT(I14) -> 2.247946 | K14: =AVERAGE((B14-$B$11)^2, (C14-$C$11)^2, (D14-$D$11)^2) -> 7.7551895 | L14: =SQRT(K14) -> 2.7848141
A15: API - P.perfecto - GPT 5 | B15: 45.38619 | C15: 37.64398 | D15: 16.96983 | E15: =AVERAGE((B15-$B$23)^2, (C15-$C$23)^2) -> 78.662891 | F15: =SQRT(E15) -> 8.8692103 | G15: =AVERAGE((B15-$B$23)^2, (C15-$C$23)^2, (D15-$D$23)^2) -> 134.02127 | H15: =SQRT(G15) -> 11.576756 | I15: =AVERAGE((B15-$B$11)^2, (C15-$C$11)^2) -> 5.5986794 | J15: =SQRT(I15) -> 2.3661529 | K15: =AVERAGE((B15-$B$11)^2, (C15-$C$11)^2, (D15-$D$11)^2) -> 10.225359 | L15: =SQRT(K15) -> 3.1977115
A16: API - P.original - GPT 4o mini | B16: 33.33333 | C16: 66.66667 | D16: 0 | E16: =AVERAGE((B16-$B$23)^2, (C16-$C$23)^2) -> 611.44318 | F16: =SQRT(E16) -> 24.727377 | G16: =AVERAGE((B16-$B$23)^2, (C16-$C$23)^2, (D16-$D$23)^2) -> 408.21463 | H16: =SQRT(G16) -> 20.204322 | I16: =AVERAGE((B16-$B$11)^2, (C16-$C$11)^2) -> 497.01567 | J16: =SQRT(I16) -> 22.293848 | K16: =AVERAGE((B16-$B$11)^2, (C16-$C$11)^2, (D16-$D$11)^2) -> 383.89784 | L16: =SQRT(K16) -> 19.593311
A17: API - P.perfecto - GPT 4o mini | B17: 33.33333 | C17: 55.40537 | D17: 11.2613 | E17: =AVERAGE((B17-$B$23)^2, (C17-$C$23)^2) -> 389.02458 | F17: =SQRT(E17) -> 19.723706 | G17: =AVERAGE((B17-$B$23)^2, (C17-$C$23)^2, (D17-$D$23)^2) -> 292.25494 | H17: =SQRT(G17) -> 17.095465 | I17: =AVERAGE((B17-$B$11)^2, (C17-$C$11)^2) -> 248.82652 | J17: =SQRT(I17) -> 15.774236 | K17: =AVERAGE((B17-$B$11)^2, (C17-$C$11)^2, (D17-$D$11)^2) -> 166.44341 | L17: =SQRT(K17) -> 12.901295
A18: CHAT - P.original - GPT 5 - 2.2 | B18: 47.30841 | C18: 35.99263 | D18: 16.69895 | E18: =AVERAGE((B18-$B$23)^2, (C18-$C$23)^2) -> 64.814994 | F18: =SQRT(E18) -> 8.050776 | G18: =AVERAGE((B18-$B$23)^2, (C18-$C$23)^2, (D18-$D$23)^2) -> 121.98868 | H18: =SQRT(G18) -> 11.044849 | I18: =AVERAGE((B18-$B$11)^2, (C18-$C$11)^2) -> 5.1607167 | J18: =SQRT(I18) -> 2.2717211 | K18: =AVERAGE((B18-$B$11)^2, (C18-$C$11)^2, (D18-$D$11)^2) -> 9.1608284 | L18: =SQRT(K18) -> 3.026686
A19: CHAT - P.perfecto - GPT 5 - 2.2 | B19: 46.52006 | C19: 38.96781 | D19: 14.51213 | E19: =AVERAGE((B19-$B$23)^2, (C19-$C$23)^2) -> 61.751895 | F19: =SQRT(E19) -> 7.8582374 | G19: =AVERAGE((B19-$B$23)^2, (C19-$C$23)^2, (D19-$D$23)^2) -> 99.128356 | H19: =SQRT(G19) -> 9.9563224 | I19: =AVERAGE((B19-$B$11)^2, (C19-$C$11)^2) -> 1.856471 | J19: =SQRT(I19) -> 1.3625238 | K19: =AVERAGE((B19-$B$11)^2, (C19-$C$11)^2, (D19-$D$11)^2) -> 2.5126594 | L19: =SQRT(K19) -> 1.585137
A20: Encuestas Humanas - Ronda 2.3 | B20: 46.2579 | C20: 40.93662 | D20: 12.80549 | E20: =AVERAGE((B20-$B$23)^2, (C20-$C$23)^2) -> 62.011025 | F20: =SQRT(E20) -> 7.8747079 | G20: =AVERAGE((B20-$B$23)^2, (C20-$C$23)^2, (D20-$D$23)^2) -> 85.269019 | H20: =SQRT(G20) -> 9.2341225
A21: CHAT - P.original - GPT 5 - 2.3 | B21: 40.15694 | C21: 40.35093 | D21: 19.49213 | E21: =AVERAGE((B21-$B$23)^2, (C21-$C$23)^2) -> 148.90777 | F21: =SQRT(E21) -> 12.202777 | G21: =AVERAGE((B21-$B$23)^2, (C21-$C$23)^2, (D21-$D$23)^2) -> 209.27794 | H21: =SQRT(G21) -> 14.466442 | I21: =AVERAGE((B21-$B$20)^2, (C21-$C$20)^2) -> 18.782373 | J21: =SQRT(I21) -> 4.3338635 | K21: =AVERAGE((B21-$B$20)^2, (C21-$C$20)^2, (D21-$D$20)^2) -> 27.4253 | L21: =SQRT(K21) -> 5.236917
A22: CHAT - P.perfecto - GPT 5 - 2.3 | B22: 47.10032 | C22: 39.72668 | D22: 13.173 | E22: =AVERAGE((B22-$B$23)^2, (C22-$C$23)^2) -> 54.142714 | F22: =SQRT(E22) -> 7.3581733 | G22: =AVERAGE((B22-$B$23)^2, (C22-$C$23)^2, (D22-$D$23)^2) -> 82.881118 | H22: =SQRT(G22) -> 9.1039068 | I22: =AVERAGE((B22-$B$20)^2, (C22-$C$20)^2) -> 1.0868131 | J22: =SQRT(I22) -> 1.0425033 | K22: =AVERAGE((B22-$B$20)^2, (C22-$C$20)^2, (D22-$D$20)^2) -> 0.76956329 | L22: =SQRT(K22) -> 0.87724756
A23: Resultados Reales | B23: 57.388958 | C23: 41.285317 | D23: 1.3257249 | I23: =AVERAGE((B23-$B$2)^2, (C23-$C$2)^2) -> 49.472923 | J23: =SQRT(I23) -> 7.0336991 | K23: =AVERAGE((B23-$B$2)^2, (C23-$C$2)^2, (D23-$D$2)^2) -> 70.961998 | L23: =SQRT(K23) -> 8.4238945 | M23: 2.1
I24: =AVERAGE((B23-$B$11)^2, (C23-$C$11)^2) -> 42.60006 | J24: =SQRT(I24) -> 6.5268722 | K24: =AVERAGE((B23-$B$11)^2, (C23-$C$11)^2, (D23-$D$11)^2) -> 70.442428 | L24: =SQRT(K24) -> 8.3929988 | M24: 2.2
I25: =AVERAGE((B23-$B$20)^2, (C23-$C$20)^2) -> 62.011025 | J25: =SQRT(I25) -> 7.8747079 | K25: =AVERAGE((B23-$B$11)^2, (C23-$C$11)^2, (D23-$D$11)^2) -> 70.442428 | L25: =SQRT(K25) -> 8.3929988 | M25: 2.3

Sheet Round 1
A1: (NAIVE) | B1: FP | C1: JJ | D1: MEO | E1: JK | F1: JAK | G1: EA | H1: EM | I1: HM | J1: Blanco | K1: MSE | L1: RMSE | M1: MSE (+Blank) | N1: RMSE (+Blank)
A2: Encuestas Humanas | B2: 7.1 | C2: 23.8 | D2: 2.1 | E2: 13.6 | F2: 26.7 | G2: 1.7 | H2: 14 | I2: 2.9 | J2: 8.1 | K2: =AVERAGE((B2-$B$13)^2, (C2-$C$13)^2, (D2-$D$13)^2, (E2-$E$13)^2,(F2-$F$13)^2,(G2-$G$13)^2,(H2-$H$13)^2, (I2-$I$13)^2) -> 22.888925 | L2: =SQRT(K2) -> 4.7842371 | M2: =AVERAGE((B2-$B$13)^2, (C2-$C$13)^2, (D2-$D$13)^2, (E2-$E$13)^2,(F2-$F$13)^2,(G2-$G$13)^2,(H2-$H$13)^2, (I2-$I$13)^2, (J2-$J$13)^2) -> 25.852556 | N2: =SQRT(M2) -> 5.0845408
A3: API - P.original - GPT 4 | B3: 15.2 | C3: 12.8 | D3: 13.8 | E3: 2.6 | F3: 21.8 | G3: 1.9 | H3: 16.2 | I3: 6.7 | J3: 9 | K3: =AVERAGE((B3-$B$13)^2, (C3-$C$13)^2, (D3-$D$13)^2, (E3-$E$13)^2,(F3-$F$13)^2,(G3-$G$13)^2,(H3-$H$13)^2, (I3-$I$13)^2) -> 69.338925 | L3: =SQRT(K3) -> 8.3269998 | M3: =AVERAGE((B3-$B$13)^2, (C3-$C$13)^2, (D3-$D$13)^2, (E3-$E$13)^2,(F3-$F$13)^2,(G3-$G$13)^2,(H3-$H$13)^2, (I3-$I$13)^2, (J3-$J$13)^2) -> 68.639444 | N3: =SQRT(M3) -> 8.2848925
A4: API - P.perfecto - GPT 4 | B4: 14.3 | C4: 13.9 | D4: 15.4 | E4: 2.8 | F4: 17.4 | G4: 1.5 | H4: 15.2 | I4: 6.7 | J4: 12.7 | K4: =AVERAGE((B4-$B$13)^2, (C4-$C$13)^2, (D4-$D$13)^2, (E4-$E$13)^2,(F4-$F$13)^2,(G4-$G$13)^2,(H4-$H$13)^2, (I4-$I$13)^2) -> 75.378425 | L4: =SQRT(K4) -> 8.6820749 | M4: =AVERAGE((B4-$B$13)^2, (C4-$C$13)^2, (D4-$D$13)^2, (E4-$E$13)^2,(F4-$F$13)^2,(G4-$G$13)^2,(H4-$H$13)^2, (I4-$I$13)^2, (J4-$J$13)^2) -> 82.057444 | N4: =SQRT(M4) -> 9.0585564
A5: API - P.original - GPT 5 | B5: 10.2 | C5: 12.5 | D5: 7.9 | E5: 3.9 | F5: 20.3 | G5: 3.9 | H5: 27.9 | I5: 2.7 | J5: 10.6 | K5: =AVERAGE((B5-$B$13)^2, (C5-$C$13)^2, (D5-$D$13)^2, (E5-$E$13)^2,(F5-$F$13)^2,(G5-$G$13)^2,(H5-$H$13)^2, (I5-$I$13)^2) -> 88.265425 | L5: =SQRT(K5) -> 9.3949681 | M5: =AVERAGE((B5-$B$13)^2, (C5-$C$13)^2, (D5-$D$13)^2, (E5-$E$13)^2,(F5-$F$13)^2,(G5-$G$13)^2,(H5-$H$13)^2, (I5-$I$13)^2, (J5-$J$13)^2) -> 88.570556 | N5: =SQRT(M5) -> 9.4111931
A6: API - P.perfecto - GPT 5 | B6: 10 | C6: 12.6 | D6: 7.8 | E6: 3.7 | F6: 20.5 | G6: 3.7 | H6: 29.2 | I6: 2.6 | J6: 10 | K6: =AVERAGE((B6-$B$13)^2, (C6-$C$13)^2, (D6-$D$13)^2, (E6-$E$13)^2,(F6-$F$13)^2,(G6-$G$13)^2,(H6-$H$13)^2, (I6-$I$13)^2) -> 93.590675 | L6: =SQRT(K6) -> 9.6742274 | M6: =AVERAGE((B6-$B$13)^2, (C6-$C$13)^2, (D6-$D$13)^2, (E6-$E$13)^2,(F6-$F$13)^2,(G6-$G$13)^2,(H6-$H$13)^2, (I6-$I$13)^2, (J6-$J$13)^2) -> 92.072111 | N6: =SQRT(M6) -> 9.5954214
A7: API - P.original - GPT 4o mini | B7: 22.2 | C7: 11.1 | D7: 0 | E7: 0 | F7: 33.3 | G7: 0 | H7: 11.1 | I7: 0 | J7: 22.2 | K7: =AVERAGE((B7-$B$13)^2, (C7-$C$13)^2, (D7-$D$13)^2, (E7-$E$13)^2,(F7-$F$13)^2,(G7-$G$13)^2,(H7-$H$13)^2, (I7-$I$13)^2) -> 67.735425 | L7: =SQRT(K7) -> 8.2301534 | M7: =AVERAGE((B7-$B$13)^2, (C7-$C$13)^2, (D7-$D$13)^2, (E7-$E$13)^2,(F7-$F$13)^2,(G7-$G$13)^2,(H7-$H$13)^2, (I7-$I$13)^2, (J7-$J$13)^2) -> 109.86478 | N7: =SQRT(M7) -> 10.48164
A8: API - P.perfecto - GPT 4o mini | B8: 22.2 | C8: 11.1 | D8: 0 | E8: 0 | F8: 33.3 | G8: 0.1 | H8: 11.1 | I8: 0 | J8: 22.2 | K8: =AVERAGE((B8-$B$13)^2, (C8-$C$13)^2, (D8-$D$13)^2, (E8-$E$13)^2,(F8-$F$13)^2,(G8-$G$13)^2,(H8-$H$13)^2, (I8-$I$13)^2) -> 67.720175 | L8: =SQRT(K8) -> 8.2292269 | M8: =AVERAGE((B8-$B$13)^2, (C8-$C$13)^2, (D8-$D$13)^2, (E8-$E$13)^2,(F8-$F$13)^2,(G8-$G$13)^2,(H8-$H$13)^2, (I8-$I$13)^2, (J8-$J$13)^2) -> 109.85122 | N8: =SQRT(M8) -> 10.480993
A9: CHAT - P.original - GPT 5 | B9: 20.4 | C9: 11.7 | D9: 7.5 | E9: 0.9 | F9: 26.9 | G9: 0.1 | H9: 19.6 | I9: 6 | J9: 6.9 | K9: =AVERAGE((B9-$B$13)^2, (C9-$C$13)^2, (D9-$D$13)^2, (E9-$E$13)^2,(F9-$F$13)^2,(G9-$G$13)^2,(H9-$H$13)^2, (I9-$I$13)^2) -> 65.296425 | L9: =SQRT(K9) -> 8.0806203 | M9: =AVERAGE((B9-$B$13)^2, (C9-$C$13)^2, (D9-$D$13)^2, (E9-$E$13)^2,(F9-$F$13)^2,(G9-$G$13)^2,(H9-$H$13)^2, (I9-$I$13)^2, (J9-$J$13)^2) -> 61.830778 | N9: =SQRT(M9) -> 7.8632549
A10: CHAT - P.perfecto - GPT 5 | B10: 14.4 | C10: 14.1 | D10: 6 | E10: 0.6 | F10: 23.6 | G10: 2.6 | H10: 24.9 | I10: 3.8 | J10: 10 | K10: =AVERAGE((B10-$B$13)^2, (C10-$C$13)^2, (D10-$D$13)^2, (E10-$E$13)^2,(F10-$F$13)^2,(G10-$G$13)^2,(H10-$H$13)^2, (I10-$I$13)^2) -> 69.603175 | L10: =SQRT(K10) -> 8.3428517 | M10: =AVERAGE((B10-$B$13)^2, (C10-$C$13)^2, (D10-$D$13)^2, (E10-$E$13)^2,(F10-$F$13)^2,(G10-$G$13)^2,(H10-$H$13)^2, (I10-$I$13)^2, (J10-$J$13)^2) -> 70.749889 | N10: =SQRT(M10) -> 8.4112953
A11: CHAT - P.original - GPT 5 - Post | B11: 13.7 | C11: 10.7 | D11: 6.2 | E11: 0.9 | F11: 22.7 | G11: 0.3 | H11: 29.8 | I11: 3.8 | J11: 12 | K11: =AVERAGE((B11-$B$13)^2, (C11-$C$13)^2, (D11-$D$13)^2, (E11-$E$13)^2,(F11-$F$13)^2,(G11-$G$13)^2,(H11-$H$13)^2, (I11-$I$13)^2) -> 100.09118 | L11: =SQRT(K11) -> 10.004558 | M11: =AVERAGE((B11-$B$13)^2, (C11-$C$13)^2, (D11-$D$13)^2, (E11-$E$13)^2,(F11-$F$13)^2,(G11-$G$13)^2,(H11-$H$13)^2, (I11-$I$13)^2, (J11-$J$13)^2) -> 102.26811 | N11: =SQRT(M11) -> 10.11277
A12: CHAT - P.perfecto - GPT 5 - Post | B12: 16.5 | C12: 17.6 | D12: 8.1 | E12: 1.7 | F12: 24.3 | G12: 2.2 | H12: 18.2 | I12: 1.9 | J12: 9.5 | K12: =AVERAGE((B12-$B$13)^2, (C12-$C$13)^2, (D12-$D$13)^2, (E12-$E$13)^2,(F12-$F$13)^2,(G12-$G$13)^2,(H12-$H$13)^2, (I12-$I$13)^2) -> 41.145925 | L12: =SQRT(K12) -> 6.4145089 | M12: =AVERAGE((B12-$B$13)^2, (C12-$C$13)^2, (D12-$D$13)^2, (E12-$E$13)^2,(F12-$F$13)^2,(G12-$G$13)^2,(H12-$H$13)^2, (I12-$I$13)^2, (J12-$J$13)^2) -> 44.489 | N12: =SQRT(M12) -> 6.6700075
A13: Resultados Reales | B13: 19.71 | C13: 26.85 | D13: 1.2 | E13: 13.94 | F13: 23.92 | G13: 0.66 | H13: 12.46 | I13: 1.26 | J13: 1.06
A15: (MOS) | B15: FP | C15: JJ | D15: MEO | E15: JK | F15: JAK | G15: EA | H15: EM | I15: HM | J15: Blanco | K15: MSE | L15: RMSE | M15: MSE (+Blank) | N15: RMSE (+Blank)
A16: Encuestas Humanas | B16: 7 | C16: 23.3 | D16: 3.5 | E16: 13.3 | F16: 27 | G16: 1.9 | H16: 12.6 | I16: 2.9 | J16: 8.5 | K16: =AVERAGE((B16-$B$13)^2, (C16-$C$13)^2, (D16-$D$13)^2, (E16-$E$13)^2,(F16-$F$13)^2,(G16-$G$13)^2,(H16-$H$13)^2, (I16-$I$13)^2) -> 24.197425 | L16: =SQRT(K16) -> 4.9190878 | M16: =AVERAGE((B16-$B$13)^2, (C16-$C$13)^2, (D16-$D$13)^2, (E16-$E$13)^2,(F16-$F$13)^2,(G16-$G$13)^2,(H16-$H$13)^2, (I16-$I$13)^2, (J16-$J$13)^2) -> 27.659222 | N16: =SQRT(M16) -> 5.2592036
A17: API - P.original - GPT 4 | B17: 15.2 | C17: 12.7 | D17: 14.1 | E17: 2.7 | F17: 21.6 | G17: 1.8 | H17: 16.2 | I17: 6.7 | J17: 8.8 | K17: =AVERAGE((B17-$B$13)^2, (C17-$C$13)^2, (D17-$D$13)^2, (E17-$E$13)^2,(F17-$F$13)^2,(G17-$G$13)^2,(H17-$H$13)^2, (I17-$I$13)^2) -> 70.446675 | L17: =SQRT(K17) -> 8.3932518 | M17: =AVERAGE((B17-$B$13)^2, (C17-$C$13)^2, (D17-$D$13)^2, (E17-$E$13)^2,(F17-$F$13)^2,(G17-$G$13)^2,(H17-$H$13)^2, (I17-$I$13)^2, (J17-$J$13)^2) -> 69.275667 | N17: =SQRT(M17) -> 8.3232005
A18: API - P.perfecto - GPT 4 | B18: 14.3 | C18: 13.9 | D18: 15.5 | E18: 2.9 | F18: 17.4 | G18: 1.5 | H18: 15.3 | I18: 6.7 | J18: 12.6 | K18: =AVERAGE((B18-$B$13)^2, (C18-$C$13)^2, (D18-$D$13)^2, (E18-$E$13)^2,(F18-$F$13)^2,(G18-$G$13)^2,(H18-$H$13)^2, (I18-$I$13)^2) -> 75.527175 | L18: =SQRT(K18) -> 8.6906372 | M18: =AVERAGE((B18-$B$13)^2, (C18-$C$13)^2, (D18-$D$13)^2, (E18-$E$13)^2,(F18-$F$13)^2,(G18-$G$13)^2,(H18-$H$13)^2, (I18-$I$13)^2, (J18-$J$13)^2) -> 81.932111 | N18: =SQRT(M18) -> 9.0516358
A19: API - P.original - GPT 5 | B19: 10.2 | C19: 12.6 | D19: 8 | E19: 3.9 | F19: 20.3 | G19: 3.9 | H19: 28 | I19: 2.7 | J19: 10.5 | K19: =AVERAGE((B19-$B$13)^2, (C19-$C$13)^2, (D19-$D$13)^2, (E19-$E$13)^2,(F19-$F$13)^2,(G19-$G$13)^2,(H19-$H$13)^2, (I19-$I$13)^2) -> 88.463925 | L19: =SQRT(K19) -> 9.4055263 | M19: =AVERAGE((B19-$B$13)^2, (C19-$C$13)^2, (D19-$D$13)^2, (E19-$E$13)^2,(F19-$F$13)^2,(G19-$G$13)^2,(H19-$H$13)^2, (I19-$I$13)^2, (J19-$J$13)^2) -> 88.536111 | N19: =SQRT(M19) -> 9.4093629
A20: API - P.perfecto - GPT 5 | B20: 10 | C20: 12.7 | D20: 7.8 | E20: 3.7 | F20: 20.4 | G20: 3.7 | H20: 29.2 | I20: 2.7 | J20: 9.9 | K20: =AVERAGE((B20-$B$13)^2, (C20-$C$13)^2, (D20-$D$13)^2, (E20-$E$13)^2,(F20-$F$13)^2,(G20-$G$13)^2,(H20-$H$13)^2, (I20-$I$13)^2) -> 93.357175 | L20: =SQRT(K20) -> 9.6621517 | M20: =AVERAGE((B20-$B$13)^2, (C20-$C$13)^2, (D20-$D$13)^2, (E20-$E$13)^2,(F20-$F$13)^2,(G20-$G$13)^2,(H20-$H$13)^2, (I20-$I$13)^2, (J20-$J$13)^2) -> 91.667 | N20: =SQRT(M20) -> 9.5742885
A21: API - P.original - GPT 4o mini | B21: 22.2 | C21: 11.1 | D21: 0 | E21: 0 | F21: 33.3 | G21: 0 | H21: 11.1 | I21: 0 | J21: 22.2 | K21: =AVERAGE((B21-$B$13)^2, (C21-$C$13)^2, (D21-$D$13)^2, (E21-$E$13)^2,(F21-$F$13)^2,(G21-$G$13)^2,(H21-$H$13)^2, (I21-$I$13)^2) -> 67.735425 | L21: =SQRT(K21) -> 8.2301534 | M21: =AVERAGE((B21-$B$13)^2, (C21-$C$13)^2, (D21-$D$13)^2, (E21-$E$13)^2,(F21-$F$13)^2,(G21-$G$13)^2,(H21-$H$13)^2, (I21-$I$13)^2, (J21-$J$13)^2) -> 109.86478 | N21: =SQRT(M21) -> 10.48164
A22: API - P.perfecto - GPT 4o mini | B22: 22.2 | C22: 11.1 | D22: 0 | E22: 0 | F22: 33.3 | G22: 0.1 | H22: 11.1 | I22: 0 | J22: 22.2 | K22: =AVERAGE((B22-$B$13)^2, (C22-$C$13)^2, (D22-$D$13)^2, (E22-$E$13)^2,(F22-$F$13)^2,(G22-$G$13)^2,(H22-$H$13)^2, (I22-$I$13)^2) -> 67.720175 | L22: =SQRT(K22) -> 8.2292269 | M22: =AVERAGE((B22-$B$13)^2, (C22-$C$13)^2, (D22-$D$13)^2, (E22-$E$13)^2,(F22-$F$13)^2,(G22-$G$13)^2,(H22-$H$13)^2, (I22-$I$13)^2, (J22-$J$13)^2) -> 109.85122 | N22: =SQRT(M22) -> 10.480993
A23: CHAT - P.original - GPT 5 | B23: 20.3 | C23: 11.8 | D23: 7.5 | E23: 0.9 | F23: 26.8 | G23: 0.1 | H23: 19.8 | I23: 6 | J23: 6.9 | K23: =AVERAGE((B23-$B$13)^2, (C23-$C$13)^2, (D23-$D$13)^2, (E23-$E$13)^2,(F23-$F$13)^2,(G23-$G$13)^2,(H23-$H$13)^2, (I23-$I$13)^2) -> 65.191675 | L23: =SQRT(K23) -> 8.0741362 | M23: =AVERAGE((B23-$B$13)^2, (C23-$C$13)^2, (D23-$D$13)^2, (E23-$E$13)^2,(F23-$F$13)^2,(G23-$G$13)^2,(H23-$H$13)^2, (I23-$I$13)^2, (J23-$J$13)^2) -> 61.737667 | N23: =SQRT(M23) -> 7.857332
A24: CHAT - P.perfecto - GPT 5 | B24: 13.9 | C24: 14.4 | D24: 5.9 | E24: 0.7 | F24: 23.6 | G24: 2.6 | H24: 25.1 | I24: 3.8 | J24: 9.9 | K24: =AVERAGE((B24-$B$13)^2, (C24-$C$13)^2, (D24-$D$13)^2, (E24-$E$13)^2,(F24-$F$13)^2,(G24-$G$13)^2,(H24-$H$13)^2, (I24-$I$13)^2) -> 69.529175 | L24: =SQRT(K24) -> 8.3384156 | M24: =AVERAGE((B24-$B$13)^2, (C24-$C$13)^2, (D24-$D$13)^2, (E24-$E$13)^2,(F24-$F$13)^2,(G24-$G$13)^2,(H24-$H$13)^2, (I24-$I$13)^2, (J24-$J$13)^2) -> 70.486556 | N24: =SQRT(M24) -> 8.3956272
A25: CHAT - P.original - GPT 5 - Post | B25: 14.8 | C25: 10.6 | D25: 6.6 | E25: 0.9 | F25: 22.2 | G25: 0.3 | H25: 28.9 | I25: 4.1 | J25: 11.6 | K25: =AVERAGE((B25-$B$13)^2, (C25-$C$13)^2, (D25-$D$13)^2, (E25-$E$13)^2,(F25-$F$13)^2,(G25-$G$13)^2,(H25-$H$13)^2, (I25-$I$13)^2) -> 96.099925 | L25: =SQRT(K25) -> 9.8030569 | M25: =AVERAGE((B25-$B$13)^2, (C25-$C$13)^2, (D25-$D$13)^2, (E25-$E$13)^2,(F25-$F$13)^2,(G25-$G$13)^2,(H25-$H$13)^2, (I25-$I$13)^2, (J25-$J$13)^2) -> 97.765667 | N25: =SQRT(M25) -> 9.8876522
A26: CHAT - P.perfecto - GPT 5 - Post | B26: 16.3 | C26: 18.8 | D26: 8.4 | E26: 2 | F26: 24.4 | G26: 2.2 | H26: 17 | I26: 1.8 | J26: 9.2 | K26: =AVERAGE((B26-$B$13)^2, (C26-$C$13)^2, (D26-$D$13)^2, (E26-$E$13)^2,(F26-$F$13)^2,(G26-$G$13)^2,(H26-$H$13)^2, (I26-$I$13)^2) -> 36.792425 | L26: =SQRT(K26) -> 6.065676 | M26: =AVERAGE((B26-$B$13)^2, (C26-$C$13)^2, (D26-$D$13)^2, (E26-$E$13)^2,(F26-$F$13)^2,(G26-$G$13)^2,(H26-$H$13)^2, (I26-$I$13)^2, (J26-$J$13)^2) -> 40.066556 | N26: =SQRT(M26) -> 6.3298148
A27: Resultados Reales | B27: 19.71 | C27: 26.85 | D27: 1.2 | E27: 13.94 | F27: 23.92 | G27: 0.66 | H27: 12.46 | I27: 1.26 | J27: 1.06
A29: (MLE) | B29: FP | C29: JJ | D29: MEO | E29: JK | F29: JAK | G29: EA | H29: EM | I29: HM | J29: Blanco | K29: MSE | L29: RMSE | M29: MSE (+Blank) | N29: RMSE (+Blank)
A30: Encuestas Humanas | B30: 7.3 | C30: 23.5 | D30: 2.4 | E30: 13.5 | F30: 25.5 | G30: 2 | H30: 13.4 | I30: 3.2 | J30: 9.3 | K30: =AVERAGE((B30-$B$13)^2, (C30-$C$13)^2, (D30-$D$13)^2, (E30-$E$13)^2,(F30-$F$13)^2,(G30-$G$13)^2,(H30-$H$13)^2, (I30-$I$13)^2) -> 21.975425 | L30: =SQRT(K30) -> 4.6877953 | M30: =AVERAGE((B30-$B$13)^2, (C30-$C$13)^2, (D30-$D$13)^2, (E30-$E$13)^2,(F30-$F$13)^2,(G30-$G$13)^2,(H30-$H$13)^2, (I30-$I$13)^2, (J30-$J$13)^2) -> 27.077889 | N30: =SQRT(M30) -> 5.2036419
A31: API - P.original - GPT 4 | B31: 14.9 | C31: 12.5 | D31: 13.9 | E31: 2.9 | F31: 21.7 | G31: 2 | H31: 16.2 | I31: 6.8 | J31: 9.2 | K31: =AVERAGE((B31-$B$13)^2, (C31-$C$13)^2, (D31-$D$13)^2, (E31-$E$13)^2,(F31-$F$13)^2,(G31-$G$13)^2,(H31-$H$13)^2, (I31-$I$13)^2) -> 70.454175 | L31: =SQRT(K31) -> 8.3936985 | M31: =AVERAGE((B31-$B$13)^2, (C31-$C$13)^2, (D31-$D$13)^2, (E31-$E$13)^2,(F31-$F$13)^2,(G31-$G$13)^2,(H31-$H$13)^2, (I31-$I$13)^2, (J31-$J$13)^2) -> 69.988111 | N31: =SQRT(M31) -> 8.3658897
A32: API - P.perfecto - GPT 4 | B32: 13.9 | C32: 14.1 | D32: 15.4 | E32: 3.1 | F32: 17.2 | G32: 1.6 | H32: 15.3 | I32: 6.9 | J32: 12.6 | K32: =AVERAGE((B32-$B$13)^2, (C32-$C$13)^2, (D32-$D$13)^2, (E32-$E$13)^2,(F32-$F$13)^2,(G32-$G$13)^2,(H32-$H$13)^2, (I32-$I$13)^2) -> 75.172675 | L32: =SQRT(K32) -> 8.6702177 | M32: =AVERAGE((B32-$B$13)^2, (C32-$C$13)^2, (D32-$D$13)^2, (E32-$E$13)^2,(F32-$F$13)^2,(G32-$G$13)^2,(H32-$H$13)^2, (I32-$I$13)^2, (J32-$J$13)^2) -> 81.617 | N32: =SQRT(M32) -> 9.0342127
A33: API - P.original - GPT 5 | B33: 10.1 | C33: 12.6 | D33: 7.9 | E33: 3.8 | F33: 20.3 | G33: 3.8 | H33: 28 | I33: 2.7 | J33: 10.6 | K33: =AVERAGE((B33-$B$13)^2, (C33-$C$13)^2, (D33-$D$13)^2, (E33-$E$13)^2,(F33-$F$13)^2,(G33-$G$13)^2,(H33-$H$13)^2, (I33-$I$13)^2) -> 88.706675 | L33: =SQRT(K33) -> 9.4184221 | M33: =AVERAGE((B33-$B$13)^2, (C33-$C$13)^2, (D33-$D$13)^2, (E33-$E$13)^2,(F33-$F$13)^2,(G33-$G$13)^2,(H33-$H$13)^2, (I33-$I$13)^2, (J33-$J$13)^2) -> 88.962778 | N33: =SQRT(M33) -> 9.4320082
A34: API - P.perfecto - GPT 5 | B34: 10 | C34: 12.7 | D34: 7.8 | E34: 3.7 | F34: 20.4 | G34: 3.7 | H34: 29.2 | I34: 2.7 | J34: 9.9 | K34: =AVERAGE((B34-$B$13)^2, (C34-$C$13)^2, (D34-$D$13)^2, (E34-$E$13)^2,(F34-$F$13)^2,(G34-$G$13)^2,(H34-$H$13)^2, (I34-$I$13)^2) -> 93.357175 | L34: =SQRT(K34) -> 9.6621517 | M34: =AVERAGE((B34-$B$13)^2, (C34-$C$13)^2, (D34-$D$13)^2, (E34-$E$13)^2,(F34-$F$13)^2,(G34-$G$13)^2,(H34-$H$13)^2, (I34-$I$13)^2, (J34-$J$13)^2) -> 91.667 | N34: =SQRT(M34) -> 9.5742885
A35: API - P.original - GPT 4o mini | B35: 22.2 | C35: 11.1 | D35: 0 | E35: 0 | F35: 33.3 | G35: 0 | H35: 11.1 | I35: 0 | J35: 22.2 | K35: =AVERAGE((B35-$B$13)^2, (C35-$C$13)^2, (D35-$D$13)^2, (E35-$E$13)^2,(F35-$F$13)^2,(G35-$G$13)^2,(H35-$H$13)^2, (I35-$I$13)^2) -> 67.735425 | L35: =SQRT(K35) -> 8.2301534 | M35: =AVERAGE((B35-$B$13)^2, (C35-$C$13)^2, (D35-$D$13)^2, (E35-$E$13)^2,(F35-$F$13)^2,(G35-$G$13)^2,(H35-$H$13)^2, (I35-$I$13)^2, (J35-$J$13)^2) -> 109.86478 | N35: =SQRT(M35) -> 10.48164
A36: API - P.perfecto - GPT 4o mini | B36: 22.2 | C36: 11.1 | D36: 0 | E36: 0 | F36: 33.3 | G36: 0.1 | H36: 11.1 | I36: 0 | J36: 22.2 | K36: =AVERAGE((B36-$B$13)^2, (C36-$C$13)^2, (D36-$D$13)^2, (E36-$E$13)^2,(F36-$F$13)^2,(G36-$G$13)^2,(H36-$H$13)^2, (I36-$I$13)^2) -> 67.720175 | L36: =SQRT(K36) -> 8.2292269 | M36: =AVERAGE((B36-$B$13)^2, (C36-$C$13)^2, (D36-$D$13)^2, (E36-$E$13)^2,(F36-$F$13)^2,(G36-$G$13)^2,(H36-$H$13)^2, (I36-$I$13)^2, (J36-$J$13)^2) -> 109.85122 | N36: =SQRT(M36) -> 10.480993
A37: CHAT - P.original - GPT 5 | B37: 20.1 | C37: 11.6 | D37: 7.7 | E37: 0.9 | F37: 26.6 | G37: 0.1 | H37: 20.2 | I37: 6 | J37: 6.9 | K37: =AVERAGE((B37-$B$13)^2, (C37-$C$13)^2, (D37-$D$13)^2, (E37-$E$13)^2,(F37-$F$13)^2,(G37-$G$13)^2,(H37-$H$13)^2, (I37-$I$13)^2) -> 66.859675 | L37: =SQRT(K37) -> 8.1767766 | M37: =AVERAGE((B37-$B$13)^2, (C37-$C$13)^2, (D37-$D$13)^2, (E37-$E$13)^2,(F37-$F$13)^2,(G37-$G$13)^2,(H37-$H$13)^2, (I37-$I$13)^2, (J37-$J$13)^2) -> 63.220333 | N37: =SQRT(M37) -> 7.9511215
A38: CHAT - P.perfecto - GPT 5 | B38: 13.7 | C38: 13.9 | D38: 5.8 | E38: 0.7 | F38: 23 | G38: 2.9 | H38: 25.9 | I38: 4.2 | J38: 9.9 | K38: =AVERAGE((B38-$B$13)^2, (C38-$C$13)^2, (D38-$D$13)^2, (E38-$E$13)^2,(F38-$F$13)^2,(G38-$G$13)^2,(H38-$H$13)^2, (I38-$I$13)^2) -> 74.427675 | L38: =SQRT(K38) -> 8.6271476 | M38: =AVERAGE((B38-$B$13)^2, (C38-$C$13)^2, (D38-$D$13)^2, (E38-$E$13)^2,(F38-$F$13)^2,(G38-$G$13)^2,(H38-$H$13)^2, (I38-$I$13)^2, (J38-$J$13)^2) -> 74.840778 | N38: =SQRT(M38) -> 8.6510565
A39: CHAT - P.original - GPT 5 - Post | B39: 15.7 | C39: 10.2 | D39: 6.9 | E39: 1.2 | F39: 21.6 | G39: 0.4 | H39: 28 | I39: 4.5 | J39: 11.4 | K39: =AVERAGE((B39-$B$13)^2, (C39-$C$13)^2, (D39-$D$13)^2, (E39-$E$13)^2,(F39-$F$13)^2,(G39-$G$13)^2,(H39-$H$13)^2, (I39-$I$13)^2) -> 93.192425 | L39: =SQRT(K39) -> 9.6536224 | M39: =AVERAGE((B39-$B$13)^2, (C39-$C$13)^2, (D39-$D$13)^2, (E39-$E$13)^2,(F39-$F$13)^2,(G39-$G$13)^2,(H39-$H$13)^2, (I39-$I$13)^2, (J39-$J$13)^2) -> 94.717222 | N39: =SQRT(M39) -> 9.7322773
A40: CHAT - P.perfecto - GPT 5 - Post | B40: 16.2 | C40: 18 | D40: 8.2 | E40: 2 | F40: 23.6 | G40: 2.5 | H40: 18 | I40: 2.1 | J40: 9.5 | K40: =AVERAGE((B40-$B$13)^2, (C40-$C$13)^2, (D40-$D$13)^2, (E40-$E$13)^2,(F40-$F$13)^2,(G40-$G$13)^2,(H40-$H$13)^2, (I40-$I$13)^2) -> 39.636425 | L40: =SQRT(K40) -> 6.2957466 | M40: =AVERAGE((B40-$B$13)^2, (C40-$C$13)^2, (D40-$D$13)^2, (E40-$E$13)^2,(F40-$F$13)^2,(G40-$G$13)^2,(H40-$H$13)^2, (I40-$I$13)^2, (J40-$J$13)^2) -> 43.147222 | N40: =SQRT(M40) -> 6.5686545
A41: Resultados Reales | B41: 19.71 | C41: 26.85 | D41: 1.2 | E41: 13.94 | F41: 23.92 | G41: 0.66 | H41: 12.46 | I41: 1.26 | J41: 1.06
A43: (PIMLE) | B43: FP | C43: JJ | D43: MEO | E43: JK | F43: JAK | G43: EA | H43: EM | I43: HM | J43: Blanco | K43: MSE | L43: RMSE | M43: MSE (+Blank) | N43: RMSE (+Blank)
...

Sheet Round 2 - 24nov
A1: (NAIVE) | B1: JAK | C1: JJ | D1: Blank | E1: MSE | F1: RMSE | G1: MSE (+Blank) | H1: RMSE (+Blank) | J1: Emulation
A2: Encuestas Humanas | B2: ='[1]Ronda 2 (valores sobre1)'!B2*100 -> 48 | C2: ='[1]Ronda 2 (valores sobre1)'!C2*100 -> 38 | D2: ='[1]Ronda 2 (valores sobre1)'!D2*100 -> 12 | E2: =AVERAGE((B2-$B$11)^2, (C2-$C$11)^2) -> 49.472923 | F2: =SQRT(E2) -> 7.0336991 | G2: =AVERAGE((B2-$B$11)^2, (C2-$C$11)^2, (D2-$D$11)^2) -> 70.961998 | H2: =SQRT(G2) -> 8.4238945 | J2: MSE | K2: RMSE | L2: MSE (+Blank) | M2: RMSE (+Blank) | O2: REALES
A3: API - P.original - GPT 4 | B3: ='[1]Ronda 2 (valores sobre1)'!B3*100 -> 38.59922 | C3: ='[1]Ronda 2 (valores sobre1)'!C3*100 -> 43.66265 | D3: ='[1]Ronda 2 (valores sobre1)'!D3*100 -> 17.73813 | E3: =AVERAGE((B3-$B$11)^2, (C3-$C$11)^2) -> 179.35299 | F3: =SQRT(E3) -> 13.392274 | G3: =AVERAGE((B3-$B$11)^2, (C3-$C$11)^2, (D3-$D$11)^2) -> 209.35767 | H3: =SQRT(G3) -> 14.469197 | J3: =AVERAGE((B3-$B$38)^2, (C3-$C$38)^2) -> 60.220135 | K3: =SQRT(J3) -> 7.7601633 | L3: =AVERAGE((B3-$B$38)^2, (C3-$C$38)^2, (D3-$D$38)^2) -> 51.122135 | M3: =SQRT(L3) -> 7.1499745 | O3: 0.5816 | P3: 0.4184
A4: API - P.perfecto - GPT 4 | B4: ='[1]Ronda 2 (valores sobre1)'!B4*100 -> 40.3347 | C4: ='[1]Ronda 2 (valores sobre1)'!C4*100 -> 39.77115 | D4: ='[1]Ronda 2 (valores sobre1)'!D4*100 -> 19.89415 | E4: =AVERAGE((B4-$B$11)^2, (C4-$C$11)^2) -> 146.57022 | F4: =SQRT(E4) -> 12.106619 | G4: =AVERAGE((B4-$B$11)^2, (C4-$C$11)^2, (D4-$D$11)^2) -> 212.64228 | H4: =SQRT(G4) -> 14.582259 | J4: =AVERAGE((B4-$B$38)^2, (C4-$C$38)^2) -> 30.946898 | K4: =SQRT(J4) -> 5.5629936 | L4: =AVERAGE((B4-$B$38)^2, (C4-$C$38)^2, (D4-$D$38)^2) -> 41.4038 | M4: =SQRT(L4) -> 6.4345785 | O4: APROX | Q4: =1-R5 -> 0.98674275 | R4: BLANCO
A5: API - P.original - GPT 5 | B5: ='[1]Ronda 2 (valores sobre1)'!B5*100 -> 44.96135 | C5: ='[1]Ronda 2 (valores sobre1)'!C5*100 -> 38.67657 | D5: ='[1]Ronda 2 (valores sobre1)'!D5*100 -> 16.36207 | E5: =AVERAGE((B5-$B$11)^2, (C5-$C$11)^2) -> 80.625505 | F5: =SQRT(E5) -> 8.9791706 | G5: =AVERAGE((B5-$B$11)^2, (C5-$C$11)^2, (D5-$D$11)^2) -> 129.11423 | H5: =SQRT(G5) -> 11.362844 | J5: =AVERAGE((B5-$B$38)^2, (C5-$C$38)^2) -> 4.8455704 | K5: =SQRT(J5) -> 2.2012656 | L5: =AVERAGE((B5-$B$38)^2, (C5-$C$38)^2, (D5-$D$38)^2) -> 9.5729318 | M5: =SQRT(L5) -> 3.0940155 | O5: =O3*Q4 -> 0.57388958 | P5: =P3*Q4 -> 0.41285317 | R5: =165344/12471969 -> 0.013257249
A6: API - P.perfecto - GPT 5 | B6: ='[1]Ronda 2 (valores sobre1)'!B6*100 -> 45.81683 | C6: ='[1]Ronda 2 (valores sobre1)'!C6*100 -> 37.94429 | D6: ='[1]Ronda 2 (valores sobre1)'!D6*100 -> 16.23887 | E6: =AVERAGE((B6-$B$11)^2, (C6-$C$11)^2) -> 72.538307 | F6: =SQRT(E6) -> 8.5169424 | G6: =AVERAGE((B6-$B$11)^2, (C6-$C$11)^2, (D6-$D$11)^2) -> 122.49284 | H6: =SQRT(G6) -> 11.067648 | J6: =AVERAGE((B6-$B$38)^2, (C6-$C$38)^2) -> 2.3846674 | K6: =SQRT(J6) -> 1.5442368 | L6: =AVERAGE((B6-$B$38)^2, (C6-$C$38)^2, (D6-$D$38)^2) -> 7.5791179 | M6: =SQRT(L6) -> 2.7530198
A7: API - P.original - GPT 4o mini | B7: ='[1]Ronda 2 (valores sobre1)'!B7*100 -> 33.33333 | C7: ='[1]Ronda 2 (valores sobre1)'!C7*100 -> 66.66667 | D7: ='[1]Ronda 2 (valores sobre1)'!D7*100 -> 0 | E7: =AVERAGE((B7-$B$11)^2, (C7-$C$11)^2) -> 611.44318 | F7: =SQRT(E7) -> 24.727377 | G7: =AVERAGE((B7-$B$11)^2, (C7-$C$11)^2, (D7-$D$11)^2) -> 408.21463 | H7: =SQRT(G7) -> 20.204322 | J7: =AVERAGE((B7-$B$38)^2, (C7-$C$38)^2) -> 518.44459 | K7: =SQRT(J7) -> 22.769378 | L7: =AVERAGE((B7-$B$38)^2, (C7-$C$38)^2, (D7-$D$38)^2) -> 393.62973 | M7: =SQRT(L7) -> 19.840104
A8: API - P.perfecto - GPT 4o mini | B8: ='[1]Ronda 2 (valores sobre1)'!B8*100 -> 33.333333 | C8: ='[1]Ronda 2 (valores sobre1)'!C8*100 -> 56.75 | D8: ='[1]Ronda 2 (valores sobre1)'!D8*100 -> 9.916667 | E8: =AVERAGE((B8-$B$11)^2, (C8-$C$11)^2) -> 408.91477 | F8: =SQRT(E8) -> 20.221641 | G8: =AVERAGE((B8-$B$11)^2, (C8-$C$11)^2, (D8-$D$11)^2) -> 297.21128 | H8: =SQRT(G8) -> 17.239817 | J8: =AVERAGE((B8-$B$38)^2, (C8-$C$38)^2) -> 283.33681 | K8: =SQRT(J8) -> 16.832612 | L8: =AVERAGE((B8-$B$38)^2, (C8-$C$38)^2, (D8-$D$38)^2) -> 190.33797 | M8: =SQRT(L8) -> 13.796303
A9: CHAT - P.original - GPT 5 | B9: ='[1]Ronda 2 (valores sobre1)'!B9*100 -> 47.24141 | C9: ='[1]Ronda 2 (valores sobre1)'!C9*100 -> 34.7038 | D9: ='[1]Ronda 2 (valores sobre1)'!D9*100 -> 18.05478 | E9: =AVERAGE((B9-$B$11)^2, (C9-$C$11)^2) -> 73.14455 | F9: =SQRT(E9) -> 8.5524587 | G9: =AVERAGE((B9-$B$11)^2, (C9-$C$11)^2, (D9-$D$11)^2) -> 142.05013 | H9: =SQRT(G9) -> 11.918478 | J9: =AVERAGE((B9-$B$38)^2, (C9-$C$38)^2) -> 5.7201966 | K9: =SQRT(J9) -> 2.3916933 | L9: =AVERAGE((B9-$B$38)^2, (C9-$C$38)^2, (D9-$D$38)^2) -> 16.033585 | M9: =SQRT(L9) -> 4.0041959
A10: CHAT - P.perfecto - GPT 5 | B10: ='[1]Ronda 2 (valores sobre1)'!B10*100 -> 45.71777 | C10: ='[1]Ronda 2 (valores sobre1)'!C10*100 -> 40.61137 | D10: ='[1]Ronda 2 (valores sobre1)'!D10*100 -> 13.67085 | E10: =AVERAGE((B10-$B$11)^2, (C10-$C$11)^2) -> 68.335421 | F10: =SQRT(E10) -> 8.2665241 | G10: =AVERAGE((B10-$B$11)^2, (C10-$C$11)^2, (D10-$D$11)^2) -> 96.357652 | H10: =SQRT(G10) -> 9.8161934 | J10: =AVERAGE((B10-$B$38)^2, (C10-$C$38)^2) -> 6.0139135 | K10: =SQRT(J10) -> 2.4523282 | L10: =AVERAGE((B10-$B$38)^2, (C10-$C$38)^2, (D10-$D$38)^2) -> 4.9398556 | M10: =SQRT(L10) -> 2.2225786
A11: Resultados Reales | B11: ='[1]Ronda 2 (valores sobre1)'!B11*100 -> 57.388958 | C11: ='[1]Ronda 2 (valores sobre1)'!C11*100 -> 41.285317 | D11: ='[1]Ronda 2 (valores sobre1)'!D11*100 -> 1.3257249 | J11: =AVERAGE((B11-$B$38)^2, (C11-$C$38)^2) -> 49.472923 | K11: =SQRT(J11) -> 7.0336991 | L11: =AVERAGE((B11-$B$38)^2, (C11-$C$38)^2, (D11-$D$38)^2) -> 70.961998 | M11: =SQRT(L11) -> 8.4238945
A13: (MOS) | B13: JAK | C13: JJ | D13: Blank | E13: MSE | F13: RMSE | G13: MSE (+Blank) | H13: RMSE (+Blank)
A14: Encuestas Humanas | B14: =B2 -> 48 | C14: =C2 -> 38 | D14: =D2 -> 12 | E14: =AVERAGE((B14-$B$11)^2, (C14-$C$11)^2) -> 49.472923 | F14: =SQRT(E14) -> 7.0336991 | G14: =AVERAGE((B14-$B$11)^2, (C14-$C$11)^2, (D14-$D$11)^2) -> 70.961998 | H14: =SQRT(G14) -> 8.4238945 | J14: MSE | K14: RMSE | L14: MSE (+Blank) | M14: RMSE (+Blank)
A15: API - P.original - GPT 4 | B15: ='[1]Ronda 2 (valores sobre1)'!B15*100 -> 38.51772 | C15: ='[1]Ronda 2 (valores sobre1)'!C15*100 -> 43.63722 | D15: ='[1]Ronda 2 (valores sobre1)'!D15*100 -> 17.84506 | E15: =AVERAGE((B15-$B$11)^2, (C15-$C$11)^2) -> 180.82754 | F15: =SQRT(E15) -> 13.447213 | G15: =AVERAGE((B15-$B$11)^2, (C15-$C$11)^2, (D15-$D$11)^2) -> 211.51451 | H15: =SQRT(G15) -> 14.543538 | J15: =AVERAGE((B15-$B$38)^2, (C15-$C$38)^2) -> 60.845942 | K15: =SQRT(J15) -> 7.8003809 | L15: =AVERAGE((B15-$B$38)^2, (C15-$C$38)^2, (D15-$D$38)^2) -> 51.952203 | M15: =SQRT(L15) -> 7.2077877
A16: API - P.perfecto - GPT 4 | B16: ='[1]Ronda 2 (valores sobre1)'!B16*100 -> 40.89145 | C16: ='[1]Ronda 2 (valores sobre1)'!C16*100 -> 39.47365 | D16: ='[1]Ronda 2 (valores sobre1)'!D16*100 -> 19.6349 | E16: =AVERAGE((B16-$B$11)^2, (C16-$C$11)^2) -> 137.72496 | F16: =SQRT(E16) -> 11.735628 | G16: =AVERAGE((B16-$B$11)^2, (C16-$C$11)^2, (D16-$D$11)^2) -> 203.5586 | H16: =SQRT(G16) -> 14.267397 | J16: =AVERAGE((B16-$B$38)^2, (C16-$C$38)^2) -> 26.351564 | K16: =SQRT(J16) -> 5.1333774 | L16: =AVERAGE((B16-$B$38)^2, (C16-$C$38)^2, (D16-$D$38)^2) -> 36.998275 | M16: =SQRT(L16) -> 6.0826207
A17: API - P.original - GPT 5 | B17: ='[1]Ronda 2 (valores sobre1)'!B17*100 -> 45.0062 | C17: ='[1]Ronda 2 (valores sobre1)'!C17*100 -> 38.6518 | D17: ='[1]Ronda 2 (valores sobre1)'!D17*100 -> 16.342 | E17: =AVERAGE((B17-$B$11)^2, (C17-$C$11)^2) -> 80.134058 | F17: =SQRT(E17) -> 8.9517628 | G17: =AVERAGE((B17-$B$11)^2, (C17-$C$11)^2, (D17-$D$11)^2) -> 128.58554 | H17: =SQRT(G17) -> 11.339557 | J17: =AVERAGE((B17-$B$38)^2, (C17-$C$38)^2) -> 4.6938408 | K17: =SQRT(J17) -> 2.1665274 | L17: =AVERAGE((B17-$B$38)^2, (C17-$C$38)^2, (D17-$D$38)^2) -> 9.4135486 | M17: =SQRT(L17) -> 3.0681507
A18: API - P.perfecto - GPT 5 | B18: ='[1]Ronda 2 (valores sobre1)'!B18*100 -> 45.86274 | C18: ='[1]Ronda 2 (valores sobre1)'!C18*100 -> 37.98849 | D18: ='[1]Ronda 2 (valores sobre1)'!D18*100 -> 16.14877 | E18: =AVERAGE((B18-$B$11)^2, (C18-$C$11)^2) -> 71.861388 | F18: =SQRT(E18) -> 8.4771097 | G18: =AVERAGE((B18-$B$11)^2, (C18-$C$11)^2, (D18-$D$11)^2) -> 121.14848 | H18: =SQRT(G18) -> 11.006747 | J18: =AVERAGE((B18-$B$38)^2, (C18-$C$38)^2) -> 2.2840064 | K18: =SQRT(J18) -> 1.511293 | L18: =AVERAGE((B18-$B$38)^2, (C18-$C$38)^2, (D18-$D$38)^2) -> 7.2601018 | M18: =SQRT(L18) -> 2.6944576
A19: API - P.original - GPT 4o mini | B19: ='[1]Ronda 2 (valores sobre1)'!B19*100 -> 33.33333 | C19: ='[1]Ronda 2 (valores sobre1)'!C19*100 -> 66.66667 | D19: ='[1]Ronda 2 (valores sobre1)'!D19*100 -> 0 | E19: =AVERAGE((B19-$B$11)^2, (C19-$C$11)^2) -> 611.44318 | F19: =SQRT(E19) -> 24.727377 | G19: =AVERAGE((B19-$B$11)^2, (C19-$C$11)^2, (D19-$D$11)^2) -> 408.21463 | H19: =SQRT(G19) -> 20.204322 | J19: =AVERAGE((B19-$B$38)^2, (C19-$C$38)^2) -> 518.44459 | K19: =SQRT(J19) -> 22.769378 | L19: =AVERAGE((B19-$B$38)^2, (C19-$C$38)^2, (D19-$D$38)^2) -> 393.62973 | M19: =SQRT(L19) -> 19.840104
A20: API - P.perfecto - GPT 4o mini | B20: ='[1]Ronda 2 (valores sobre1)'!B20*100 -> 33.33333 | C20: ='[1]Ronda 2 (valores sobre1)'!C20*100 -> 54.15675 | D20: ='[1]Ronda 2 (valores sobre1)'!D20*100 -> 12.50991 | E20: =AVERAGE((B20-$B$11)^2, (C20-$C$11)^2) -> 372.17353 | F20: =SQRT(E20) -> 19.291799 | G20: =AVERAGE((B20-$B$11)^2, (C20-$C$11)^2, (D20-$D$11)^2) -> 289.81102 | H20: =SQRT(G20) -> 17.023837 | J20: =AVERAGE((B20-$B$38)^2, (C20-$C$38)^2) -> 238.07589 | K20: =SQRT(J20) -> 15.429708 | L20: =AVERAGE((B20-$B$38)^2, (C20-$C$38)^2, (D20-$D$38)^2) -> 158.80393 | M20: =SQRT(L20) -> 12.601743
A21: CHAT - P.original - GPT 5 | B21: ='[1]Ronda 2 (valores sobre1)'!B21*100 -> 47.50337 | C21: ='[1]Ronda 2 (valores sobre1)'!C21*100 -> 34.62415 | D21: ='[1]Ronda 2 (valores sobre1)'!D21*100 -> 17.87248 | E21: =AVERAGE((B21-$B$11)^2, (C21-$C$11)^2) -> 71.048 | F21: =SQRT(E21) -> 8.4289976 | G21: =AVERAGE((B21-$B$11)^2, (C21-$C$11)^2, (D21-$D$11)^2) -> 138.63037 | H21: =SQRT(G21) -> 11.77414 | J21: =AVERAGE((B21-$B$38)^2, (C21-$C$38)^2) -> 5.8215023 | K21: =SQRT(J21) -> 2.412779 | L21: =AVERAGE((B21-$B$38)^2, (C21-$C$38)^2, (D21-$D$38)^2) -> 15.376342 | M21: =SQRT(L21) -> 3.9212679
A22: CHAT - P.perfecto - GPT 5 | B22: ='[1]Ronda 2 (valores sobre1)'!B22*100 -> 46.68928 | C22: ='[1]Ronda 2 (valores sobre1)'!C22*100 -> 39.87848 | D22: ='[1]Ronda 2 (valores sobre1)'!D22*100 -> 13.43224 | E22: =AVERAGE((B22-$B$11)^2, (C22-$C$11)^2) -> 58.231154 | F22: =SQRT(E22) -> 7.630934 | G22: =AVERAGE((B22-$B$11)^2, (C22-$C$11)^2, (D22-$D$11)^2) -> 87.676672 | H22: =SQRT(G22) -> 9.3635822 | J22: =AVERAGE((B22-$B$38)^2, (C22-$C$38)^2) -> 2.623337 | K22: =SQRT(J22) -> 1.6196719 | L22: =AVERAGE((B22-$B$38)^2, (C22-$C$38)^2, (D22-$D$38)^2) -> 2.4326618 | M22: =SQRT(L22) -> 1.5596993
A23: Resultados Reales | B23: ='[1]Ronda 2 (valores sobre1)'!B23*100 -> 57.388958 | C23: ='[1]Ronda 2 (valores sobre1)'!C23*100 -> 41.285317 | D23: ='[1]Ronda 2 (valores sobre1)'!D23*100 -> 1.3257249 | J23: =AVERAGE((B23-$B$38)^2, (C23-$C$38)^2) -> 49.472923 | K23: =SQRT(J23) -> 7.0336991 | L23: =AVERAGE((B23-$B$38)^2, (C23-$C$38)^2, (D23-$D$38)^2) -> 70.961998 | M23: =SQRT(L23) -> 8.4238945
A25: (MLE) | B25: JAK | C25: JJ | D25: Blank | E25: MSE | F25: RMSE | G25: MSE (+Blank) | H25: RMSE (+Blank)
A26: Encuestas Humanas | B26: =B2 -> 48 | C26: =C2 -> 38 | D26: =D2 -> 12 | E26: =AVERAGE((B26-$B$11)^2, (C26-$C$11)^2) -> 49.472923 | F26: =SQRT(E26) -> 7.0336991 | G26: =AVERAGE((B26-$B$11)^2, (C26-$C$11)^2, (D26-$D$11)^2) -> 70.961998 | H26: =SQRT(G26) -> 8.4238945 | J26: MSE | K26: RMSE | L26: MSE (+Blank) | M26: RMSE (+Blank)
A27: API - P.original - GPT 4 | B27: ='[1]Ronda 2 (valores sobre1)'!B27*100 -> 38.42593 | C27: ='[1]Ronda 2 (valores sobre1)'!C27*100 -> 43.35317 | D27: ='[1]Ronda 2 (valores sobre1)'!D27*100 -> 18.2209 | E27: =AVERAGE((B27-$B$11)^2, (C27-$C$11)^2) -> 181.93623 | F27: =SQRT(E27) -> 13.488374 | G27: =AVERAGE((B27-$B$11)^2, (C27-$C$11)^2, (D27-$D$11)^2) -> 216.4398 | H27: =SQRT(G27) -> 14.711893 | J27: =AVERAGE((B27-$B$38)^2, (C27-$C$38)^2) -> 60.159623 | K27: =SQRT(J27) -> 7.7562635 | L27: =AVERAGE((B27-$B$38)^2, (C27-$C$38)^2, (D27-$D$38)^2) -> 53.006281 | M27: =SQRT(L27) -> 7.2805412
A28: API - P.perfecto - GPT 4 | B28: ='[1]Ronda 2 (valores sobre1)'!B28*100 -> 40.84728 | C28: ='[1]Ronda 2 (valores sobre1)'!C28*100 -> 39.33054 | D28: ='[1]Ronda 2 (valores sobre1)'!D28*100 -> 19.82218 | E28: =AVERAGE((B28-$B$11)^2, (C28-$C$11)^2) -> 138.72414 | F28: =SQRT(E28) -> 11.778121 | G28: =AVERAGE((B28-$B$11)^2, (C28-$C$11)^2, (D28-$D$11)^2) -> 206.52238 | H28: =SQRT(G28) -> 14.370886 | J28: =AVERAGE((B28-$B$38)^2, (C28-$C$38)^2) -> 26.46587 | K28: =SQRT(J28) -> 5.144499 | L28: =AVERAGE((B28-$B$38)^2, (C28-$C$38)^2, (D28-$D$38)^2) -> 38.039413 | M28: =SQRT(L28) -> 6.16761
A29: API - P.original - GPT 5 | B29: ='[1]Ronda 2 (valores sobre1)'!B29*100 -> 45.11956 | C29: ='[1]Ronda 2 (valores sobre1)'!C29*100 -> 38.53391 | D29: ='[1]Ronda 2 (valores sobre1)'!D29*100 -> 16.34653 | E29: =AVERAGE((B29-$B$11)^2, (C29-$C$11)^2) -> 79.054188 | F29: =SQRT(E29) -> 8.8912422 | G29: =AVERAGE((B29-$B$11)^2, (C29-$C$11)^2, (D29-$D$11)^2) -> 127.91099 | H29: =SQRT(G29) -> 11.309774 | J29: =AVERAGE((B29-$B$38)^2, (C29-$C$38)^2) -> 4.2909972 | K29: =SQRT(J29) -> 2.0714722 | L29: =AVERAGE((B29-$B$38)^2, (C29-$C$38)^2, (D29-$D$38)^2) -> 9.1581058 | M29: =SQRT(L29) -> 3.0262363
A30: API - P.perfecto - GPT 5 | B30: ='[1]Ronda 2 (valores sobre1)'!B30*100 -> 46.00188 | C30: ='[1]Ronda 2 (valores sobre1)'!C30*100 -> 37.97429 | D30: ='[1]Ronda 2 (valores sobre1)'!D30*100 -> 16.02383 | E30: =AVERAGE((B30-$B$11)^2, (C30-$C$11)^2) -> 70.314226 | F30: =SQRT(E30) -> 8.3853578 | G30: =AVERAGE((B30-$B$11)^2, (C30-$C$11)^2, (D30-$D$11)^2) -> 118.88758 | H30: =SQRT(G30) -> 10.903558 | J30: =AVERAGE((B30-$B$38)^2, (C30-$C$38)^2) -> 1.9965723 | K30: =SQRT(J30) -> 1.4130012 | L30: =AVERAGE((B30-$B$38)^2, (C30-$C$38)^2, (D30-$D$38)^2) -> 6.7281175 | M30: =SQRT(L30) -> 2.5938615
A31: API - P.original - GPT 4o mini | B31: ='[1]Ronda 2 (valores sobre1)'!B31*100 -> 33.33333 | C31: ='[1]Ronda 2 (valores sobre1)'!C31*100 -> 66.66667 | D31: ='[1]Ronda 2 (valores sobre1)'!D31*100 -> 0 | E31: =AVERAGE((B31-$B$11)^2, (C31-$C$11)^2) -> 611.44318 | F31: =SQRT(E31) -> 24.727377 | G31: =AVERAGE((B31-$B$11)^2, (C31-$C$11)^2, (D31-$D$11)^2) -> 408.21463 | H31: =SQRT(G31) -> 20.204322 | J31: =AVERAGE((B31-$B$38)^2, (C31-$C$38)^2) -> 518.44459 | K31: =SQRT(J31) -> 22.769378 | L31: =AVERAGE((B31-$B$38)^2, (C31-$C$38)^2, (D31-$D$38)^2) -> 393.62973 | M31: =SQRT(L31) -> 19.840104
A32: API - P.perfecto - GPT 4o mini | B32: ='[1]Ronda 2 (valores sobre1)'!B32*100 -> 33.33333 | C32: ='[1]Ronda 2 (valores sobre1)'!C32*100 -> 54.23197 | D32: ='[1]Ronda 2 (valores sobre1)'!D32*100 -> 12.43469 | E32: =AVERAGE((B32-$B$11)^2, (C32-$C$11)^2) -> 373.14454 | F32: =SQRT(E32) -> 19.31695 | G32: =AVERAGE((B32-$B$11)^2, (C32-$C$11)^2, (D32-$D$11)^2) -> 289.8994 | H32: =SQRT(G32) -> 17.026432 | J32: =AVERAGE((B32-$B$38)^2, (C32-$C$38)^2) -> 239.29403 | K32: =SQRT(J32) -> 15.469132 | L32: =AVERAGE((B32-$B$38)^2, (C32-$C$38)^2, (D32-$D$38)^2) -> 159.59234 | M32: =SQRT(L32) -> 12.632986
A33: CHAT - P.original - GPT 5 | B33: ='[1]Ronda 2 (valores sobre1)'!B33*100 -> 47.53679 | C33: ='[1]Ronda 2 (valores sobre1)'!C33*100 -> 34.61292 | D33: ='[1]Ronda 2 (valores sobre1)'!D33*100 -> 17.85029 | E33: =AVERAGE((B33-$B$11)^2, (C33-$C$11)^2) -> 70.79305 | F33: =SQRT(E33) -> 8.4138606 | G33: =AVERAGE((B33-$B$11)^2, (C33-$C$11)^2, (D33-$D$11)^2) -> 138.21578 | H33: =SQRT(G33) -> 11.756521 | J33: =AVERAGE((B33-$B$38)^2, (C33-$C$38)^2) -> 5.8434372 | K33: =SQRT(J33) -> 2.4173203 | L33: =AVERAGE((B33-$B$38)^2, (C33-$C$38)^2, (D33-$D$38)^2) -> 15.304256 | M33: =SQRT(L33) -> 3.9120654
A34: CHAT - P.perfecto - GPT 5 | B34: ='[1]Ronda 2 (valores sobre1)'!B34*100 -> 46.43836 | C34: ='[1]Ronda 2 (valores sobre1)'!C34*100 -> 40 | D34: ='[1]Ronda 2 (valores sobre1)'!D34*100 -> 13.56164 | E34: =AVERAGE((B34-$B$11)^2, (C34-$C$11)^2) -> 60.783822 | F34: =SQRT(E34) -> 7.796398 | G34: =AVERAGE((B34-$B$11)^2, (C34-$C$11)^2, (D34-$D$11)^2) -> 90.428421 | H34: =SQRT(G34) -> 9.5093859 | J34: =AVERAGE((B34-$B$38)^2, (C34-$C$38)^2) -> 3.2193597 | K34: =SQRT(J34) -> 1.7942574 | L34: =AVERAGE((B34-$B$38)^2, (C34-$C$38)^2, (D34-$D$38)^2) -> 2.9591463 | M34: =SQRT(L34) -> 1.7202169
A35: Resultados Reales | B35: ='[1]Ronda 2 (valores sobre1)'!B35*100 -> 57.388958 | C35: ='[1]Ronda 2 (valores sobre1)'!C35*100 -> 41.285317 | D35: ='[1]Ronda 2 (valores sobre1)'!D35*100 -> 1.3257249 | J35: =AVERAGE((B35-$B$38)^2, (C35-$C$38)^2) -> 49.472923 | K35: =SQRT(J35) -> 7.0336991 | L35: =AVERAGE((B35-$B$38)^2, (C35-$C$38)^2, (D35-$D$38)^2) -> 70.961998 | M35: =SQRT(L35) -> 8.4238945
A37: (PIMLE) | B37: JAK | C37: JJ | D37: Blank | E37: MSE | F37: RMSE | G37: MSE (+Blank) | H37: RMSE (+Blank)
A38: Encuestas Humanas | B38: =B2 -> 48 | C38: =C2 -> 38 | D38: =D2 -> 12 | E38: =AVERAGE((B38-$B$11)^2, (C38-$C$11)^2) -> 49.472923 | F38: =SQRT(E38) -> 7.0336991 | G38: =AVERAGE((B38-$B$11)^2, (C38-$C$11)^2, (D38-$D$11)^2) -> 70.961998 | H38: =SQRT(G38) -> 8.4238945 | J38: MSE | K38: RMSE | L38: MSE (+Blank) | M38: RMSE (+Blank)
A39: API - P.original - GPT 4 | B39: ='[1]Ronda 2 (valores sobre1)'!B39*100 -> 38.55591 | C39: ='[1]Ronda 2 (valores sobre1)'!C39*100 -> 43.66118 | D39: ='[1]Ronda 2 (valores sobre1)'!D39*100 -> 17.78291 | E39: =AVERAGE((B39-$B$11)^2, (C39-$C$11)^2) -> 180.16422 | F39: =SQRT(E39) -> 13.422527 | G39: =AVERAGE((B39-$B$11)^2, (C39-$C$11)^2, (D39-$D$11)^2) -> 210.38913 | H39: =SQRT(G39) -> 14.504797 | J39: =AVERAGE((B39-$B$38)^2, (C39-$C$38)^2) -> 60.619897 | K39: =SQRT(J39) -> 7.7858781 | L39: =AVERAGE((B39-$B$38)^2, (C39-$C$38)^2, (D39-$D$38)^2) -> 51.560614 | M39: =SQRT(L39) -> 7.180572
A40: API - P.perfecto - GPT 4 | B40: ='[1]Ronda 2 (valores sobre1)'!B40*100 -> 41.00012 | C40: ='[1]Ronda 2 (valores sobre1)'!C40*100 -> 39.42289 | D40: ='[1]Ronda 2 (valores sobre1)'!D40*100 -> 19.57699 | E40: =AVERAGE((B40-$B$11)^2, (C40-$C$11)^2) -> 136.03133 | F40: =SQRT(E40) -> 11.663247 | G40: =AVERAGE((B40-$B$11)^2, (C40-$C$11)^2, (D40-$D$11)^2) -> 201.72378 | H40: =SQRT(G40) -> 14.20295 | J40: =AVERAGE((B40-$B$38)^2, (C40-$C$38)^2) -> 25.511468 | K40: =SQRT(J40) -> 5.0508878 | L40: =AVERAGE((B40-$B$38)^2, (C40-$C$38)^2, (D40-$D$38)^2) -> 36.144571 | M40: =SQRT(L40) -> 6.0120355
A41: API - P.original - GPT 5 | B41: ='[1]Ronda 2 (valores sobre1)'!B41*100 -> 44.99813 | C41: ='[1]Ronda 2 (valores sobre1)'!C41*100 -> 38.64987 | D41: ='[1]Ronda 2 (valores sobre1)'!D41*100 -> 16.352 | E41: =AVERAGE((B41-$B$11)^2, (C41-$C$11)^2) -> 80.239104 | F41: =SQRT(E41) -> 8.9576282 | G41: =AVERAGE((B41-$B$11)^2, (C41-$C$11)^2, (D41-$D$11)^2) -> 128.75572 | H41: =SQRT(G41) -> 11.347058 | J41: =AVERAGE((B41-$B$38)^2, (C41-$C$38)^2) -> 4.7167773 | K41: =SQRT(J41) -> 2.1718143 | L41: =AVERAGE((B41-$B$38)^2, (C41-$C$38)^2, (D41-$D$38)^2) -> 9.4578195 | M41: =SQRT(L41) -> 3.0753568
A42: API - P.perfecto - GPT 5 | B42: ='[1]Ronda 2 (valores sobre1)'!B42*100 -> 45.85742 | C42: ='[1]Ronda 2 (valores sobre1)'!C42*100 -> 37.99741 | D42: ='[1]Ronda 2 (valores sobre1)'!D42*100 -> 16.14517 | E42: =AVERAGE((B42-$B$11)^2, (C42-$C$11)^2) -> 71.893354 | F42: =SQRT(E42) -> 8.4789949 | G42: =AVERAGE((B42-$B$11)^2, (C42-$C$11)^2, (D42-$D$11)^2) -> 121.13422 | H42: =SQRT(G42) -> 11.006099 | J42: =AVERAGE((B42-$B$38)^2, (C42-$C$38)^2) -> 2.2953279 | K42: =SQRT(J42) -> 1.515034 | L42: =AVERAGE((B42-$B$38)^2, (C42-$C$38)^2, (D42-$D$38)^2) -> 7.2576967 | M42: =SQRT(L42) -> 2.6940113
A43: API - P.original - GPT 4o mini | B43: ='[1]Ronda 2 (valores sobre1)'!B43*100 -> 33.33333 | C43: ='[1]Ronda 2 (valores sobre1)'!C43*100 -> 66.66667 | D43: ='[1]Ronda 2 (valores sobre1)'!D43*100 -> 0 | E43: =AVERAGE((B43-$B$11)^2, (C43-$C$11)^2) -> 611.44318 | F43: =SQRT(E43) -> 24.727377 | G43: =AVERAGE((B43-$B$11)^2, (C43-$C$11)^2, (D43-$D$11)^2) -> 408.21463 | H43: =SQRT(G43) -> 20.204322 | J43: =AVERAGE((B43-$B$38)^2, (C43-$C$38)^2) -> 518.44459 | K43: =SQRT(J43) -> 22.769378 | L43: =AVERAGE((B43-$B$38)^2, (C43-$C$38)^2, (D43-$D$38)^2) -> 393.62973 | M43: =SQRT(L43) -> 19.840104
...

Sheet Round 2 - 4dec & 12dec
